2020-09-12 17:29:23,570 -  nornir.core -     INFO -        run() - Running task 'test' with args {} on 8 hosts
2020-09-12 17:29:23,639 - nornir.core.task -    ERROR -      start() - Host 'R5': task 'netmiko_send_command' failed with traceback:
Traceback (most recent call last):
  File "/home/eve/PycharmProjects/ospf_enterprise/venv/lib/python3.6/site-packages/netmiko/base_connection.py", line 918, in establish_connection
    self.remote_conn_pre.connect(**ssh_connect_params)
  File "/home/eve/PycharmProjects/ospf_enterprise/venv/lib/python3.6/site-packages/paramiko/client.py", line 368, in connect
    raise NoValidConnectionsError(errors)
paramiko.ssh_exception.NoValidConnectionsError: [Errno None] Unable to connect to port 22 on 10.0.56.5

During handling of the above exception, another exception occurred:

Traceback (most recent call last):
  File "/home/eve/PycharmProjects/ospf_enterprise/venv/lib/python3.6/site-packages/nornir/core/task.py", line 85, in start
    r = self.task(self, **self.params)
  File "/home/eve/PycharmProjects/ospf_enterprise/venv/lib/python3.6/site-packages/nornir/plugins/tasks/networking/netmiko_send_command.py", line 26, in netmiko_send_command
    net_connect = task.host.get_connection("netmiko", task.nornir.config)
  File "/home/eve/PycharmProjects/ospf_enterprise/venv/lib/python3.6/site-packages/nornir/core/inventory.py", line 305, in get_connection
    extras=conn.extras,
  File "/home/eve/PycharmProjects/ospf_enterprise/venv/lib/python3.6/site-packages/nornir/core/inventory.py", line 365, in open_connection
    configuration=configuration,
  File "/home/eve/PycharmProjects/ospf_enterprise/venv/lib/python3.6/site-packages/nornir/plugins/connections/netmiko.py", line 58, in open
    self.connection = ConnectHandler(**parameters)
  File "/home/eve/PycharmProjects/ospf_enterprise/venv/lib/python3.6/site-packages/netmiko/ssh_dispatcher.py", line 302, in ConnectHandler
    return ConnectionClass(*args, **kwargs)
  File "/home/eve/PycharmProjects/ospf_enterprise/venv/lib/python3.6/site-packages/netmiko/cisco/cisco_ios.py", line 17, in __init__
    return super().__init__(*args, **kwargs)
  File "/home/eve/PycharmProjects/ospf_enterprise/venv/lib/python3.6/site-packages/netmiko/base_connection.py", line 344, in __init__
    self._open()
  File "/home/eve/PycharmProjects/ospf_enterprise/venv/lib/python3.6/site-packages/netmiko/base_connection.py", line 349, in _open
    self.establish_connection()
  File "/home/eve/PycharmProjects/ospf_enterprise/venv/lib/python3.6/site-packages/netmiko/base_connection.py", line 940, in establish_connection
    raise NetmikoTimeoutException(msg)
netmiko.ssh_exception.NetmikoTimeoutException: TCP connection to device failed.

Common causes of this problem are:
1. Incorrect hostname or IP address.
2. Wrong TCP port.
3. Intermediate firewall blocking access.

Device settings: cisco_ios 10.0.56.5:22



2020-09-12 17:29:23,641 - nornir.core.task -    ERROR -      start() - Host 'R5': task 'test' failed with traceback:
Traceback (most recent call last):
  File "/home/eve/PycharmProjects/ospf_enterprise/venv/lib/python3.6/site-packages/nornir/core/task.py", line 85, in start
    r = self.task(self, **self.params)
  File "ospf.py", line 14, in test
    result = task.run(netmiko_send_command, command_string='show ip ospf neigh', use_genie=True)
  File "/home/eve/PycharmProjects/ospf_enterprise/venv/lib/python3.6/site-packages/nornir/core/task.py", line 147, in run
    raise NornirSubTaskError(task=task, result=r)
nornir.core.exceptions.NornirSubTaskError: Subtask: <function netmiko_send_command at 0x7f38010a8950> (failed)


2020-09-12 17:29:24,586 - nornir.core.task -    ERROR -      start() - Host 'R6': task 'netmiko_send_command' failed with traceback:
Traceback (most recent call last):
  File "/home/eve/PycharmProjects/ospf_enterprise/venv/lib/python3.6/site-packages/netmiko/base_connection.py", line 918, in establish_connection
    self.remote_conn_pre.connect(**ssh_connect_params)
  File "/home/eve/PycharmProjects/ospf_enterprise/venv/lib/python3.6/site-packages/paramiko/client.py", line 368, in connect
    raise NoValidConnectionsError(errors)
paramiko.ssh_exception.NoValidConnectionsError: [Errno None] Unable to connect to port 22 on 10.0.56.5

During handling of the above exception, another exception occurred:

Traceback (most recent call last):
  File "/home/eve/PycharmProjects/ospf_enterprise/venv/lib/python3.6/site-packages/nornir/core/task.py", line 85, in start
    r = self.task(self, **self.params)
  File "/home/eve/PycharmProjects/ospf_enterprise/venv/lib/python3.6/site-packages/nornir/plugins/tasks/networking/netmiko_send_command.py", line 26, in netmiko_send_command
    net_connect = task.host.get_connection("netmiko", task.nornir.config)
  File "/home/eve/PycharmProjects/ospf_enterprise/venv/lib/python3.6/site-packages/nornir/core/inventory.py", line 305, in get_connection
    extras=conn.extras,
  File "/home/eve/PycharmProjects/ospf_enterprise/venv/lib/python3.6/site-packages/nornir/core/inventory.py", line 365, in open_connection
    configuration=configuration,
  File "/home/eve/PycharmProjects/ospf_enterprise/venv/lib/python3.6/site-packages/nornir/plugins/connections/netmiko.py", line 58, in open
    self.connection = ConnectHandler(**parameters)
  File "/home/eve/PycharmProjects/ospf_enterprise/venv/lib/python3.6/site-packages/netmiko/ssh_dispatcher.py", line 302, in ConnectHandler
    return ConnectionClass(*args, **kwargs)
  File "/home/eve/PycharmProjects/ospf_enterprise/venv/lib/python3.6/site-packages/netmiko/cisco/cisco_ios.py", line 17, in __init__
    return super().__init__(*args, **kwargs)
  File "/home/eve/PycharmProjects/ospf_enterprise/venv/lib/python3.6/site-packages/netmiko/base_connection.py", line 344, in __init__
    self._open()
  File "/home/eve/PycharmProjects/ospf_enterprise/venv/lib/python3.6/site-packages/netmiko/base_connection.py", line 349, in _open
    self.establish_connection()
  File "/home/eve/PycharmProjects/ospf_enterprise/venv/lib/python3.6/site-packages/netmiko/base_connection.py", line 940, in establish_connection
    raise NetmikoTimeoutException(msg)
netmiko.ssh_exception.NetmikoTimeoutException: TCP connection to device failed.

Common causes of this problem are:
1. Incorrect hostname or IP address.
2. Wrong TCP port.
3. Intermediate firewall blocking access.

Device settings: cisco_ios 10.0.56.5:22



2020-09-12 17:29:24,586 - nornir.core.task -    ERROR -      start() - Host 'R6': task 'test' failed with traceback:
Traceback (most recent call last):
  File "/home/eve/PycharmProjects/ospf_enterprise/venv/lib/python3.6/site-packages/nornir/core/task.py", line 85, in start
    r = self.task(self, **self.params)
  File "ospf.py", line 14, in test
    result = task.run(netmiko_send_command, command_string='show ip ospf neigh', use_genie=True)
  File "/home/eve/PycharmProjects/ospf_enterprise/venv/lib/python3.6/site-packages/nornir/core/task.py", line 147, in run
    raise NornirSubTaskError(task=task, result=r)
nornir.core.exceptions.NornirSubTaskError: Subtask: <function netmiko_send_command at 0x7f38010a8950> (failed)


2020-09-12 17:29:45,248 -  nornir.core -     INFO -        run() - Running task 'test' with args {} on 8 hosts
2020-09-12 17:29:45,328 - nornir.core.task -    ERROR -      start() - Host 'R5': task 'netmiko_send_command' failed with traceback:
Traceback (most recent call last):
  File "/home/eve/PycharmProjects/ospf_enterprise/venv/lib/python3.6/site-packages/netmiko/base_connection.py", line 918, in establish_connection
    self.remote_conn_pre.connect(**ssh_connect_params)
  File "/home/eve/PycharmProjects/ospf_enterprise/venv/lib/python3.6/site-packages/paramiko/client.py", line 368, in connect
    raise NoValidConnectionsError(errors)
paramiko.ssh_exception.NoValidConnectionsError: [Errno None] Unable to connect to port 22 on 10.0.56.5

During handling of the above exception, another exception occurred:

Traceback (most recent call last):
  File "/home/eve/PycharmProjects/ospf_enterprise/venv/lib/python3.6/site-packages/nornir/core/task.py", line 85, in start
    r = self.task(self, **self.params)
  File "/home/eve/PycharmProjects/ospf_enterprise/venv/lib/python3.6/site-packages/nornir/plugins/tasks/networking/netmiko_send_command.py", line 26, in netmiko_send_command
    net_connect = task.host.get_connection("netmiko", task.nornir.config)
  File "/home/eve/PycharmProjects/ospf_enterprise/venv/lib/python3.6/site-packages/nornir/core/inventory.py", line 305, in get_connection
    extras=conn.extras,
  File "/home/eve/PycharmProjects/ospf_enterprise/venv/lib/python3.6/site-packages/nornir/core/inventory.py", line 365, in open_connection
    configuration=configuration,
  File "/home/eve/PycharmProjects/ospf_enterprise/venv/lib/python3.6/site-packages/nornir/plugins/connections/netmiko.py", line 58, in open
    self.connection = ConnectHandler(**parameters)
  File "/home/eve/PycharmProjects/ospf_enterprise/venv/lib/python3.6/site-packages/netmiko/ssh_dispatcher.py", line 302, in ConnectHandler
    return ConnectionClass(*args, **kwargs)
  File "/home/eve/PycharmProjects/ospf_enterprise/venv/lib/python3.6/site-packages/netmiko/cisco/cisco_ios.py", line 17, in __init__
    return super().__init__(*args, **kwargs)
  File "/home/eve/PycharmProjects/ospf_enterprise/venv/lib/python3.6/site-packages/netmiko/base_connection.py", line 344, in __init__
    self._open()
  File "/home/eve/PycharmProjects/ospf_enterprise/venv/lib/python3.6/site-packages/netmiko/base_connection.py", line 349, in _open
    self.establish_connection()
  File "/home/eve/PycharmProjects/ospf_enterprise/venv/lib/python3.6/site-packages/netmiko/base_connection.py", line 940, in establish_connection
    raise NetmikoTimeoutException(msg)
netmiko.ssh_exception.NetmikoTimeoutException: TCP connection to device failed.

Common causes of this problem are:
1. Incorrect hostname or IP address.
2. Wrong TCP port.
3. Intermediate firewall blocking access.

Device settings: cisco_ios 10.0.56.5:22



2020-09-12 17:29:45,331 - nornir.core.task -    ERROR -      start() - Host 'R5': task 'test' failed with traceback:
Traceback (most recent call last):
  File "/home/eve/PycharmProjects/ospf_enterprise/venv/lib/python3.6/site-packages/nornir/core/task.py", line 85, in start
    r = self.task(self, **self.params)
  File "ospf.py", line 14, in test
    result = task.run(netmiko_send_command, command_string='show ip ospf neigh', use_genie=True)
  File "/home/eve/PycharmProjects/ospf_enterprise/venv/lib/python3.6/site-packages/nornir/core/task.py", line 147, in run
    raise NornirSubTaskError(task=task, result=r)
nornir.core.exceptions.NornirSubTaskError: Subtask: <function netmiko_send_command at 0x7f4345d788c8> (failed)


2020-09-12 17:29:46,292 - nornir.core.task -    ERROR -      start() - Host 'R6': task 'netmiko_send_command' failed with traceback:
Traceback (most recent call last):
  File "/home/eve/PycharmProjects/ospf_enterprise/venv/lib/python3.6/site-packages/netmiko/base_connection.py", line 918, in establish_connection
    self.remote_conn_pre.connect(**ssh_connect_params)
  File "/home/eve/PycharmProjects/ospf_enterprise/venv/lib/python3.6/site-packages/paramiko/client.py", line 368, in connect
    raise NoValidConnectionsError(errors)
paramiko.ssh_exception.NoValidConnectionsError: [Errno None] Unable to connect to port 22 on 10.0.56.5

During handling of the above exception, another exception occurred:

Traceback (most recent call last):
  File "/home/eve/PycharmProjects/ospf_enterprise/venv/lib/python3.6/site-packages/nornir/core/task.py", line 85, in start
    r = self.task(self, **self.params)
  File "/home/eve/PycharmProjects/ospf_enterprise/venv/lib/python3.6/site-packages/nornir/plugins/tasks/networking/netmiko_send_command.py", line 26, in netmiko_send_command
    net_connect = task.host.get_connection("netmiko", task.nornir.config)
  File "/home/eve/PycharmProjects/ospf_enterprise/venv/lib/python3.6/site-packages/nornir/core/inventory.py", line 305, in get_connection
    extras=conn.extras,
  File "/home/eve/PycharmProjects/ospf_enterprise/venv/lib/python3.6/site-packages/nornir/core/inventory.py", line 365, in open_connection
    configuration=configuration,
  File "/home/eve/PycharmProjects/ospf_enterprise/venv/lib/python3.6/site-packages/nornir/plugins/connections/netmiko.py", line 58, in open
    self.connection = ConnectHandler(**parameters)
  File "/home/eve/PycharmProjects/ospf_enterprise/venv/lib/python3.6/site-packages/netmiko/ssh_dispatcher.py", line 302, in ConnectHandler
    return ConnectionClass(*args, **kwargs)
  File "/home/eve/PycharmProjects/ospf_enterprise/venv/lib/python3.6/site-packages/netmiko/cisco/cisco_ios.py", line 17, in __init__
    return super().__init__(*args, **kwargs)
  File "/home/eve/PycharmProjects/ospf_enterprise/venv/lib/python3.6/site-packages/netmiko/base_connection.py", line 344, in __init__
    self._open()
  File "/home/eve/PycharmProjects/ospf_enterprise/venv/lib/python3.6/site-packages/netmiko/base_connection.py", line 349, in _open
    self.establish_connection()
  File "/home/eve/PycharmProjects/ospf_enterprise/venv/lib/python3.6/site-packages/netmiko/base_connection.py", line 940, in establish_connection
    raise NetmikoTimeoutException(msg)
netmiko.ssh_exception.NetmikoTimeoutException: TCP connection to device failed.

Common causes of this problem are:
1. Incorrect hostname or IP address.
2. Wrong TCP port.
3. Intermediate firewall blocking access.

Device settings: cisco_ios 10.0.56.5:22



2020-09-12 17:29:46,293 - nornir.core.task -    ERROR -      start() - Host 'R6': task 'test' failed with traceback:
Traceback (most recent call last):
  File "/home/eve/PycharmProjects/ospf_enterprise/venv/lib/python3.6/site-packages/nornir/core/task.py", line 85, in start
    r = self.task(self, **self.params)
  File "ospf.py", line 14, in test
    result = task.run(netmiko_send_command, command_string='show ip ospf neigh', use_genie=True)
  File "/home/eve/PycharmProjects/ospf_enterprise/venv/lib/python3.6/site-packages/nornir/core/task.py", line 147, in run
    raise NornirSubTaskError(task=task, result=r)
nornir.core.exceptions.NornirSubTaskError: Subtask: <function netmiko_send_command at 0x7f4345d788c8> (failed)


2020-09-12 18:54:20,387 -  nornir.core -     INFO -        run() - Running task 'test' with args {} on 6 hosts
2020-09-12 19:27:35,247 -  nornir.core -     INFO -        run() - Running task 'test' with args {} on 6 hosts
2020-09-12 19:28:10,362 -  nornir.core -     INFO -        run() - Running task 'test' with args {} on 6 hosts
2020-09-12 19:30:02,930 -  nornir.core -     INFO -        run() - Running task 'test' with args {} on 6 hosts
2020-09-12 19:31:13,885 -  nornir.core -     INFO -        run() - Running task 'test' with args {} on 6 hosts
2020-09-12 19:32:13,683 -  nornir.core -     INFO -        run() - Running task 'test' with args {} on 6 hosts
2020-09-12 19:32:38,917 -  nornir.core -     INFO -        run() - Running task 'test' with args {} on 6 hosts
2020-09-12 19:33:18,156 -  nornir.core -     INFO -        run() - Running task 'test' with args {} on 6 hosts
2020-09-12 19:33:24,330 - nornir.core.task -    ERROR -      start() - Host 'R3': task 'test' failed with traceback:
Traceback (most recent call last):
  File "/home/eve/PycharmProjects/ospf_enterprise/venv/lib/python3.6/site-packages/nornir/core/task.py", line 85, in start
    r = self.task(self, **self.params)
  File "ospf.py", line 16, in test
    interfaces = task.host['facts']['interfaces']
TypeError: string indices must be integers

2020-09-12 19:33:24,355 - nornir.core.task -    ERROR -      start() - Host 'R8': task 'test' failed with traceback:
Traceback (most recent call last):
  File "/home/eve/PycharmProjects/ospf_enterprise/venv/lib/python3.6/site-packages/nornir/core/task.py", line 85, in start
    r = self.task(self, **self.params)
  File "ospf.py", line 16, in test
    interfaces = task.host['facts']['interfaces']
TypeError: string indices must be integers

2020-09-12 19:33:24,357 - nornir.core.task -    ERROR -      start() - Host 'R7': task 'test' failed with traceback:
Traceback (most recent call last):
  File "/home/eve/PycharmProjects/ospf_enterprise/venv/lib/python3.6/site-packages/nornir/core/task.py", line 85, in start
    r = self.task(self, **self.params)
  File "ospf.py", line 16, in test
    interfaces = task.host['facts']['interfaces']
TypeError: string indices must be integers

2020-09-12 19:33:24,366 - nornir.core.task -    ERROR -      start() - Host 'R4': task 'test' failed with traceback:
Traceback (most recent call last):
  File "/home/eve/PycharmProjects/ospf_enterprise/venv/lib/python3.6/site-packages/nornir/core/task.py", line 85, in start
    r = self.task(self, **self.params)
  File "ospf.py", line 16, in test
    interfaces = task.host['facts']['interfaces']
TypeError: string indices must be integers

2020-09-12 19:33:24,368 - nornir.core.task -    ERROR -      start() - Host 'R1': task 'test' failed with traceback:
Traceback (most recent call last):
  File "/home/eve/PycharmProjects/ospf_enterprise/venv/lib/python3.6/site-packages/nornir/core/task.py", line 85, in start
    r = self.task(self, **self.params)
  File "ospf.py", line 16, in test
    interfaces = task.host['facts']['interfaces']
TypeError: string indices must be integers

2020-09-12 19:33:24,378 - nornir.core.task -    ERROR -      start() - Host 'R2': task 'test' failed with traceback:
Traceback (most recent call last):
  File "/home/eve/PycharmProjects/ospf_enterprise/venv/lib/python3.6/site-packages/nornir/core/task.py", line 85, in start
    r = self.task(self, **self.params)
  File "ospf.py", line 16, in test
    interfaces = task.host['facts']['interfaces']
TypeError: string indices must be integers

2020-09-12 19:34:01,891 -  nornir.core -     INFO -        run() - Running task 'test' with args {} on 6 hosts
2020-09-12 19:34:07,827 - nornir.core.task -    ERROR -      start() - Host 'R7': task 'test' failed with traceback:
Traceback (most recent call last):
  File "/home/eve/PycharmProjects/ospf_enterprise/venv/lib/python3.6/site-packages/nornir/core/task.py", line 85, in start
    r = self.task(self, **self.params)
  File "ospf.py", line 16, in test
    interfaces = task.host['facts']['interfaces']
TypeError: string indices must be integers

2020-09-12 19:34:07,870 - nornir.core.task -    ERROR -      start() - Host 'R4': task 'test' failed with traceback:
Traceback (most recent call last):
  File "/home/eve/PycharmProjects/ospf_enterprise/venv/lib/python3.6/site-packages/nornir/core/task.py", line 85, in start
    r = self.task(self, **self.params)
  File "ospf.py", line 16, in test
    interfaces = task.host['facts']['interfaces']
TypeError: string indices must be integers

2020-09-12 19:34:07,903 - nornir.core.task -    ERROR -      start() - Host 'R8': task 'test' failed with traceback:
Traceback (most recent call last):
  File "/home/eve/PycharmProjects/ospf_enterprise/venv/lib/python3.6/site-packages/nornir/core/task.py", line 85, in start
    r = self.task(self, **self.params)
  File "ospf.py", line 16, in test
    interfaces = task.host['facts']['interfaces']
TypeError: string indices must be integers

2020-09-12 19:34:07,903 - nornir.core.task -    ERROR -      start() - Host 'R1': task 'test' failed with traceback:
Traceback (most recent call last):
  File "/home/eve/PycharmProjects/ospf_enterprise/venv/lib/python3.6/site-packages/nornir/core/task.py", line 85, in start
    r = self.task(self, **self.params)
  File "ospf.py", line 16, in test
    interfaces = task.host['facts']['interfaces']
TypeError: string indices must be integers

2020-09-12 19:34:07,947 - nornir.core.task -    ERROR -      start() - Host 'R3': task 'test' failed with traceback:
Traceback (most recent call last):
  File "/home/eve/PycharmProjects/ospf_enterprise/venv/lib/python3.6/site-packages/nornir/core/task.py", line 85, in start
    r = self.task(self, **self.params)
  File "ospf.py", line 16, in test
    interfaces = task.host['facts']['interfaces']
TypeError: string indices must be integers

2020-09-12 19:34:07,989 - nornir.core.task -    ERROR -      start() - Host 'R2': task 'test' failed with traceback:
Traceback (most recent call last):
  File "/home/eve/PycharmProjects/ospf_enterprise/venv/lib/python3.6/site-packages/nornir/core/task.py", line 85, in start
    r = self.task(self, **self.params)
  File "ospf.py", line 16, in test
    interfaces = task.host['facts']['interfaces']
TypeError: string indices must be integers

2020-09-12 19:35:11,430 -  nornir.core -     INFO -        run() - Running task 'test' with args {} on 6 hosts
2020-09-12 19:35:16,896 - nornir.core.task -    ERROR -      start() - Host 'R8': task 'test' failed with traceback:
Traceback (most recent call last):
  File "/home/eve/PycharmProjects/ospf_enterprise/venv/lib/python3.6/site-packages/nornir/core/task.py", line 85, in start
    r = self.task(self, **self.params)
  File "ospf.py", line 16, in test
    interfaces = task.host['facts']['interfaces']
TypeError: string indices must be integers

2020-09-12 19:35:16,898 - nornir.core.task -    ERROR -      start() - Host 'R7': task 'test' failed with traceback:
Traceback (most recent call last):
  File "/home/eve/PycharmProjects/ospf_enterprise/venv/lib/python3.6/site-packages/nornir/core/task.py", line 85, in start
    r = self.task(self, **self.params)
  File "ospf.py", line 16, in test
    interfaces = task.host['facts']['interfaces']
TypeError: string indices must be integers

2020-09-12 19:35:16,899 - nornir.core.task -    ERROR -      start() - Host 'R1': task 'test' failed with traceback:
Traceback (most recent call last):
  File "/home/eve/PycharmProjects/ospf_enterprise/venv/lib/python3.6/site-packages/nornir/core/task.py", line 85, in start
    r = self.task(self, **self.params)
  File "ospf.py", line 16, in test
    interfaces = task.host['facts']['interfaces']
TypeError: string indices must be integers

2020-09-12 19:35:16,901 - nornir.core.task -    ERROR -      start() - Host 'R2': task 'test' failed with traceback:
Traceback (most recent call last):
  File "/home/eve/PycharmProjects/ospf_enterprise/venv/lib/python3.6/site-packages/nornir/core/task.py", line 85, in start
    r = self.task(self, **self.params)
  File "ospf.py", line 16, in test
    interfaces = task.host['facts']['interfaces']
TypeError: string indices must be integers

2020-09-12 19:35:16,902 - nornir.core.task -    ERROR -      start() - Host 'R3': task 'test' failed with traceback:
Traceback (most recent call last):
  File "/home/eve/PycharmProjects/ospf_enterprise/venv/lib/python3.6/site-packages/nornir/core/task.py", line 85, in start
    r = self.task(self, **self.params)
  File "ospf.py", line 16, in test
    interfaces = task.host['facts']['interfaces']
TypeError: string indices must be integers

2020-09-12 19:35:16,904 - nornir.core.task -    ERROR -      start() - Host 'R4': task 'test' failed with traceback:
Traceback (most recent call last):
  File "/home/eve/PycharmProjects/ospf_enterprise/venv/lib/python3.6/site-packages/nornir/core/task.py", line 85, in start
    r = self.task(self, **self.params)
  File "ospf.py", line 16, in test
    interfaces = task.host['facts']['interfaces']
TypeError: string indices must be integers

2020-09-12 19:36:50,822 -  nornir.core -     INFO -        run() - Running task 'test' with args {} on 6 hosts
2020-09-12 19:36:58,357 - nornir.core.task -    ERROR -      start() - Host 'R2': task 'test' failed with traceback:
Traceback (most recent call last):
  File "/home/eve/PycharmProjects/ospf_enterprise/venv/lib/python3.6/site-packages/nornir/core/task.py", line 85, in start
    r = self.task(self, **self.params)
  File "ospf.py", line 16, in test
    interfaces = task.host['facts']['interfaces']
TypeError: string indices must be integers

2020-09-12 19:36:58,371 - nornir.core.task -    ERROR -      start() - Host 'R8': task 'test' failed with traceback:
Traceback (most recent call last):
  File "/home/eve/PycharmProjects/ospf_enterprise/venv/lib/python3.6/site-packages/nornir/core/task.py", line 85, in start
    r = self.task(self, **self.params)
  File "ospf.py", line 16, in test
    interfaces = task.host['facts']['interfaces']
TypeError: string indices must be integers

2020-09-12 19:36:58,373 - nornir.core.task -    ERROR -      start() - Host 'R7': task 'test' failed with traceback:
Traceback (most recent call last):
  File "/home/eve/PycharmProjects/ospf_enterprise/venv/lib/python3.6/site-packages/nornir/core/task.py", line 85, in start
    r = self.task(self, **self.params)
  File "ospf.py", line 16, in test
    interfaces = task.host['facts']['interfaces']
TypeError: string indices must be integers

2020-09-12 19:36:58,389 - nornir.core.task -    ERROR -      start() - Host 'R3': task 'test' failed with traceback:
Traceback (most recent call last):
  File "/home/eve/PycharmProjects/ospf_enterprise/venv/lib/python3.6/site-packages/nornir/core/task.py", line 85, in start
    r = self.task(self, **self.params)
  File "ospf.py", line 16, in test
    interfaces = task.host['facts']['interfaces']
TypeError: string indices must be integers

2020-09-12 19:36:58,387 - nornir.core.task -    ERROR -      start() - Host 'R4': task 'test' failed with traceback:
Traceback (most recent call last):
  File "/home/eve/PycharmProjects/ospf_enterprise/venv/lib/python3.6/site-packages/nornir/core/task.py", line 85, in start
    r = self.task(self, **self.params)
  File "ospf.py", line 16, in test
    interfaces = task.host['facts']['interfaces']
TypeError: string indices must be integers

2020-09-12 19:36:58,402 - nornir.core.task -    ERROR -      start() - Host 'R1': task 'test' failed with traceback:
Traceback (most recent call last):
  File "/home/eve/PycharmProjects/ospf_enterprise/venv/lib/python3.6/site-packages/nornir/core/task.py", line 85, in start
    r = self.task(self, **self.params)
  File "ospf.py", line 16, in test
    interfaces = task.host['facts']['interfaces']
TypeError: string indices must be integers

2020-09-12 19:38:59,999 -  nornir.core -     INFO -        run() - Running task 'test' with args {} on 6 hosts
2020-09-12 19:39:05,262 - nornir.core.task -    ERROR -      start() - Host 'R7': task 'test' failed with traceback:
Traceback (most recent call last):
  File "/home/eve/PycharmProjects/ospf_enterprise/venv/lib/python3.6/site-packages/nornir/core/task.py", line 85, in start
    r = self.task(self, **self.params)
  File "ospf.py", line 16, in test
    interfaces = task.host['facts']['interfaces']
TypeError: string indices must be integers

2020-09-12 19:39:05,272 - nornir.core.task -    ERROR -      start() - Host 'R1': task 'test' failed with traceback:
Traceback (most recent call last):
  File "/home/eve/PycharmProjects/ospf_enterprise/venv/lib/python3.6/site-packages/nornir/core/task.py", line 85, in start
    r = self.task(self, **self.params)
  File "ospf.py", line 16, in test
    interfaces = task.host['facts']['interfaces']
TypeError: string indices must be integers

2020-09-12 19:39:05,273 - nornir.core.task -    ERROR -      start() - Host 'R3': task 'test' failed with traceback:
Traceback (most recent call last):
  File "/home/eve/PycharmProjects/ospf_enterprise/venv/lib/python3.6/site-packages/nornir/core/task.py", line 85, in start
    r = self.task(self, **self.params)
  File "ospf.py", line 16, in test
    interfaces = task.host['facts']['interfaces']
TypeError: string indices must be integers

2020-09-12 19:39:05,281 - nornir.core.task -    ERROR -      start() - Host 'R8': task 'test' failed with traceback:
Traceback (most recent call last):
  File "/home/eve/PycharmProjects/ospf_enterprise/venv/lib/python3.6/site-packages/nornir/core/task.py", line 85, in start
    r = self.task(self, **self.params)
  File "ospf.py", line 16, in test
    interfaces = task.host['facts']['interfaces']
TypeError: string indices must be integers

2020-09-12 19:39:05,282 - nornir.core.task -    ERROR -      start() - Host 'R4': task 'test' failed with traceback:
Traceback (most recent call last):
  File "/home/eve/PycharmProjects/ospf_enterprise/venv/lib/python3.6/site-packages/nornir/core/task.py", line 85, in start
    r = self.task(self, **self.params)
  File "ospf.py", line 16, in test
    interfaces = task.host['facts']['interfaces']
TypeError: string indices must be integers

2020-09-12 19:39:05,286 - nornir.core.task -    ERROR -      start() - Host 'R2': task 'test' failed with traceback:
Traceback (most recent call last):
  File "/home/eve/PycharmProjects/ospf_enterprise/venv/lib/python3.6/site-packages/nornir/core/task.py", line 85, in start
    r = self.task(self, **self.params)
  File "ospf.py", line 16, in test
    interfaces = task.host['facts']['interfaces']
TypeError: string indices must be integers

2020-09-12 19:40:00,526 -  nornir.core -     INFO -        run() - Running task 'test' with args {} on 6 hosts
2020-09-12 19:40:06,244 - nornir.core.task -    ERROR -      start() - Host 'R4': task 'test' failed with traceback:
Traceback (most recent call last):
  File "/home/eve/PycharmProjects/ospf_enterprise/venv/lib/python3.6/site-packages/nornir/core/task.py", line 85, in start
    r = self.task(self, **self.params)
  File "ospf.py", line 16, in test
    interfaces = task.host['facts']['interfaces']
TypeError: string indices must be integers

2020-09-12 19:40:06,275 - nornir.core.task -    ERROR -      start() - Host 'R8': task 'test' failed with traceback:
Traceback (most recent call last):
  File "/home/eve/PycharmProjects/ospf_enterprise/venv/lib/python3.6/site-packages/nornir/core/task.py", line 85, in start
    r = self.task(self, **self.params)
  File "ospf.py", line 16, in test
    interfaces = task.host['facts']['interfaces']
TypeError: string indices must be integers

2020-09-12 19:40:06,276 - nornir.core.task -    ERROR -      start() - Host 'R7': task 'test' failed with traceback:
Traceback (most recent call last):
  File "/home/eve/PycharmProjects/ospf_enterprise/venv/lib/python3.6/site-packages/nornir/core/task.py", line 85, in start
    r = self.task(self, **self.params)
  File "ospf.py", line 16, in test
    interfaces = task.host['facts']['interfaces']
TypeError: string indices must be integers

2020-09-12 19:40:06,284 - nornir.core.task -    ERROR -      start() - Host 'R3': task 'test' failed with traceback:
Traceback (most recent call last):
  File "/home/eve/PycharmProjects/ospf_enterprise/venv/lib/python3.6/site-packages/nornir/core/task.py", line 85, in start
    r = self.task(self, **self.params)
  File "ospf.py", line 16, in test
    interfaces = task.host['facts']['interfaces']
TypeError: string indices must be integers

2020-09-12 19:40:06,285 - nornir.core.task -    ERROR -      start() - Host 'R2': task 'test' failed with traceback:
Traceback (most recent call last):
  File "/home/eve/PycharmProjects/ospf_enterprise/venv/lib/python3.6/site-packages/nornir/core/task.py", line 85, in start
    r = self.task(self, **self.params)
  File "ospf.py", line 16, in test
    interfaces = task.host['facts']['interfaces']
TypeError: string indices must be integers

2020-09-12 19:40:06,238 - nornir.core.task -    ERROR -      start() - Host 'R1': task 'test' failed with traceback:
Traceback (most recent call last):
  File "/home/eve/PycharmProjects/ospf_enterprise/venv/lib/python3.6/site-packages/nornir/core/task.py", line 85, in start
    r = self.task(self, **self.params)
  File "ospf.py", line 16, in test
    interfaces = task.host['facts']['interfaces']
TypeError: string indices must be integers

2020-09-12 19:40:30,784 -  nornir.core -     INFO -        run() - Running task 'test' with args {} on 6 hosts
2020-09-12 19:41:20,887 -  nornir.core -     INFO -        run() - Running task 'test' with args {} on 6 hosts
2020-09-12 19:42:01,274 -  nornir.core -     INFO -        run() - Running task 'test' with args {} on 6 hosts
2020-09-12 19:42:22,926 -  nornir.core -     INFO -        run() - Running task 'test' with args {} on 6 hosts
2020-09-12 19:42:29,457 - nornir.core.task -    ERROR -      start() - Host 'R3': task 'test' failed with traceback:
Traceback (most recent call last):
  File "/home/eve/PycharmProjects/ospf_enterprise/venv/lib/python3.6/site-packages/nornir/core/task.py", line 85, in start
    r = self.task(self, **self.params)
  File "ospf.py", line 17, in test
    interfaces = task.host['facts']['Interface']
TypeError: string indices must be integers

2020-09-12 19:42:29,461 - nornir.core.task -    ERROR -      start() - Host 'R4': task 'test' failed with traceback:
Traceback (most recent call last):
  File "/home/eve/PycharmProjects/ospf_enterprise/venv/lib/python3.6/site-packages/nornir/core/task.py", line 85, in start
    r = self.task(self, **self.params)
  File "ospf.py", line 17, in test
    interfaces = task.host['facts']['Interface']
TypeError: string indices must be integers

2020-09-12 19:42:29,488 - nornir.core.task -    ERROR -      start() - Host 'R2': task 'test' failed with traceback:
Traceback (most recent call last):
  File "/home/eve/PycharmProjects/ospf_enterprise/venv/lib/python3.6/site-packages/nornir/core/task.py", line 85, in start
    r = self.task(self, **self.params)
  File "ospf.py", line 17, in test
    interfaces = task.host['facts']['Interface']
TypeError: string indices must be integers

2020-09-12 19:42:29,492 - nornir.core.task -    ERROR -      start() - Host 'R8': task 'test' failed with traceback:
Traceback (most recent call last):
  File "/home/eve/PycharmProjects/ospf_enterprise/venv/lib/python3.6/site-packages/nornir/core/task.py", line 85, in start
    r = self.task(self, **self.params)
  File "ospf.py", line 17, in test
    interfaces = task.host['facts']['Interface']
TypeError: string indices must be integers

2020-09-12 19:42:29,492 - nornir.core.task -    ERROR -      start() - Host 'R7': task 'test' failed with traceback:
Traceback (most recent call last):
  File "/home/eve/PycharmProjects/ospf_enterprise/venv/lib/python3.6/site-packages/nornir/core/task.py", line 85, in start
    r = self.task(self, **self.params)
  File "ospf.py", line 17, in test
    interfaces = task.host['facts']['Interface']
TypeError: string indices must be integers

2020-09-12 19:42:29,493 - nornir.core.task -    ERROR -      start() - Host 'R1': task 'test' failed with traceback:
Traceback (most recent call last):
  File "/home/eve/PycharmProjects/ospf_enterprise/venv/lib/python3.6/site-packages/nornir/core/task.py", line 85, in start
    r = self.task(self, **self.params)
  File "ospf.py", line 17, in test
    interfaces = task.host['facts']['Interface']
TypeError: string indices must be integers

2020-09-12 19:43:06,953 -  nornir.core -     INFO -        run() - Running task 'test' with args {} on 6 hosts
2020-09-12 19:43:35,350 -  nornir.core -     INFO -        run() - Running task 'test' with args {} on 6 hosts
2020-09-12 19:43:58,548 -  nornir.core -     INFO -        run() - Running task 'test' with args {} on 6 hosts
2020-09-12 19:48:12,923 -  nornir.core -     INFO -        run() - Running task 'test' with args {} on 6 hosts
2020-09-12 19:48:15,895 - nornir.core.task -    ERROR -      start() - Host 'R2': task 'test' failed with traceback:
Traceback (most recent call last):
  File "/home/eve/PycharmProjects/ospf_enterprise/venv/lib/python3.6/site-packages/nornir/core/task.py", line 85, in start
    r = self.task(self, **self.params)
  File "ospf.py", line 16, in test
    interfaces = task.host['facts']['interfaces']
TypeError: string indices must be integers

2020-09-12 19:48:15,907 - nornir.core.task -    ERROR -      start() - Host 'R4': task 'test' failed with traceback:
Traceback (most recent call last):
  File "/home/eve/PycharmProjects/ospf_enterprise/venv/lib/python3.6/site-packages/nornir/core/task.py", line 85, in start
    r = self.task(self, **self.params)
  File "ospf.py", line 16, in test
    interfaces = task.host['facts']['interfaces']
TypeError: string indices must be integers

2020-09-12 19:48:15,924 - nornir.core.task -    ERROR -      start() - Host 'R7': task 'test' failed with traceback:
Traceback (most recent call last):
  File "/home/eve/PycharmProjects/ospf_enterprise/venv/lib/python3.6/site-packages/nornir/core/task.py", line 85, in start
    r = self.task(self, **self.params)
  File "ospf.py", line 16, in test
    interfaces = task.host['facts']['interfaces']
TypeError: string indices must be integers

2020-09-12 19:48:15,934 - nornir.core.task -    ERROR -      start() - Host 'R1': task 'test' failed with traceback:
Traceback (most recent call last):
  File "/home/eve/PycharmProjects/ospf_enterprise/venv/lib/python3.6/site-packages/nornir/core/task.py", line 85, in start
    r = self.task(self, **self.params)
  File "ospf.py", line 16, in test
    interfaces = task.host['facts']['interfaces']
TypeError: string indices must be integers

2020-09-12 19:48:15,924 - nornir.core.task -    ERROR -      start() - Host 'R8': task 'test' failed with traceback:
Traceback (most recent call last):
  File "/home/eve/PycharmProjects/ospf_enterprise/venv/lib/python3.6/site-packages/nornir/core/task.py", line 85, in start
    r = self.task(self, **self.params)
  File "ospf.py", line 16, in test
    interfaces = task.host['facts']['interfaces']
TypeError: string indices must be integers

2020-09-12 19:48:15,925 - nornir.core.task -    ERROR -      start() - Host 'R3': task 'test' failed with traceback:
Traceback (most recent call last):
  File "/home/eve/PycharmProjects/ospf_enterprise/venv/lib/python3.6/site-packages/nornir/core/task.py", line 85, in start
    r = self.task(self, **self.params)
  File "ospf.py", line 16, in test
    interfaces = task.host['facts']['interfaces']
TypeError: string indices must be integers

2020-09-12 19:53:25,867 -  nornir.core -     INFO -        run() - Running task 'test' with args {} on 6 hosts
2020-09-12 19:53:55,024 -  nornir.core -     INFO -        run() - Running task 'test' with args {} on 6 hosts
2020-09-12 19:55:28,138 -  nornir.core -     INFO -        run() - Running task 'test' with args {} on 6 hosts
2020-09-12 19:55:30,847 - nornir.core.task -    ERROR -      start() - Host 'R8': task 'test' failed with traceback:
Traceback (most recent call last):
  File "/home/eve/PycharmProjects/ospf_enterprise/venv/lib/python3.6/site-packages/nornir/core/task.py", line 85, in start
    r = self.task(self, **self.params)
  File "ospf.py", line 16, in test
    interfaces = task.host['facts']['Interface']
TypeError: string indices must be integers

2020-09-12 19:55:30,852 - nornir.core.task -    ERROR -      start() - Host 'R7': task 'test' failed with traceback:
Traceback (most recent call last):
  File "/home/eve/PycharmProjects/ospf_enterprise/venv/lib/python3.6/site-packages/nornir/core/task.py", line 85, in start
    r = self.task(self, **self.params)
  File "ospf.py", line 16, in test
    interfaces = task.host['facts']['Interface']
TypeError: string indices must be integers

2020-09-12 19:55:30,854 - nornir.core.task -    ERROR -      start() - Host 'R4': task 'test' failed with traceback:
Traceback (most recent call last):
  File "/home/eve/PycharmProjects/ospf_enterprise/venv/lib/python3.6/site-packages/nornir/core/task.py", line 85, in start
    r = self.task(self, **self.params)
  File "ospf.py", line 16, in test
    interfaces = task.host['facts']['Interface']
TypeError: string indices must be integers

2020-09-12 19:55:30,855 - nornir.core.task -    ERROR -      start() - Host 'R2': task 'test' failed with traceback:
Traceback (most recent call last):
  File "/home/eve/PycharmProjects/ospf_enterprise/venv/lib/python3.6/site-packages/nornir/core/task.py", line 85, in start
    r = self.task(self, **self.params)
  File "ospf.py", line 16, in test
    interfaces = task.host['facts']['Interface']
TypeError: string indices must be integers

2020-09-12 19:55:30,855 - nornir.core.task -    ERROR -      start() - Host 'R1': task 'test' failed with traceback:
Traceback (most recent call last):
  File "/home/eve/PycharmProjects/ospf_enterprise/venv/lib/python3.6/site-packages/nornir/core/task.py", line 85, in start
    r = self.task(self, **self.params)
  File "ospf.py", line 16, in test
    interfaces = task.host['facts']['Interface']
TypeError: string indices must be integers

2020-09-12 19:55:30,856 - nornir.core.task -    ERROR -      start() - Host 'R3': task 'test' failed with traceback:
Traceback (most recent call last):
  File "/home/eve/PycharmProjects/ospf_enterprise/venv/lib/python3.6/site-packages/nornir/core/task.py", line 85, in start
    r = self.task(self, **self.params)
  File "ospf.py", line 16, in test
    interfaces = task.host['facts']['Interface']
TypeError: string indices must be integers

2020-09-12 19:55:47,896 -  nornir.core -     INFO -        run() - Running task 'test' with args {} on 6 hosts
2020-09-12 19:55:50,575 - nornir.core.task -    ERROR -      start() - Host 'R7': task 'test' failed with traceback:
Traceback (most recent call last):
  File "/home/eve/PycharmProjects/ospf_enterprise/venv/lib/python3.6/site-packages/nornir/core/task.py", line 85, in start
    r = self.task(self, **self.params)
  File "ospf.py", line 16, in test
    interfaces = task.host['facts']['interfaces']
TypeError: string indices must be integers

2020-09-12 19:55:50,582 - nornir.core.task -    ERROR -      start() - Host 'R4': task 'test' failed with traceback:
Traceback (most recent call last):
  File "/home/eve/PycharmProjects/ospf_enterprise/venv/lib/python3.6/site-packages/nornir/core/task.py", line 85, in start
    r = self.task(self, **self.params)
  File "ospf.py", line 16, in test
    interfaces = task.host['facts']['interfaces']
TypeError: string indices must be integers

2020-09-12 19:55:50,590 - nornir.core.task -    ERROR -      start() - Host 'R1': task 'test' failed with traceback:
Traceback (most recent call last):
  File "/home/eve/PycharmProjects/ospf_enterprise/venv/lib/python3.6/site-packages/nornir/core/task.py", line 85, in start
    r = self.task(self, **self.params)
  File "ospf.py", line 16, in test
    interfaces = task.host['facts']['interfaces']
TypeError: string indices must be integers

2020-09-12 19:55:50,596 - nornir.core.task -    ERROR -      start() - Host 'R2': task 'test' failed with traceback:
Traceback (most recent call last):
  File "/home/eve/PycharmProjects/ospf_enterprise/venv/lib/python3.6/site-packages/nornir/core/task.py", line 85, in start
    r = self.task(self, **self.params)
  File "ospf.py", line 16, in test
    interfaces = task.host['facts']['interfaces']
TypeError: string indices must be integers

2020-09-12 19:55:50,599 - nornir.core.task -    ERROR -      start() - Host 'R8': task 'test' failed with traceback:
Traceback (most recent call last):
  File "/home/eve/PycharmProjects/ospf_enterprise/venv/lib/python3.6/site-packages/nornir/core/task.py", line 85, in start
    r = self.task(self, **self.params)
  File "ospf.py", line 16, in test
    interfaces = task.host['facts']['interfaces']
TypeError: string indices must be integers

2020-09-12 19:55:50,604 - nornir.core.task -    ERROR -      start() - Host 'R3': task 'test' failed with traceback:
Traceback (most recent call last):
  File "/home/eve/PycharmProjects/ospf_enterprise/venv/lib/python3.6/site-packages/nornir/core/task.py", line 85, in start
    r = self.task(self, **self.params)
  File "ospf.py", line 16, in test
    interfaces = task.host['facts']['interfaces']
TypeError: string indices must be integers

2020-09-12 20:11:38,765 -  nornir.core -     INFO -        run() - Running task 'test' with args {} on 6 hosts
2020-09-12 20:11:38,766 -  nornir.core -     INFO -        run() - Running task 'napalm_get' with args {'getters': ['facts']} on 6 hosts
2020-09-12 20:11:38,767 -  nornir.core -     INFO -        run() - Running task 'napalm_get' with args {'getters': ['facts']} on 6 hosts
2020-09-12 20:11:38,773 -  nornir.core -     INFO -        run() - Running task 'napalm_get' with args {'getters': ['facts']} on 6 hosts
2020-09-12 20:11:38,778 -  nornir.core -     INFO -        run() - Running task 'napalm_get' with args {'getters': ['facts']} on 6 hosts
2020-09-12 20:11:38,783 -  nornir.core -     INFO -        run() - Running task 'napalm_get' with args {'getters': ['facts']} on 6 hosts
2020-09-12 20:11:38,820 -  nornir.core -     INFO -        run() - Running task 'napalm_get' with args {'getters': ['facts']} on 6 hosts
2020-09-12 20:11:41,678 - nornir.core.task -    ERROR -      start() - Host 'R1': task 'napalm_get' failed with traceback:
Traceback (most recent call last):
  File "/home/eve/PycharmProjects/ospf_enterprise/venv/lib/python3.6/site-packages/paramiko/transport.py", line 2211, in _check_banner
    buf = self.packetizer.readline(timeout)
  File "/home/eve/PycharmProjects/ospf_enterprise/venv/lib/python3.6/site-packages/paramiko/packet.py", line 380, in readline
    buf += self._read_timeout(timeout)
  File "/home/eve/PycharmProjects/ospf_enterprise/venv/lib/python3.6/site-packages/paramiko/packet.py", line 609, in _read_timeout
    raise EOFError()
EOFError

During handling of the above exception, another exception occurred:

Traceback (most recent call last):
  File "/home/eve/PycharmProjects/ospf_enterprise/venv/lib/python3.6/site-packages/nornir/core/task.py", line 85, in start
    r = self.task(self, **self.params)
  File "/home/eve/PycharmProjects/ospf_enterprise/venv/lib/python3.6/site-packages/nornir/plugins/tasks/networking/napalm_get.py", line 49, in napalm_get
    device = task.host.get_connection("napalm", task.nornir.config)
  File "/home/eve/PycharmProjects/ospf_enterprise/venv/lib/python3.6/site-packages/nornir/core/inventory.py", line 305, in get_connection
    extras=conn.extras,
  File "/home/eve/PycharmProjects/ospf_enterprise/venv/lib/python3.6/site-packages/nornir/core/inventory.py", line 365, in open_connection
    configuration=configuration,
  File "/home/eve/PycharmProjects/ospf_enterprise/venv/lib/python3.6/site-packages/nornir/plugins/connections/napalm.py", line 51, in open
    connection.open()
  File "/home/eve/PycharmProjects/ospf_enterprise/venv/lib/python3.6/site-packages/napalm/ios/ios.py", line 170, in open
    device_type, netmiko_optional_args=self.netmiko_optional_args
  File "/home/eve/PycharmProjects/ospf_enterprise/venv/lib/python3.6/site-packages/napalm/base/base.py", line 92, in _netmiko_open
    **netmiko_optional_args
  File "/home/eve/PycharmProjects/ospf_enterprise/venv/lib/python3.6/site-packages/netmiko/ssh_dispatcher.py", line 302, in ConnectHandler
    return ConnectionClass(*args, **kwargs)
  File "/home/eve/PycharmProjects/ospf_enterprise/venv/lib/python3.6/site-packages/netmiko/cisco/cisco_ios.py", line 17, in __init__
    return super().__init__(*args, **kwargs)
  File "/home/eve/PycharmProjects/ospf_enterprise/venv/lib/python3.6/site-packages/netmiko/base_connection.py", line 344, in __init__
    self._open()
  File "/home/eve/PycharmProjects/ospf_enterprise/venv/lib/python3.6/site-packages/netmiko/base_connection.py", line 349, in _open
    self.establish_connection()
  File "/home/eve/PycharmProjects/ospf_enterprise/venv/lib/python3.6/site-packages/netmiko/base_connection.py", line 918, in establish_connection
    self.remote_conn_pre.connect(**ssh_connect_params)
  File "/home/eve/PycharmProjects/ospf_enterprise/venv/lib/python3.6/site-packages/paramiko/client.py", line 406, in connect
    t.start_client(timeout=timeout)
  File "/home/eve/PycharmProjects/ospf_enterprise/venv/lib/python3.6/site-packages/paramiko/transport.py", line 660, in start_client
    raise e
  File "/home/eve/PycharmProjects/ospf_enterprise/venv/lib/python3.6/site-packages/paramiko/transport.py", line 2039, in run
    self._check_banner()
  File "/home/eve/PycharmProjects/ospf_enterprise/venv/lib/python3.6/site-packages/paramiko/transport.py", line 2216, in _check_banner
    "Error reading SSH protocol banner" + str(e)
paramiko.ssh_exception.SSHException: Error reading SSH protocol banner

2020-09-12 20:11:41,698 - nornir.core.task -    ERROR -      start() - Host 'R3': task 'napalm_get' failed with traceback:
Traceback (most recent call last):
  File "/home/eve/PycharmProjects/ospf_enterprise/venv/lib/python3.6/site-packages/netmiko/base_connection.py", line 918, in establish_connection
    self.remote_conn_pre.connect(**ssh_connect_params)
  File "/home/eve/PycharmProjects/ospf_enterprise/venv/lib/python3.6/site-packages/paramiko/client.py", line 368, in connect
    raise NoValidConnectionsError(errors)
paramiko.ssh_exception.NoValidConnectionsError: [Errno None] Unable to connect to port 22 on 10.0.34.3

During handling of the above exception, another exception occurred:

Traceback (most recent call last):
  File "/home/eve/PycharmProjects/ospf_enterprise/venv/lib/python3.6/site-packages/napalm/base/base.py", line 92, in _netmiko_open
    **netmiko_optional_args
  File "/home/eve/PycharmProjects/ospf_enterprise/venv/lib/python3.6/site-packages/netmiko/ssh_dispatcher.py", line 302, in ConnectHandler
    return ConnectionClass(*args, **kwargs)
  File "/home/eve/PycharmProjects/ospf_enterprise/venv/lib/python3.6/site-packages/netmiko/cisco/cisco_ios.py", line 17, in __init__
    return super().__init__(*args, **kwargs)
  File "/home/eve/PycharmProjects/ospf_enterprise/venv/lib/python3.6/site-packages/netmiko/base_connection.py", line 344, in __init__
    self._open()
  File "/home/eve/PycharmProjects/ospf_enterprise/venv/lib/python3.6/site-packages/netmiko/base_connection.py", line 349, in _open
    self.establish_connection()
  File "/home/eve/PycharmProjects/ospf_enterprise/venv/lib/python3.6/site-packages/netmiko/base_connection.py", line 940, in establish_connection
    raise NetmikoTimeoutException(msg)
netmiko.ssh_exception.NetmikoTimeoutException: TCP connection to device failed.

Common causes of this problem are:
1. Incorrect hostname or IP address.
2. Wrong TCP port.
3. Intermediate firewall blocking access.

Device settings: cisco_ios 10.0.34.3:22



During handling of the above exception, another exception occurred:

Traceback (most recent call last):
  File "/home/eve/PycharmProjects/ospf_enterprise/venv/lib/python3.6/site-packages/nornir/core/task.py", line 85, in start
    r = self.task(self, **self.params)
  File "/home/eve/PycharmProjects/ospf_enterprise/venv/lib/python3.6/site-packages/nornir/plugins/tasks/networking/napalm_get.py", line 49, in napalm_get
    device = task.host.get_connection("napalm", task.nornir.config)
  File "/home/eve/PycharmProjects/ospf_enterprise/venv/lib/python3.6/site-packages/nornir/core/inventory.py", line 305, in get_connection
    extras=conn.extras,
  File "/home/eve/PycharmProjects/ospf_enterprise/venv/lib/python3.6/site-packages/nornir/core/inventory.py", line 365, in open_connection
    configuration=configuration,
  File "/home/eve/PycharmProjects/ospf_enterprise/venv/lib/python3.6/site-packages/nornir/plugins/connections/napalm.py", line 51, in open
    connection.open()
  File "/home/eve/PycharmProjects/ospf_enterprise/venv/lib/python3.6/site-packages/napalm/ios/ios.py", line 170, in open
    device_type, netmiko_optional_args=self.netmiko_optional_args
  File "/home/eve/PycharmProjects/ospf_enterprise/venv/lib/python3.6/site-packages/napalm/base/base.py", line 95, in _netmiko_open
    raise ConnectionException("Cannot connect to {}".format(self.hostname))
napalm.base.exceptions.ConnectionException: Cannot connect to 10.0.34.3

2020-09-12 20:11:42,104 - nornir.core.task -    ERROR -      start() - Host 'R7': task 'napalm_get' failed with traceback:
Traceback (most recent call last):
  File "/home/eve/PycharmProjects/ospf_enterprise/venv/lib/python3.6/site-packages/paramiko/transport.py", line 2211, in _check_banner
    buf = self.packetizer.readline(timeout)
  File "/home/eve/PycharmProjects/ospf_enterprise/venv/lib/python3.6/site-packages/paramiko/packet.py", line 380, in readline
    buf += self._read_timeout(timeout)
  File "/home/eve/PycharmProjects/ospf_enterprise/venv/lib/python3.6/site-packages/paramiko/packet.py", line 609, in _read_timeout
    raise EOFError()
EOFError

During handling of the above exception, another exception occurred:

Traceback (most recent call last):
  File "/home/eve/PycharmProjects/ospf_enterprise/venv/lib/python3.6/site-packages/nornir/core/task.py", line 85, in start
    r = self.task(self, **self.params)
  File "/home/eve/PycharmProjects/ospf_enterprise/venv/lib/python3.6/site-packages/nornir/plugins/tasks/networking/napalm_get.py", line 49, in napalm_get
    device = task.host.get_connection("napalm", task.nornir.config)
  File "/home/eve/PycharmProjects/ospf_enterprise/venv/lib/python3.6/site-packages/nornir/core/inventory.py", line 305, in get_connection
    extras=conn.extras,
  File "/home/eve/PycharmProjects/ospf_enterprise/venv/lib/python3.6/site-packages/nornir/core/inventory.py", line 365, in open_connection
    configuration=configuration,
  File "/home/eve/PycharmProjects/ospf_enterprise/venv/lib/python3.6/site-packages/nornir/plugins/connections/napalm.py", line 51, in open
    connection.open()
  File "/home/eve/PycharmProjects/ospf_enterprise/venv/lib/python3.6/site-packages/napalm/ios/ios.py", line 170, in open
    device_type, netmiko_optional_args=self.netmiko_optional_args
  File "/home/eve/PycharmProjects/ospf_enterprise/venv/lib/python3.6/site-packages/napalm/base/base.py", line 92, in _netmiko_open
    **netmiko_optional_args
  File "/home/eve/PycharmProjects/ospf_enterprise/venv/lib/python3.6/site-packages/netmiko/ssh_dispatcher.py", line 302, in ConnectHandler
    return ConnectionClass(*args, **kwargs)
  File "/home/eve/PycharmProjects/ospf_enterprise/venv/lib/python3.6/site-packages/netmiko/cisco/cisco_ios.py", line 17, in __init__
    return super().__init__(*args, **kwargs)
  File "/home/eve/PycharmProjects/ospf_enterprise/venv/lib/python3.6/site-packages/netmiko/base_connection.py", line 344, in __init__
    self._open()
  File "/home/eve/PycharmProjects/ospf_enterprise/venv/lib/python3.6/site-packages/netmiko/base_connection.py", line 349, in _open
    self.establish_connection()
  File "/home/eve/PycharmProjects/ospf_enterprise/venv/lib/python3.6/site-packages/netmiko/base_connection.py", line 918, in establish_connection
    self.remote_conn_pre.connect(**ssh_connect_params)
  File "/home/eve/PycharmProjects/ospf_enterprise/venv/lib/python3.6/site-packages/paramiko/client.py", line 406, in connect
    t.start_client(timeout=timeout)
  File "/home/eve/PycharmProjects/ospf_enterprise/venv/lib/python3.6/site-packages/paramiko/transport.py", line 660, in start_client
    raise e
  File "/home/eve/PycharmProjects/ospf_enterprise/venv/lib/python3.6/site-packages/paramiko/transport.py", line 2039, in run
    self._check_banner()
  File "/home/eve/PycharmProjects/ospf_enterprise/venv/lib/python3.6/site-packages/paramiko/transport.py", line 2216, in _check_banner
    "Error reading SSH protocol banner" + str(e)
paramiko.ssh_exception.SSHException: Error reading SSH protocol banner

2020-09-12 20:11:42,344 - nornir.core.task -    ERROR -      start() - Host 'R8': task 'napalm_get' failed with traceback:
Traceback (most recent call last):
  File "/home/eve/PycharmProjects/ospf_enterprise/venv/lib/python3.6/site-packages/paramiko/transport.py", line 2211, in _check_banner
    buf = self.packetizer.readline(timeout)
  File "/home/eve/PycharmProjects/ospf_enterprise/venv/lib/python3.6/site-packages/paramiko/packet.py", line 380, in readline
    buf += self._read_timeout(timeout)
  File "/home/eve/PycharmProjects/ospf_enterprise/venv/lib/python3.6/site-packages/paramiko/packet.py", line 609, in _read_timeout
    raise EOFError()
EOFError

During handling of the above exception, another exception occurred:

Traceback (most recent call last):
  File "/home/eve/PycharmProjects/ospf_enterprise/venv/lib/python3.6/site-packages/nornir/core/task.py", line 85, in start
    r = self.task(self, **self.params)
  File "/home/eve/PycharmProjects/ospf_enterprise/venv/lib/python3.6/site-packages/nornir/plugins/tasks/networking/napalm_get.py", line 49, in napalm_get
    device = task.host.get_connection("napalm", task.nornir.config)
  File "/home/eve/PycharmProjects/ospf_enterprise/venv/lib/python3.6/site-packages/nornir/core/inventory.py", line 305, in get_connection
    extras=conn.extras,
  File "/home/eve/PycharmProjects/ospf_enterprise/venv/lib/python3.6/site-packages/nornir/core/inventory.py", line 365, in open_connection
    configuration=configuration,
  File "/home/eve/PycharmProjects/ospf_enterprise/venv/lib/python3.6/site-packages/nornir/plugins/connections/napalm.py", line 51, in open
    connection.open()
  File "/home/eve/PycharmProjects/ospf_enterprise/venv/lib/python3.6/site-packages/napalm/ios/ios.py", line 170, in open
    device_type, netmiko_optional_args=self.netmiko_optional_args
  File "/home/eve/PycharmProjects/ospf_enterprise/venv/lib/python3.6/site-packages/napalm/base/base.py", line 92, in _netmiko_open
    **netmiko_optional_args
  File "/home/eve/PycharmProjects/ospf_enterprise/venv/lib/python3.6/site-packages/netmiko/ssh_dispatcher.py", line 302, in ConnectHandler
    return ConnectionClass(*args, **kwargs)
  File "/home/eve/PycharmProjects/ospf_enterprise/venv/lib/python3.6/site-packages/netmiko/cisco/cisco_ios.py", line 17, in __init__
    return super().__init__(*args, **kwargs)
  File "/home/eve/PycharmProjects/ospf_enterprise/venv/lib/python3.6/site-packages/netmiko/base_connection.py", line 344, in __init__
    self._open()
  File "/home/eve/PycharmProjects/ospf_enterprise/venv/lib/python3.6/site-packages/netmiko/base_connection.py", line 349, in _open
    self.establish_connection()
  File "/home/eve/PycharmProjects/ospf_enterprise/venv/lib/python3.6/site-packages/netmiko/base_connection.py", line 918, in establish_connection
    self.remote_conn_pre.connect(**ssh_connect_params)
  File "/home/eve/PycharmProjects/ospf_enterprise/venv/lib/python3.6/site-packages/paramiko/client.py", line 406, in connect
    t.start_client(timeout=timeout)
  File "/home/eve/PycharmProjects/ospf_enterprise/venv/lib/python3.6/site-packages/paramiko/transport.py", line 660, in start_client
    raise e
  File "/home/eve/PycharmProjects/ospf_enterprise/venv/lib/python3.6/site-packages/paramiko/transport.py", line 2039, in run
    self._check_banner()
  File "/home/eve/PycharmProjects/ospf_enterprise/venv/lib/python3.6/site-packages/paramiko/transport.py", line 2216, in _check_banner
    "Error reading SSH protocol banner" + str(e)
paramiko.ssh_exception.SSHException: Error reading SSH protocol banner

2020-09-12 20:11:43,052 - nornir.core.task -    ERROR -      start() - Host 'R2': task 'napalm_get' failed with traceback:
Traceback (most recent call last):
  File "/home/eve/PycharmProjects/ospf_enterprise/venv/lib/python3.6/site-packages/netmiko/base_connection.py", line 918, in establish_connection
    self.remote_conn_pre.connect(**ssh_connect_params)
  File "/home/eve/PycharmProjects/ospf_enterprise/venv/lib/python3.6/site-packages/paramiko/client.py", line 368, in connect
    raise NoValidConnectionsError(errors)
paramiko.ssh_exception.NoValidConnectionsError: [Errno None] Unable to connect to port 22 on 10.0.12.2

During handling of the above exception, another exception occurred:

Traceback (most recent call last):
  File "/home/eve/PycharmProjects/ospf_enterprise/venv/lib/python3.6/site-packages/napalm/base/base.py", line 92, in _netmiko_open
    **netmiko_optional_args
  File "/home/eve/PycharmProjects/ospf_enterprise/venv/lib/python3.6/site-packages/netmiko/ssh_dispatcher.py", line 302, in ConnectHandler
    return ConnectionClass(*args, **kwargs)
  File "/home/eve/PycharmProjects/ospf_enterprise/venv/lib/python3.6/site-packages/netmiko/cisco/cisco_ios.py", line 17, in __init__
    return super().__init__(*args, **kwargs)
  File "/home/eve/PycharmProjects/ospf_enterprise/venv/lib/python3.6/site-packages/netmiko/base_connection.py", line 344, in __init__
    self._open()
  File "/home/eve/PycharmProjects/ospf_enterprise/venv/lib/python3.6/site-packages/netmiko/base_connection.py", line 349, in _open
    self.establish_connection()
  File "/home/eve/PycharmProjects/ospf_enterprise/venv/lib/python3.6/site-packages/netmiko/base_connection.py", line 940, in establish_connection
    raise NetmikoTimeoutException(msg)
netmiko.ssh_exception.NetmikoTimeoutException: TCP connection to device failed.

Common causes of this problem are:
1. Incorrect hostname or IP address.
2. Wrong TCP port.
3. Intermediate firewall blocking access.

Device settings: cisco_ios 10.0.12.2:22



During handling of the above exception, another exception occurred:

Traceback (most recent call last):
  File "/home/eve/PycharmProjects/ospf_enterprise/venv/lib/python3.6/site-packages/nornir/core/task.py", line 85, in start
    r = self.task(self, **self.params)
  File "/home/eve/PycharmProjects/ospf_enterprise/venv/lib/python3.6/site-packages/nornir/plugins/tasks/networking/napalm_get.py", line 49, in napalm_get
    device = task.host.get_connection("napalm", task.nornir.config)
  File "/home/eve/PycharmProjects/ospf_enterprise/venv/lib/python3.6/site-packages/nornir/core/inventory.py", line 305, in get_connection
    extras=conn.extras,
  File "/home/eve/PycharmProjects/ospf_enterprise/venv/lib/python3.6/site-packages/nornir/core/inventory.py", line 365, in open_connection
    configuration=configuration,
  File "/home/eve/PycharmProjects/ospf_enterprise/venv/lib/python3.6/site-packages/nornir/plugins/connections/napalm.py", line 51, in open
    connection.open()
  File "/home/eve/PycharmProjects/ospf_enterprise/venv/lib/python3.6/site-packages/napalm/ios/ios.py", line 170, in open
    device_type, netmiko_optional_args=self.netmiko_optional_args
  File "/home/eve/PycharmProjects/ospf_enterprise/venv/lib/python3.6/site-packages/napalm/base/base.py", line 95, in _netmiko_open
    raise ConnectionException("Cannot connect to {}".format(self.hostname))
napalm.base.exceptions.ConnectionException: Cannot connect to 10.0.12.2

2020-09-12 20:11:43,067 - nornir.core.task -    ERROR -      start() - Host 'R4': task 'napalm_get' failed with traceback:
Traceback (most recent call last):
  File "/home/eve/PycharmProjects/ospf_enterprise/venv/lib/python3.6/site-packages/paramiko/transport.py", line 2211, in _check_banner
    buf = self.packetizer.readline(timeout)
  File "/home/eve/PycharmProjects/ospf_enterprise/venv/lib/python3.6/site-packages/paramiko/packet.py", line 380, in readline
    buf += self._read_timeout(timeout)
  File "/home/eve/PycharmProjects/ospf_enterprise/venv/lib/python3.6/site-packages/paramiko/packet.py", line 609, in _read_timeout
    raise EOFError()
EOFError

During handling of the above exception, another exception occurred:

Traceback (most recent call last):
  File "/home/eve/PycharmProjects/ospf_enterprise/venv/lib/python3.6/site-packages/nornir/core/task.py", line 85, in start
    r = self.task(self, **self.params)
  File "/home/eve/PycharmProjects/ospf_enterprise/venv/lib/python3.6/site-packages/nornir/plugins/tasks/networking/napalm_get.py", line 49, in napalm_get
    device = task.host.get_connection("napalm", task.nornir.config)
  File "/home/eve/PycharmProjects/ospf_enterprise/venv/lib/python3.6/site-packages/nornir/core/inventory.py", line 305, in get_connection
    extras=conn.extras,
  File "/home/eve/PycharmProjects/ospf_enterprise/venv/lib/python3.6/site-packages/nornir/core/inventory.py", line 365, in open_connection
    configuration=configuration,
  File "/home/eve/PycharmProjects/ospf_enterprise/venv/lib/python3.6/site-packages/nornir/plugins/connections/napalm.py", line 51, in open
    connection.open()
  File "/home/eve/PycharmProjects/ospf_enterprise/venv/lib/python3.6/site-packages/napalm/ios/ios.py", line 170, in open
    device_type, netmiko_optional_args=self.netmiko_optional_args
  File "/home/eve/PycharmProjects/ospf_enterprise/venv/lib/python3.6/site-packages/napalm/base/base.py", line 92, in _netmiko_open
    **netmiko_optional_args
  File "/home/eve/PycharmProjects/ospf_enterprise/venv/lib/python3.6/site-packages/netmiko/ssh_dispatcher.py", line 302, in ConnectHandler
    return ConnectionClass(*args, **kwargs)
  File "/home/eve/PycharmProjects/ospf_enterprise/venv/lib/python3.6/site-packages/netmiko/cisco/cisco_ios.py", line 17, in __init__
    return super().__init__(*args, **kwargs)
  File "/home/eve/PycharmProjects/ospf_enterprise/venv/lib/python3.6/site-packages/netmiko/base_connection.py", line 344, in __init__
    self._open()
  File "/home/eve/PycharmProjects/ospf_enterprise/venv/lib/python3.6/site-packages/netmiko/base_connection.py", line 349, in _open
    self.establish_connection()
  File "/home/eve/PycharmProjects/ospf_enterprise/venv/lib/python3.6/site-packages/netmiko/base_connection.py", line 918, in establish_connection
    self.remote_conn_pre.connect(**ssh_connect_params)
  File "/home/eve/PycharmProjects/ospf_enterprise/venv/lib/python3.6/site-packages/paramiko/client.py", line 406, in connect
    t.start_client(timeout=timeout)
  File "/home/eve/PycharmProjects/ospf_enterprise/venv/lib/python3.6/site-packages/paramiko/transport.py", line 660, in start_client
    raise e
  File "/home/eve/PycharmProjects/ospf_enterprise/venv/lib/python3.6/site-packages/paramiko/transport.py", line 2039, in run
    self._check_banner()
  File "/home/eve/PycharmProjects/ospf_enterprise/venv/lib/python3.6/site-packages/paramiko/transport.py", line 2216, in _check_banner
    "Error reading SSH protocol banner" + str(e)
paramiko.ssh_exception.SSHException: Error reading SSH protocol banner

2020-09-12 20:12:43,615 -  nornir.core -     INFO -        run() - Running task 'test' with args {} on 6 hosts
2020-09-12 20:12:43,616 -  nornir.core -     INFO -        run() - Running task 'napalm_get' with args {'getters': ['facts']} on 6 hosts
2020-09-12 20:12:43,617 -  nornir.core -     INFO -        run() - Running task 'napalm_get' with args {'getters': ['facts']} on 6 hosts
2020-09-12 20:12:43,620 -  nornir.core -     INFO -        run() - Running task 'napalm_get' with args {'getters': ['facts']} on 6 hosts
2020-09-12 20:12:43,626 -  nornir.core -     INFO -        run() - Running task 'napalm_get' with args {'getters': ['facts']} on 6 hosts
2020-09-12 20:12:43,638 -  nornir.core -     INFO -        run() - Running task 'napalm_get' with args {'getters': ['facts']} on 6 hosts
2020-09-12 20:12:43,642 -  nornir.core -     INFO -        run() - Running task 'napalm_get' with args {'getters': ['facts']} on 6 hosts
2020-09-12 20:12:44,052 - nornir.core.task -    ERROR -      start() - Host 'R4': task 'napalm_get' failed with traceback:
Traceback (most recent call last):
  File "/home/eve/PycharmProjects/ospf_enterprise/venv/lib/python3.6/site-packages/paramiko/transport.py", line 2211, in _check_banner
    buf = self.packetizer.readline(timeout)
  File "/home/eve/PycharmProjects/ospf_enterprise/venv/lib/python3.6/site-packages/paramiko/packet.py", line 380, in readline
    buf += self._read_timeout(timeout)
  File "/home/eve/PycharmProjects/ospf_enterprise/venv/lib/python3.6/site-packages/paramiko/packet.py", line 609, in _read_timeout
    raise EOFError()
EOFError

During handling of the above exception, another exception occurred:

Traceback (most recent call last):
  File "/home/eve/PycharmProjects/ospf_enterprise/venv/lib/python3.6/site-packages/nornir/core/task.py", line 85, in start
    r = self.task(self, **self.params)
  File "/home/eve/PycharmProjects/ospf_enterprise/venv/lib/python3.6/site-packages/nornir/plugins/tasks/networking/napalm_get.py", line 49, in napalm_get
    device = task.host.get_connection("napalm", task.nornir.config)
  File "/home/eve/PycharmProjects/ospf_enterprise/venv/lib/python3.6/site-packages/nornir/core/inventory.py", line 305, in get_connection
    extras=conn.extras,
  File "/home/eve/PycharmProjects/ospf_enterprise/venv/lib/python3.6/site-packages/nornir/core/inventory.py", line 365, in open_connection
    configuration=configuration,
  File "/home/eve/PycharmProjects/ospf_enterprise/venv/lib/python3.6/site-packages/nornir/plugins/connections/napalm.py", line 51, in open
    connection.open()
  File "/home/eve/PycharmProjects/ospf_enterprise/venv/lib/python3.6/site-packages/napalm/ios/ios.py", line 170, in open
    device_type, netmiko_optional_args=self.netmiko_optional_args
  File "/home/eve/PycharmProjects/ospf_enterprise/venv/lib/python3.6/site-packages/napalm/base/base.py", line 92, in _netmiko_open
    **netmiko_optional_args
  File "/home/eve/PycharmProjects/ospf_enterprise/venv/lib/python3.6/site-packages/netmiko/ssh_dispatcher.py", line 302, in ConnectHandler
    return ConnectionClass(*args, **kwargs)
  File "/home/eve/PycharmProjects/ospf_enterprise/venv/lib/python3.6/site-packages/netmiko/cisco/cisco_ios.py", line 17, in __init__
    return super().__init__(*args, **kwargs)
  File "/home/eve/PycharmProjects/ospf_enterprise/venv/lib/python3.6/site-packages/netmiko/base_connection.py", line 344, in __init__
    self._open()
  File "/home/eve/PycharmProjects/ospf_enterprise/venv/lib/python3.6/site-packages/netmiko/base_connection.py", line 349, in _open
    self.establish_connection()
  File "/home/eve/PycharmProjects/ospf_enterprise/venv/lib/python3.6/site-packages/netmiko/base_connection.py", line 918, in establish_connection
    self.remote_conn_pre.connect(**ssh_connect_params)
  File "/home/eve/PycharmProjects/ospf_enterprise/venv/lib/python3.6/site-packages/paramiko/client.py", line 406, in connect
    t.start_client(timeout=timeout)
  File "/home/eve/PycharmProjects/ospf_enterprise/venv/lib/python3.6/site-packages/paramiko/transport.py", line 660, in start_client
    raise e
  File "/home/eve/PycharmProjects/ospf_enterprise/venv/lib/python3.6/site-packages/paramiko/transport.py", line 2039, in run
    self._check_banner()
  File "/home/eve/PycharmProjects/ospf_enterprise/venv/lib/python3.6/site-packages/paramiko/transport.py", line 2216, in _check_banner
    "Error reading SSH protocol banner" + str(e)
paramiko.ssh_exception.SSHException: Error reading SSH protocol banner

2020-09-12 20:12:44,066 - nornir.core.task -    ERROR -      start() - Host 'R8': task 'napalm_get' failed with traceback:
Traceback (most recent call last):
  File "/home/eve/PycharmProjects/ospf_enterprise/venv/lib/python3.6/site-packages/paramiko/transport.py", line 2211, in _check_banner
    buf = self.packetizer.readline(timeout)
  File "/home/eve/PycharmProjects/ospf_enterprise/venv/lib/python3.6/site-packages/paramiko/packet.py", line 380, in readline
    buf += self._read_timeout(timeout)
  File "/home/eve/PycharmProjects/ospf_enterprise/venv/lib/python3.6/site-packages/paramiko/packet.py", line 609, in _read_timeout
    raise EOFError()
EOFError

During handling of the above exception, another exception occurred:

Traceback (most recent call last):
  File "/home/eve/PycharmProjects/ospf_enterprise/venv/lib/python3.6/site-packages/nornir/core/task.py", line 85, in start
    r = self.task(self, **self.params)
  File "/home/eve/PycharmProjects/ospf_enterprise/venv/lib/python3.6/site-packages/nornir/plugins/tasks/networking/napalm_get.py", line 49, in napalm_get
    device = task.host.get_connection("napalm", task.nornir.config)
  File "/home/eve/PycharmProjects/ospf_enterprise/venv/lib/python3.6/site-packages/nornir/core/inventory.py", line 305, in get_connection
    extras=conn.extras,
  File "/home/eve/PycharmProjects/ospf_enterprise/venv/lib/python3.6/site-packages/nornir/core/inventory.py", line 365, in open_connection
    configuration=configuration,
  File "/home/eve/PycharmProjects/ospf_enterprise/venv/lib/python3.6/site-packages/nornir/plugins/connections/napalm.py", line 51, in open
    connection.open()
  File "/home/eve/PycharmProjects/ospf_enterprise/venv/lib/python3.6/site-packages/napalm/ios/ios.py", line 170, in open
    device_type, netmiko_optional_args=self.netmiko_optional_args
  File "/home/eve/PycharmProjects/ospf_enterprise/venv/lib/python3.6/site-packages/napalm/base/base.py", line 92, in _netmiko_open
    **netmiko_optional_args
  File "/home/eve/PycharmProjects/ospf_enterprise/venv/lib/python3.6/site-packages/netmiko/ssh_dispatcher.py", line 302, in ConnectHandler
    return ConnectionClass(*args, **kwargs)
  File "/home/eve/PycharmProjects/ospf_enterprise/venv/lib/python3.6/site-packages/netmiko/cisco/cisco_ios.py", line 17, in __init__
    return super().__init__(*args, **kwargs)
  File "/home/eve/PycharmProjects/ospf_enterprise/venv/lib/python3.6/site-packages/netmiko/base_connection.py", line 344, in __init__
    self._open()
  File "/home/eve/PycharmProjects/ospf_enterprise/venv/lib/python3.6/site-packages/netmiko/base_connection.py", line 349, in _open
    self.establish_connection()
  File "/home/eve/PycharmProjects/ospf_enterprise/venv/lib/python3.6/site-packages/netmiko/base_connection.py", line 918, in establish_connection
    self.remote_conn_pre.connect(**ssh_connect_params)
  File "/home/eve/PycharmProjects/ospf_enterprise/venv/lib/python3.6/site-packages/paramiko/client.py", line 406, in connect
    t.start_client(timeout=timeout)
  File "/home/eve/PycharmProjects/ospf_enterprise/venv/lib/python3.6/site-packages/paramiko/transport.py", line 660, in start_client
    raise e
  File "/home/eve/PycharmProjects/ospf_enterprise/venv/lib/python3.6/site-packages/paramiko/transport.py", line 2039, in run
    self._check_banner()
  File "/home/eve/PycharmProjects/ospf_enterprise/venv/lib/python3.6/site-packages/paramiko/transport.py", line 2216, in _check_banner
    "Error reading SSH protocol banner" + str(e)
paramiko.ssh_exception.SSHException: Error reading SSH protocol banner

2020-09-12 20:12:44,075 - nornir.core.task -    ERROR -      start() - Host 'R1': task 'napalm_get' failed with traceback:
Traceback (most recent call last):
  File "/home/eve/PycharmProjects/ospf_enterprise/venv/lib/python3.6/site-packages/paramiko/transport.py", line 2211, in _check_banner
    buf = self.packetizer.readline(timeout)
  File "/home/eve/PycharmProjects/ospf_enterprise/venv/lib/python3.6/site-packages/paramiko/packet.py", line 380, in readline
    buf += self._read_timeout(timeout)
  File "/home/eve/PycharmProjects/ospf_enterprise/venv/lib/python3.6/site-packages/paramiko/packet.py", line 609, in _read_timeout
    raise EOFError()
EOFError

During handling of the above exception, another exception occurred:

Traceback (most recent call last):
  File "/home/eve/PycharmProjects/ospf_enterprise/venv/lib/python3.6/site-packages/nornir/core/task.py", line 85, in start
    r = self.task(self, **self.params)
  File "/home/eve/PycharmProjects/ospf_enterprise/venv/lib/python3.6/site-packages/nornir/plugins/tasks/networking/napalm_get.py", line 49, in napalm_get
    device = task.host.get_connection("napalm", task.nornir.config)
  File "/home/eve/PycharmProjects/ospf_enterprise/venv/lib/python3.6/site-packages/nornir/core/inventory.py", line 305, in get_connection
    extras=conn.extras,
  File "/home/eve/PycharmProjects/ospf_enterprise/venv/lib/python3.6/site-packages/nornir/core/inventory.py", line 365, in open_connection
    configuration=configuration,
  File "/home/eve/PycharmProjects/ospf_enterprise/venv/lib/python3.6/site-packages/nornir/plugins/connections/napalm.py", line 51, in open
    connection.open()
  File "/home/eve/PycharmProjects/ospf_enterprise/venv/lib/python3.6/site-packages/napalm/ios/ios.py", line 170, in open
    device_type, netmiko_optional_args=self.netmiko_optional_args
  File "/home/eve/PycharmProjects/ospf_enterprise/venv/lib/python3.6/site-packages/napalm/base/base.py", line 92, in _netmiko_open
    **netmiko_optional_args
  File "/home/eve/PycharmProjects/ospf_enterprise/venv/lib/python3.6/site-packages/netmiko/ssh_dispatcher.py", line 302, in ConnectHandler
    return ConnectionClass(*args, **kwargs)
  File "/home/eve/PycharmProjects/ospf_enterprise/venv/lib/python3.6/site-packages/netmiko/cisco/cisco_ios.py", line 17, in __init__
    return super().__init__(*args, **kwargs)
  File "/home/eve/PycharmProjects/ospf_enterprise/venv/lib/python3.6/site-packages/netmiko/base_connection.py", line 344, in __init__
    self._open()
  File "/home/eve/PycharmProjects/ospf_enterprise/venv/lib/python3.6/site-packages/netmiko/base_connection.py", line 349, in _open
    self.establish_connection()
  File "/home/eve/PycharmProjects/ospf_enterprise/venv/lib/python3.6/site-packages/netmiko/base_connection.py", line 918, in establish_connection
    self.remote_conn_pre.connect(**ssh_connect_params)
  File "/home/eve/PycharmProjects/ospf_enterprise/venv/lib/python3.6/site-packages/paramiko/client.py", line 406, in connect
    t.start_client(timeout=timeout)
  File "/home/eve/PycharmProjects/ospf_enterprise/venv/lib/python3.6/site-packages/paramiko/transport.py", line 660, in start_client
    raise e
  File "/home/eve/PycharmProjects/ospf_enterprise/venv/lib/python3.6/site-packages/paramiko/transport.py", line 2039, in run
    self._check_banner()
  File "/home/eve/PycharmProjects/ospf_enterprise/venv/lib/python3.6/site-packages/paramiko/transport.py", line 2216, in _check_banner
    "Error reading SSH protocol banner" + str(e)
paramiko.ssh_exception.SSHException: Error reading SSH protocol banner

2020-09-12 20:12:44,078 - nornir.core.task -    ERROR -      start() - Host 'R2': task 'napalm_get' failed with traceback:
Traceback (most recent call last):
  File "/home/eve/PycharmProjects/ospf_enterprise/venv/lib/python3.6/site-packages/paramiko/transport.py", line 2211, in _check_banner
    buf = self.packetizer.readline(timeout)
  File "/home/eve/PycharmProjects/ospf_enterprise/venv/lib/python3.6/site-packages/paramiko/packet.py", line 380, in readline
    buf += self._read_timeout(timeout)
  File "/home/eve/PycharmProjects/ospf_enterprise/venv/lib/python3.6/site-packages/paramiko/packet.py", line 609, in _read_timeout
    raise EOFError()
EOFError

During handling of the above exception, another exception occurred:

Traceback (most recent call last):
  File "/home/eve/PycharmProjects/ospf_enterprise/venv/lib/python3.6/site-packages/nornir/core/task.py", line 85, in start
    r = self.task(self, **self.params)
  File "/home/eve/PycharmProjects/ospf_enterprise/venv/lib/python3.6/site-packages/nornir/plugins/tasks/networking/napalm_get.py", line 49, in napalm_get
    device = task.host.get_connection("napalm", task.nornir.config)
  File "/home/eve/PycharmProjects/ospf_enterprise/venv/lib/python3.6/site-packages/nornir/core/inventory.py", line 305, in get_connection
    extras=conn.extras,
  File "/home/eve/PycharmProjects/ospf_enterprise/venv/lib/python3.6/site-packages/nornir/core/inventory.py", line 365, in open_connection
    configuration=configuration,
  File "/home/eve/PycharmProjects/ospf_enterprise/venv/lib/python3.6/site-packages/nornir/plugins/connections/napalm.py", line 51, in open
    connection.open()
  File "/home/eve/PycharmProjects/ospf_enterprise/venv/lib/python3.6/site-packages/napalm/ios/ios.py", line 170, in open
    device_type, netmiko_optional_args=self.netmiko_optional_args
  File "/home/eve/PycharmProjects/ospf_enterprise/venv/lib/python3.6/site-packages/napalm/base/base.py", line 92, in _netmiko_open
    **netmiko_optional_args
  File "/home/eve/PycharmProjects/ospf_enterprise/venv/lib/python3.6/site-packages/netmiko/ssh_dispatcher.py", line 302, in ConnectHandler
    return ConnectionClass(*args, **kwargs)
  File "/home/eve/PycharmProjects/ospf_enterprise/venv/lib/python3.6/site-packages/netmiko/cisco/cisco_ios.py", line 17, in __init__
    return super().__init__(*args, **kwargs)
  File "/home/eve/PycharmProjects/ospf_enterprise/venv/lib/python3.6/site-packages/netmiko/base_connection.py", line 344, in __init__
    self._open()
  File "/home/eve/PycharmProjects/ospf_enterprise/venv/lib/python3.6/site-packages/netmiko/base_connection.py", line 349, in _open
    self.establish_connection()
  File "/home/eve/PycharmProjects/ospf_enterprise/venv/lib/python3.6/site-packages/netmiko/base_connection.py", line 918, in establish_connection
    self.remote_conn_pre.connect(**ssh_connect_params)
  File "/home/eve/PycharmProjects/ospf_enterprise/venv/lib/python3.6/site-packages/paramiko/client.py", line 406, in connect
    t.start_client(timeout=timeout)
  File "/home/eve/PycharmProjects/ospf_enterprise/venv/lib/python3.6/site-packages/paramiko/transport.py", line 660, in start_client
    raise e
  File "/home/eve/PycharmProjects/ospf_enterprise/venv/lib/python3.6/site-packages/paramiko/transport.py", line 2039, in run
    self._check_banner()
  File "/home/eve/PycharmProjects/ospf_enterprise/venv/lib/python3.6/site-packages/paramiko/transport.py", line 2216, in _check_banner
    "Error reading SSH protocol banner" + str(e)
paramiko.ssh_exception.SSHException: Error reading SSH protocol banner

2020-09-12 20:12:44,093 - nornir.core.task -    ERROR -      start() - Host 'R3': task 'napalm_get' failed with traceback:
Traceback (most recent call last):
  File "/home/eve/PycharmProjects/ospf_enterprise/venv/lib/python3.6/site-packages/paramiko/transport.py", line 2211, in _check_banner
    buf = self.packetizer.readline(timeout)
  File "/home/eve/PycharmProjects/ospf_enterprise/venv/lib/python3.6/site-packages/paramiko/packet.py", line 380, in readline
    buf += self._read_timeout(timeout)
  File "/home/eve/PycharmProjects/ospf_enterprise/venv/lib/python3.6/site-packages/paramiko/packet.py", line 609, in _read_timeout
    raise EOFError()
EOFError

During handling of the above exception, another exception occurred:

Traceback (most recent call last):
  File "/home/eve/PycharmProjects/ospf_enterprise/venv/lib/python3.6/site-packages/nornir/core/task.py", line 85, in start
    r = self.task(self, **self.params)
  File "/home/eve/PycharmProjects/ospf_enterprise/venv/lib/python3.6/site-packages/nornir/plugins/tasks/networking/napalm_get.py", line 49, in napalm_get
    device = task.host.get_connection("napalm", task.nornir.config)
  File "/home/eve/PycharmProjects/ospf_enterprise/venv/lib/python3.6/site-packages/nornir/core/inventory.py", line 305, in get_connection
    extras=conn.extras,
  File "/home/eve/PycharmProjects/ospf_enterprise/venv/lib/python3.6/site-packages/nornir/core/inventory.py", line 365, in open_connection
    configuration=configuration,
  File "/home/eve/PycharmProjects/ospf_enterprise/venv/lib/python3.6/site-packages/nornir/plugins/connections/napalm.py", line 51, in open
    connection.open()
  File "/home/eve/PycharmProjects/ospf_enterprise/venv/lib/python3.6/site-packages/napalm/ios/ios.py", line 170, in open
    device_type, netmiko_optional_args=self.netmiko_optional_args
  File "/home/eve/PycharmProjects/ospf_enterprise/venv/lib/python3.6/site-packages/napalm/base/base.py", line 92, in _netmiko_open
    **netmiko_optional_args
  File "/home/eve/PycharmProjects/ospf_enterprise/venv/lib/python3.6/site-packages/netmiko/ssh_dispatcher.py", line 302, in ConnectHandler
    return ConnectionClass(*args, **kwargs)
  File "/home/eve/PycharmProjects/ospf_enterprise/venv/lib/python3.6/site-packages/netmiko/cisco/cisco_ios.py", line 17, in __init__
    return super().__init__(*args, **kwargs)
  File "/home/eve/PycharmProjects/ospf_enterprise/venv/lib/python3.6/site-packages/netmiko/base_connection.py", line 344, in __init__
    self._open()
  File "/home/eve/PycharmProjects/ospf_enterprise/venv/lib/python3.6/site-packages/netmiko/base_connection.py", line 349, in _open
    self.establish_connection()
  File "/home/eve/PycharmProjects/ospf_enterprise/venv/lib/python3.6/site-packages/netmiko/base_connection.py", line 918, in establish_connection
    self.remote_conn_pre.connect(**ssh_connect_params)
  File "/home/eve/PycharmProjects/ospf_enterprise/venv/lib/python3.6/site-packages/paramiko/client.py", line 406, in connect
    t.start_client(timeout=timeout)
  File "/home/eve/PycharmProjects/ospf_enterprise/venv/lib/python3.6/site-packages/paramiko/transport.py", line 660, in start_client
    raise e
  File "/home/eve/PycharmProjects/ospf_enterprise/venv/lib/python3.6/site-packages/paramiko/transport.py", line 2039, in run
    self._check_banner()
  File "/home/eve/PycharmProjects/ospf_enterprise/venv/lib/python3.6/site-packages/paramiko/transport.py", line 2216, in _check_banner
    "Error reading SSH protocol banner" + str(e)
paramiko.ssh_exception.SSHException: Error reading SSH protocol banner

2020-09-12 20:12:44,089 - nornir.core.task -    ERROR -      start() - Host 'R7': task 'napalm_get' failed with traceback:
Traceback (most recent call last):
  File "/home/eve/PycharmProjects/ospf_enterprise/venv/lib/python3.6/site-packages/paramiko/transport.py", line 2211, in _check_banner
    buf = self.packetizer.readline(timeout)
  File "/home/eve/PycharmProjects/ospf_enterprise/venv/lib/python3.6/site-packages/paramiko/packet.py", line 380, in readline
    buf += self._read_timeout(timeout)
  File "/home/eve/PycharmProjects/ospf_enterprise/venv/lib/python3.6/site-packages/paramiko/packet.py", line 609, in _read_timeout
    raise EOFError()
EOFError

During handling of the above exception, another exception occurred:

Traceback (most recent call last):
  File "/home/eve/PycharmProjects/ospf_enterprise/venv/lib/python3.6/site-packages/nornir/core/task.py", line 85, in start
    r = self.task(self, **self.params)
  File "/home/eve/PycharmProjects/ospf_enterprise/venv/lib/python3.6/site-packages/nornir/plugins/tasks/networking/napalm_get.py", line 49, in napalm_get
    device = task.host.get_connection("napalm", task.nornir.config)
  File "/home/eve/PycharmProjects/ospf_enterprise/venv/lib/python3.6/site-packages/nornir/core/inventory.py", line 305, in get_connection
    extras=conn.extras,
  File "/home/eve/PycharmProjects/ospf_enterprise/venv/lib/python3.6/site-packages/nornir/core/inventory.py", line 365, in open_connection
    configuration=configuration,
  File "/home/eve/PycharmProjects/ospf_enterprise/venv/lib/python3.6/site-packages/nornir/plugins/connections/napalm.py", line 51, in open
    connection.open()
  File "/home/eve/PycharmProjects/ospf_enterprise/venv/lib/python3.6/site-packages/napalm/ios/ios.py", line 170, in open
    device_type, netmiko_optional_args=self.netmiko_optional_args
  File "/home/eve/PycharmProjects/ospf_enterprise/venv/lib/python3.6/site-packages/napalm/base/base.py", line 92, in _netmiko_open
    **netmiko_optional_args
  File "/home/eve/PycharmProjects/ospf_enterprise/venv/lib/python3.6/site-packages/netmiko/ssh_dispatcher.py", line 302, in ConnectHandler
    return ConnectionClass(*args, **kwargs)
  File "/home/eve/PycharmProjects/ospf_enterprise/venv/lib/python3.6/site-packages/netmiko/cisco/cisco_ios.py", line 17, in __init__
    return super().__init__(*args, **kwargs)
  File "/home/eve/PycharmProjects/ospf_enterprise/venv/lib/python3.6/site-packages/netmiko/base_connection.py", line 344, in __init__
    self._open()
  File "/home/eve/PycharmProjects/ospf_enterprise/venv/lib/python3.6/site-packages/netmiko/base_connection.py", line 349, in _open
    self.establish_connection()
  File "/home/eve/PycharmProjects/ospf_enterprise/venv/lib/python3.6/site-packages/netmiko/base_connection.py", line 918, in establish_connection
    self.remote_conn_pre.connect(**ssh_connect_params)
  File "/home/eve/PycharmProjects/ospf_enterprise/venv/lib/python3.6/site-packages/paramiko/client.py", line 406, in connect
    t.start_client(timeout=timeout)
  File "/home/eve/PycharmProjects/ospf_enterprise/venv/lib/python3.6/site-packages/paramiko/transport.py", line 660, in start_client
    raise e
  File "/home/eve/PycharmProjects/ospf_enterprise/venv/lib/python3.6/site-packages/paramiko/transport.py", line 2039, in run
    self._check_banner()
  File "/home/eve/PycharmProjects/ospf_enterprise/venv/lib/python3.6/site-packages/paramiko/transport.py", line 2216, in _check_banner
    "Error reading SSH protocol banner" + str(e)
paramiko.ssh_exception.SSHException: Error reading SSH protocol banner

2020-09-12 20:12:48,821 - nornir.core.task -    ERROR -      start() - Host 'R2': task 'napalm_get' failed with traceback:
Traceback (most recent call last):
  File "/home/eve/PycharmProjects/ospf_enterprise/venv/lib/python3.6/site-packages/netmiko/base_connection.py", line 918, in establish_connection
    self.remote_conn_pre.connect(**ssh_connect_params)
  File "/home/eve/PycharmProjects/ospf_enterprise/venv/lib/python3.6/site-packages/paramiko/client.py", line 412, in connect
    server_key = t.get_remote_server_key()
  File "/home/eve/PycharmProjects/ospf_enterprise/venv/lib/python3.6/site-packages/paramiko/transport.py", line 834, in get_remote_server_key
    raise SSHException("No existing session")
paramiko.ssh_exception.SSHException: No existing session

During handling of the above exception, another exception occurred:

Traceback (most recent call last):
  File "/home/eve/PycharmProjects/ospf_enterprise/venv/lib/python3.6/site-packages/napalm/base/base.py", line 92, in _netmiko_open
    **netmiko_optional_args
  File "/home/eve/PycharmProjects/ospf_enterprise/venv/lib/python3.6/site-packages/netmiko/ssh_dispatcher.py", line 302, in ConnectHandler
    return ConnectionClass(*args, **kwargs)
  File "/home/eve/PycharmProjects/ospf_enterprise/venv/lib/python3.6/site-packages/netmiko/cisco/cisco_ios.py", line 17, in __init__
    return super().__init__(*args, **kwargs)
  File "/home/eve/PycharmProjects/ospf_enterprise/venv/lib/python3.6/site-packages/netmiko/base_connection.py", line 344, in __init__
    self._open()
  File "/home/eve/PycharmProjects/ospf_enterprise/venv/lib/python3.6/site-packages/netmiko/base_connection.py", line 349, in _open
    self.establish_connection()
  File "/home/eve/PycharmProjects/ospf_enterprise/venv/lib/python3.6/site-packages/netmiko/base_connection.py", line 948, in establish_connection
    raise NetmikoTimeoutException(msg)
netmiko.ssh_exception.NetmikoTimeoutException: Paramiko: 'No existing session' error: try increasing 'conn_timeout' to 10 seconds or larger.

During handling of the above exception, another exception occurred:

Traceback (most recent call last):
  File "/home/eve/PycharmProjects/ospf_enterprise/venv/lib/python3.6/site-packages/nornir/core/task.py", line 85, in start
    r = self.task(self, **self.params)
  File "/home/eve/PycharmProjects/ospf_enterprise/venv/lib/python3.6/site-packages/nornir/plugins/tasks/networking/napalm_get.py", line 49, in napalm_get
    device = task.host.get_connection("napalm", task.nornir.config)
  File "/home/eve/PycharmProjects/ospf_enterprise/venv/lib/python3.6/site-packages/nornir/core/inventory.py", line 305, in get_connection
    extras=conn.extras,
  File "/home/eve/PycharmProjects/ospf_enterprise/venv/lib/python3.6/site-packages/nornir/core/inventory.py", line 365, in open_connection
    configuration=configuration,
  File "/home/eve/PycharmProjects/ospf_enterprise/venv/lib/python3.6/site-packages/nornir/plugins/connections/napalm.py", line 51, in open
    connection.open()
  File "/home/eve/PycharmProjects/ospf_enterprise/venv/lib/python3.6/site-packages/napalm/ios/ios.py", line 170, in open
    device_type, netmiko_optional_args=self.netmiko_optional_args
  File "/home/eve/PycharmProjects/ospf_enterprise/venv/lib/python3.6/site-packages/napalm/base/base.py", line 95, in _netmiko_open
    raise ConnectionException("Cannot connect to {}".format(self.hostname))
napalm.base.exceptions.ConnectionException: Cannot connect to 10.0.12.2

2020-09-12 20:12:58,051 - nornir.core.task -    ERROR -      start() - Host 'R8': task 'test' failed with traceback:
Traceback (most recent call last):
  File "/home/eve/PycharmProjects/ospf_enterprise/venv/lib/python3.6/site-packages/nornir/core/task.py", line 85, in start
    r = self.task(self, **self.params)
  File "ospf.py", line 21, in test
    print(r.result)
AttributeError: 'AggregatedResult' object has no attribute 'result'

2020-09-12 20:12:58,283 - nornir.core.task -    ERROR -      start() - Host 'R7': task 'test' failed with traceback:
Traceback (most recent call last):
  File "/home/eve/PycharmProjects/ospf_enterprise/venv/lib/python3.6/site-packages/nornir/core/task.py", line 85, in start
    r = self.task(self, **self.params)
  File "ospf.py", line 21, in test
    print(r.result)
AttributeError: 'AggregatedResult' object has no attribute 'result'

2020-09-12 20:12:59,607 - nornir.core.task -    ERROR -      start() - Host 'R2': task 'test' failed with traceback:
Traceback (most recent call last):
  File "/home/eve/PycharmProjects/ospf_enterprise/venv/lib/python3.6/site-packages/nornir/core/task.py", line 85, in start
    r = self.task(self, **self.params)
  File "ospf.py", line 21, in test
    print(r.result)
AttributeError: 'AggregatedResult' object has no attribute 'result'

2020-09-12 20:12:59,689 - nornir.core.task -    ERROR -      start() - Host 'R1': task 'test' failed with traceback:
Traceback (most recent call last):
  File "/home/eve/PycharmProjects/ospf_enterprise/venv/lib/python3.6/site-packages/nornir/core/task.py", line 85, in start
    r = self.task(self, **self.params)
  File "ospf.py", line 21, in test
    print(r.result)
AttributeError: 'AggregatedResult' object has no attribute 'result'

2020-09-12 20:12:59,815 - nornir.core.task -    ERROR -      start() - Host 'R4': task 'test' failed with traceback:
Traceback (most recent call last):
  File "/home/eve/PycharmProjects/ospf_enterprise/venv/lib/python3.6/site-packages/nornir/core/task.py", line 85, in start
    r = self.task(self, **self.params)
  File "ospf.py", line 21, in test
    print(r.result)
AttributeError: 'AggregatedResult' object has no attribute 'result'

2020-09-12 20:12:59,971 - nornir.core.task -    ERROR -      start() - Host 'R3': task 'test' failed with traceback:
Traceback (most recent call last):
  File "/home/eve/PycharmProjects/ospf_enterprise/venv/lib/python3.6/site-packages/nornir/core/task.py", line 85, in start
    r = self.task(self, **self.params)
  File "ospf.py", line 21, in test
    print(r.result)
AttributeError: 'AggregatedResult' object has no attribute 'result'

2020-09-12 20:13:20,522 -  nornir.core -     INFO -        run() - Running task 'test' with args {} on 6 hosts
2020-09-12 20:13:20,524 -  nornir.core -     INFO -        run() - Running task 'napalm_get' with args {'getters': ['facts']} on 6 hosts
2020-09-12 20:13:20,527 -  nornir.core -     INFO -        run() - Running task 'napalm_get' with args {'getters': ['facts']} on 6 hosts
2020-09-12 20:13:20,531 -  nornir.core -     INFO -        run() - Running task 'napalm_get' with args {'getters': ['facts']} on 6 hosts
2020-09-12 20:13:20,536 -  nornir.core -     INFO -        run() - Running task 'napalm_get' with args {'getters': ['facts']} on 6 hosts
2020-09-12 20:13:20,537 -  nornir.core -     INFO -        run() - Running task 'napalm_get' with args {'getters': ['facts']} on 6 hosts
2020-09-12 20:13:20,541 -  nornir.core -     INFO -        run() - Running task 'napalm_get' with args {'getters': ['facts']} on 6 hosts
2020-09-12 20:13:20,717 - nornir.core.task -    ERROR -      start() - Host 'R3': task 'napalm_get' failed with traceback:
Traceback (most recent call last):
  File "/home/eve/PycharmProjects/ospf_enterprise/venv/lib/python3.6/site-packages/paramiko/transport.py", line 2211, in _check_banner
    buf = self.packetizer.readline(timeout)
  File "/home/eve/PycharmProjects/ospf_enterprise/venv/lib/python3.6/site-packages/paramiko/packet.py", line 380, in readline
    buf += self._read_timeout(timeout)
  File "/home/eve/PycharmProjects/ospf_enterprise/venv/lib/python3.6/site-packages/paramiko/packet.py", line 609, in _read_timeout
    raise EOFError()
EOFError

During handling of the above exception, another exception occurred:

Traceback (most recent call last):
  File "/home/eve/PycharmProjects/ospf_enterprise/venv/lib/python3.6/site-packages/nornir/core/task.py", line 85, in start
    r = self.task(self, **self.params)
  File "/home/eve/PycharmProjects/ospf_enterprise/venv/lib/python3.6/site-packages/nornir/plugins/tasks/networking/napalm_get.py", line 49, in napalm_get
    device = task.host.get_connection("napalm", task.nornir.config)
  File "/home/eve/PycharmProjects/ospf_enterprise/venv/lib/python3.6/site-packages/nornir/core/inventory.py", line 305, in get_connection
    extras=conn.extras,
  File "/home/eve/PycharmProjects/ospf_enterprise/venv/lib/python3.6/site-packages/nornir/core/inventory.py", line 365, in open_connection
    configuration=configuration,
  File "/home/eve/PycharmProjects/ospf_enterprise/venv/lib/python3.6/site-packages/nornir/plugins/connections/napalm.py", line 51, in open
    connection.open()
  File "/home/eve/PycharmProjects/ospf_enterprise/venv/lib/python3.6/site-packages/napalm/ios/ios.py", line 170, in open
    device_type, netmiko_optional_args=self.netmiko_optional_args
  File "/home/eve/PycharmProjects/ospf_enterprise/venv/lib/python3.6/site-packages/napalm/base/base.py", line 92, in _netmiko_open
    **netmiko_optional_args
  File "/home/eve/PycharmProjects/ospf_enterprise/venv/lib/python3.6/site-packages/netmiko/ssh_dispatcher.py", line 302, in ConnectHandler
    return ConnectionClass(*args, **kwargs)
  File "/home/eve/PycharmProjects/ospf_enterprise/venv/lib/python3.6/site-packages/netmiko/cisco/cisco_ios.py", line 17, in __init__
    return super().__init__(*args, **kwargs)
  File "/home/eve/PycharmProjects/ospf_enterprise/venv/lib/python3.6/site-packages/netmiko/base_connection.py", line 344, in __init__
    self._open()
  File "/home/eve/PycharmProjects/ospf_enterprise/venv/lib/python3.6/site-packages/netmiko/base_connection.py", line 349, in _open
    self.establish_connection()
  File "/home/eve/PycharmProjects/ospf_enterprise/venv/lib/python3.6/site-packages/netmiko/base_connection.py", line 918, in establish_connection
    self.remote_conn_pre.connect(**ssh_connect_params)
  File "/home/eve/PycharmProjects/ospf_enterprise/venv/lib/python3.6/site-packages/paramiko/client.py", line 406, in connect
    t.start_client(timeout=timeout)
  File "/home/eve/PycharmProjects/ospf_enterprise/venv/lib/python3.6/site-packages/paramiko/transport.py", line 660, in start_client
    raise e
  File "/home/eve/PycharmProjects/ospf_enterprise/venv/lib/python3.6/site-packages/paramiko/transport.py", line 2039, in run
    self._check_banner()
  File "/home/eve/PycharmProjects/ospf_enterprise/venv/lib/python3.6/site-packages/paramiko/transport.py", line 2216, in _check_banner
    "Error reading SSH protocol banner" + str(e)
paramiko.ssh_exception.SSHException: Error reading SSH protocol banner

2020-09-12 20:13:20,826 - nornir.core.task -    ERROR -      start() - Host 'R4': task 'napalm_get' failed with traceback:
Traceback (most recent call last):
  File "/home/eve/PycharmProjects/ospf_enterprise/venv/lib/python3.6/site-packages/paramiko/transport.py", line 2211, in _check_banner
    buf = self.packetizer.readline(timeout)
  File "/home/eve/PycharmProjects/ospf_enterprise/venv/lib/python3.6/site-packages/paramiko/packet.py", line 380, in readline
    buf += self._read_timeout(timeout)
  File "/home/eve/PycharmProjects/ospf_enterprise/venv/lib/python3.6/site-packages/paramiko/packet.py", line 609, in _read_timeout
    raise EOFError()
EOFError

During handling of the above exception, another exception occurred:

Traceback (most recent call last):
  File "/home/eve/PycharmProjects/ospf_enterprise/venv/lib/python3.6/site-packages/nornir/core/task.py", line 85, in start
    r = self.task(self, **self.params)
  File "/home/eve/PycharmProjects/ospf_enterprise/venv/lib/python3.6/site-packages/nornir/plugins/tasks/networking/napalm_get.py", line 49, in napalm_get
    device = task.host.get_connection("napalm", task.nornir.config)
  File "/home/eve/PycharmProjects/ospf_enterprise/venv/lib/python3.6/site-packages/nornir/core/inventory.py", line 305, in get_connection
    extras=conn.extras,
  File "/home/eve/PycharmProjects/ospf_enterprise/venv/lib/python3.6/site-packages/nornir/core/inventory.py", line 365, in open_connection
    configuration=configuration,
  File "/home/eve/PycharmProjects/ospf_enterprise/venv/lib/python3.6/site-packages/nornir/plugins/connections/napalm.py", line 51, in open
    connection.open()
  File "/home/eve/PycharmProjects/ospf_enterprise/venv/lib/python3.6/site-packages/napalm/ios/ios.py", line 170, in open
    device_type, netmiko_optional_args=self.netmiko_optional_args
  File "/home/eve/PycharmProjects/ospf_enterprise/venv/lib/python3.6/site-packages/napalm/base/base.py", line 92, in _netmiko_open
    **netmiko_optional_args
  File "/home/eve/PycharmProjects/ospf_enterprise/venv/lib/python3.6/site-packages/netmiko/ssh_dispatcher.py", line 302, in ConnectHandler
    return ConnectionClass(*args, **kwargs)
  File "/home/eve/PycharmProjects/ospf_enterprise/venv/lib/python3.6/site-packages/netmiko/cisco/cisco_ios.py", line 17, in __init__
    return super().__init__(*args, **kwargs)
  File "/home/eve/PycharmProjects/ospf_enterprise/venv/lib/python3.6/site-packages/netmiko/base_connection.py", line 344, in __init__
    self._open()
  File "/home/eve/PycharmProjects/ospf_enterprise/venv/lib/python3.6/site-packages/netmiko/base_connection.py", line 349, in _open
    self.establish_connection()
  File "/home/eve/PycharmProjects/ospf_enterprise/venv/lib/python3.6/site-packages/netmiko/base_connection.py", line 918, in establish_connection
    self.remote_conn_pre.connect(**ssh_connect_params)
  File "/home/eve/PycharmProjects/ospf_enterprise/venv/lib/python3.6/site-packages/paramiko/client.py", line 406, in connect
    t.start_client(timeout=timeout)
  File "/home/eve/PycharmProjects/ospf_enterprise/venv/lib/python3.6/site-packages/paramiko/transport.py", line 660, in start_client
    raise e
  File "/home/eve/PycharmProjects/ospf_enterprise/venv/lib/python3.6/site-packages/paramiko/transport.py", line 2039, in run
    self._check_banner()
  File "/home/eve/PycharmProjects/ospf_enterprise/venv/lib/python3.6/site-packages/paramiko/transport.py", line 2216, in _check_banner
    "Error reading SSH protocol banner" + str(e)
paramiko.ssh_exception.SSHException: Error reading SSH protocol banner

2020-09-12 20:13:20,828 - nornir.core.task -    ERROR -      start() - Host 'R8': task 'napalm_get' failed with traceback:
Traceback (most recent call last):
  File "/home/eve/PycharmProjects/ospf_enterprise/venv/lib/python3.6/site-packages/paramiko/transport.py", line 2211, in _check_banner
    buf = self.packetizer.readline(timeout)
  File "/home/eve/PycharmProjects/ospf_enterprise/venv/lib/python3.6/site-packages/paramiko/packet.py", line 380, in readline
    buf += self._read_timeout(timeout)
  File "/home/eve/PycharmProjects/ospf_enterprise/venv/lib/python3.6/site-packages/paramiko/packet.py", line 609, in _read_timeout
    raise EOFError()
EOFError

During handling of the above exception, another exception occurred:

Traceback (most recent call last):
  File "/home/eve/PycharmProjects/ospf_enterprise/venv/lib/python3.6/site-packages/nornir/core/task.py", line 85, in start
    r = self.task(self, **self.params)
  File "/home/eve/PycharmProjects/ospf_enterprise/venv/lib/python3.6/site-packages/nornir/plugins/tasks/networking/napalm_get.py", line 49, in napalm_get
    device = task.host.get_connection("napalm", task.nornir.config)
  File "/home/eve/PycharmProjects/ospf_enterprise/venv/lib/python3.6/site-packages/nornir/core/inventory.py", line 305, in get_connection
    extras=conn.extras,
  File "/home/eve/PycharmProjects/ospf_enterprise/venv/lib/python3.6/site-packages/nornir/core/inventory.py", line 365, in open_connection
    configuration=configuration,
  File "/home/eve/PycharmProjects/ospf_enterprise/venv/lib/python3.6/site-packages/nornir/plugins/connections/napalm.py", line 51, in open
    connection.open()
  File "/home/eve/PycharmProjects/ospf_enterprise/venv/lib/python3.6/site-packages/napalm/ios/ios.py", line 170, in open
    device_type, netmiko_optional_args=self.netmiko_optional_args
  File "/home/eve/PycharmProjects/ospf_enterprise/venv/lib/python3.6/site-packages/napalm/base/base.py", line 92, in _netmiko_open
    **netmiko_optional_args
  File "/home/eve/PycharmProjects/ospf_enterprise/venv/lib/python3.6/site-packages/netmiko/ssh_dispatcher.py", line 302, in ConnectHandler
    return ConnectionClass(*args, **kwargs)
  File "/home/eve/PycharmProjects/ospf_enterprise/venv/lib/python3.6/site-packages/netmiko/cisco/cisco_ios.py", line 17, in __init__
    return super().__init__(*args, **kwargs)
  File "/home/eve/PycharmProjects/ospf_enterprise/venv/lib/python3.6/site-packages/netmiko/base_connection.py", line 344, in __init__
    self._open()
  File "/home/eve/PycharmProjects/ospf_enterprise/venv/lib/python3.6/site-packages/netmiko/base_connection.py", line 349, in _open
    self.establish_connection()
  File "/home/eve/PycharmProjects/ospf_enterprise/venv/lib/python3.6/site-packages/netmiko/base_connection.py", line 918, in establish_connection
    self.remote_conn_pre.connect(**ssh_connect_params)
  File "/home/eve/PycharmProjects/ospf_enterprise/venv/lib/python3.6/site-packages/paramiko/client.py", line 406, in connect
    t.start_client(timeout=timeout)
  File "/home/eve/PycharmProjects/ospf_enterprise/venv/lib/python3.6/site-packages/paramiko/transport.py", line 660, in start_client
    raise e
  File "/home/eve/PycharmProjects/ospf_enterprise/venv/lib/python3.6/site-packages/paramiko/transport.py", line 2039, in run
    self._check_banner()
  File "/home/eve/PycharmProjects/ospf_enterprise/venv/lib/python3.6/site-packages/paramiko/transport.py", line 2216, in _check_banner
    "Error reading SSH protocol banner" + str(e)
paramiko.ssh_exception.SSHException: Error reading SSH protocol banner

2020-09-12 20:13:20,836 - nornir.core.task -    ERROR -      start() - Host 'R7': task 'napalm_get' failed with traceback:
Traceback (most recent call last):
  File "/home/eve/PycharmProjects/ospf_enterprise/venv/lib/python3.6/site-packages/paramiko/transport.py", line 2211, in _check_banner
    buf = self.packetizer.readline(timeout)
  File "/home/eve/PycharmProjects/ospf_enterprise/venv/lib/python3.6/site-packages/paramiko/packet.py", line 380, in readline
    buf += self._read_timeout(timeout)
  File "/home/eve/PycharmProjects/ospf_enterprise/venv/lib/python3.6/site-packages/paramiko/packet.py", line 609, in _read_timeout
    raise EOFError()
EOFError

During handling of the above exception, another exception occurred:

Traceback (most recent call last):
  File "/home/eve/PycharmProjects/ospf_enterprise/venv/lib/python3.6/site-packages/nornir/core/task.py", line 85, in start
    r = self.task(self, **self.params)
  File "/home/eve/PycharmProjects/ospf_enterprise/venv/lib/python3.6/site-packages/nornir/plugins/tasks/networking/napalm_get.py", line 49, in napalm_get
    device = task.host.get_connection("napalm", task.nornir.config)
  File "/home/eve/PycharmProjects/ospf_enterprise/venv/lib/python3.6/site-packages/nornir/core/inventory.py", line 305, in get_connection
    extras=conn.extras,
  File "/home/eve/PycharmProjects/ospf_enterprise/venv/lib/python3.6/site-packages/nornir/core/inventory.py", line 365, in open_connection
    configuration=configuration,
  File "/home/eve/PycharmProjects/ospf_enterprise/venv/lib/python3.6/site-packages/nornir/plugins/connections/napalm.py", line 51, in open
    connection.open()
  File "/home/eve/PycharmProjects/ospf_enterprise/venv/lib/python3.6/site-packages/napalm/ios/ios.py", line 170, in open
    device_type, netmiko_optional_args=self.netmiko_optional_args
  File "/home/eve/PycharmProjects/ospf_enterprise/venv/lib/python3.6/site-packages/napalm/base/base.py", line 92, in _netmiko_open
    **netmiko_optional_args
  File "/home/eve/PycharmProjects/ospf_enterprise/venv/lib/python3.6/site-packages/netmiko/ssh_dispatcher.py", line 302, in ConnectHandler
    return ConnectionClass(*args, **kwargs)
  File "/home/eve/PycharmProjects/ospf_enterprise/venv/lib/python3.6/site-packages/netmiko/cisco/cisco_ios.py", line 17, in __init__
    return super().__init__(*args, **kwargs)
  File "/home/eve/PycharmProjects/ospf_enterprise/venv/lib/python3.6/site-packages/netmiko/base_connection.py", line 344, in __init__
    self._open()
  File "/home/eve/PycharmProjects/ospf_enterprise/venv/lib/python3.6/site-packages/netmiko/base_connection.py", line 349, in _open
    self.establish_connection()
  File "/home/eve/PycharmProjects/ospf_enterprise/venv/lib/python3.6/site-packages/netmiko/base_connection.py", line 918, in establish_connection
    self.remote_conn_pre.connect(**ssh_connect_params)
  File "/home/eve/PycharmProjects/ospf_enterprise/venv/lib/python3.6/site-packages/paramiko/client.py", line 406, in connect
    t.start_client(timeout=timeout)
  File "/home/eve/PycharmProjects/ospf_enterprise/venv/lib/python3.6/site-packages/paramiko/transport.py", line 660, in start_client
    raise e
  File "/home/eve/PycharmProjects/ospf_enterprise/venv/lib/python3.6/site-packages/paramiko/transport.py", line 2039, in run
    self._check_banner()
  File "/home/eve/PycharmProjects/ospf_enterprise/venv/lib/python3.6/site-packages/paramiko/transport.py", line 2216, in _check_banner
    "Error reading SSH protocol banner" + str(e)
paramiko.ssh_exception.SSHException: Error reading SSH protocol banner

2020-09-12 20:13:20,924 - nornir.core.task -    ERROR -      start() - Host 'R1': task 'napalm_get' failed with traceback:
Traceback (most recent call last):
  File "/home/eve/PycharmProjects/ospf_enterprise/venv/lib/python3.6/site-packages/paramiko/transport.py", line 2211, in _check_banner
    buf = self.packetizer.readline(timeout)
  File "/home/eve/PycharmProjects/ospf_enterprise/venv/lib/python3.6/site-packages/paramiko/packet.py", line 380, in readline
    buf += self._read_timeout(timeout)
  File "/home/eve/PycharmProjects/ospf_enterprise/venv/lib/python3.6/site-packages/paramiko/packet.py", line 609, in _read_timeout
    raise EOFError()
EOFError

During handling of the above exception, another exception occurred:

Traceback (most recent call last):
  File "/home/eve/PycharmProjects/ospf_enterprise/venv/lib/python3.6/site-packages/nornir/core/task.py", line 85, in start
    r = self.task(self, **self.params)
  File "/home/eve/PycharmProjects/ospf_enterprise/venv/lib/python3.6/site-packages/nornir/plugins/tasks/networking/napalm_get.py", line 49, in napalm_get
    device = task.host.get_connection("napalm", task.nornir.config)
  File "/home/eve/PycharmProjects/ospf_enterprise/venv/lib/python3.6/site-packages/nornir/core/inventory.py", line 305, in get_connection
    extras=conn.extras,
  File "/home/eve/PycharmProjects/ospf_enterprise/venv/lib/python3.6/site-packages/nornir/core/inventory.py", line 365, in open_connection
    configuration=configuration,
  File "/home/eve/PycharmProjects/ospf_enterprise/venv/lib/python3.6/site-packages/nornir/plugins/connections/napalm.py", line 51, in open
    connection.open()
  File "/home/eve/PycharmProjects/ospf_enterprise/venv/lib/python3.6/site-packages/napalm/ios/ios.py", line 170, in open
    device_type, netmiko_optional_args=self.netmiko_optional_args
  File "/home/eve/PycharmProjects/ospf_enterprise/venv/lib/python3.6/site-packages/napalm/base/base.py", line 92, in _netmiko_open
    **netmiko_optional_args
  File "/home/eve/PycharmProjects/ospf_enterprise/venv/lib/python3.6/site-packages/netmiko/ssh_dispatcher.py", line 302, in ConnectHandler
    return ConnectionClass(*args, **kwargs)
  File "/home/eve/PycharmProjects/ospf_enterprise/venv/lib/python3.6/site-packages/netmiko/cisco/cisco_ios.py", line 17, in __init__
    return super().__init__(*args, **kwargs)
  File "/home/eve/PycharmProjects/ospf_enterprise/venv/lib/python3.6/site-packages/netmiko/base_connection.py", line 344, in __init__
    self._open()
  File "/home/eve/PycharmProjects/ospf_enterprise/venv/lib/python3.6/site-packages/netmiko/base_connection.py", line 349, in _open
    self.establish_connection()
  File "/home/eve/PycharmProjects/ospf_enterprise/venv/lib/python3.6/site-packages/netmiko/base_connection.py", line 918, in establish_connection
    self.remote_conn_pre.connect(**ssh_connect_params)
  File "/home/eve/PycharmProjects/ospf_enterprise/venv/lib/python3.6/site-packages/paramiko/client.py", line 406, in connect
    t.start_client(timeout=timeout)
  File "/home/eve/PycharmProjects/ospf_enterprise/venv/lib/python3.6/site-packages/paramiko/transport.py", line 660, in start_client
    raise e
  File "/home/eve/PycharmProjects/ospf_enterprise/venv/lib/python3.6/site-packages/paramiko/transport.py", line 2039, in run
    self._check_banner()
  File "/home/eve/PycharmProjects/ospf_enterprise/venv/lib/python3.6/site-packages/paramiko/transport.py", line 2216, in _check_banner
    "Error reading SSH protocol banner" + str(e)
paramiko.ssh_exception.SSHException: Error reading SSH protocol banner

2020-09-12 20:13:22,564 - nornir.core.task -    ERROR -      start() - Host 'R2': task 'napalm_get' failed with traceback:
Traceback (most recent call last):
  File "/home/eve/PycharmProjects/ospf_enterprise/venv/lib/python3.6/site-packages/paramiko/transport.py", line 2211, in _check_banner
    buf = self.packetizer.readline(timeout)
  File "/home/eve/PycharmProjects/ospf_enterprise/venv/lib/python3.6/site-packages/paramiko/packet.py", line 380, in readline
    buf += self._read_timeout(timeout)
  File "/home/eve/PycharmProjects/ospf_enterprise/venv/lib/python3.6/site-packages/paramiko/packet.py", line 609, in _read_timeout
    raise EOFError()
EOFError

During handling of the above exception, another exception occurred:

Traceback (most recent call last):
  File "/home/eve/PycharmProjects/ospf_enterprise/venv/lib/python3.6/site-packages/nornir/core/task.py", line 85, in start
    r = self.task(self, **self.params)
  File "/home/eve/PycharmProjects/ospf_enterprise/venv/lib/python3.6/site-packages/nornir/plugins/tasks/networking/napalm_get.py", line 49, in napalm_get
    device = task.host.get_connection("napalm", task.nornir.config)
  File "/home/eve/PycharmProjects/ospf_enterprise/venv/lib/python3.6/site-packages/nornir/core/inventory.py", line 305, in get_connection
    extras=conn.extras,
  File "/home/eve/PycharmProjects/ospf_enterprise/venv/lib/python3.6/site-packages/nornir/core/inventory.py", line 365, in open_connection
    configuration=configuration,
  File "/home/eve/PycharmProjects/ospf_enterprise/venv/lib/python3.6/site-packages/nornir/plugins/connections/napalm.py", line 51, in open
    connection.open()
  File "/home/eve/PycharmProjects/ospf_enterprise/venv/lib/python3.6/site-packages/napalm/ios/ios.py", line 170, in open
    device_type, netmiko_optional_args=self.netmiko_optional_args
  File "/home/eve/PycharmProjects/ospf_enterprise/venv/lib/python3.6/site-packages/napalm/base/base.py", line 92, in _netmiko_open
    **netmiko_optional_args
  File "/home/eve/PycharmProjects/ospf_enterprise/venv/lib/python3.6/site-packages/netmiko/ssh_dispatcher.py", line 302, in ConnectHandler
    return ConnectionClass(*args, **kwargs)
  File "/home/eve/PycharmProjects/ospf_enterprise/venv/lib/python3.6/site-packages/netmiko/cisco/cisco_ios.py", line 17, in __init__
    return super().__init__(*args, **kwargs)
  File "/home/eve/PycharmProjects/ospf_enterprise/venv/lib/python3.6/site-packages/netmiko/base_connection.py", line 344, in __init__
    self._open()
  File "/home/eve/PycharmProjects/ospf_enterprise/venv/lib/python3.6/site-packages/netmiko/base_connection.py", line 349, in _open
    self.establish_connection()
  File "/home/eve/PycharmProjects/ospf_enterprise/venv/lib/python3.6/site-packages/netmiko/base_connection.py", line 918, in establish_connection
    self.remote_conn_pre.connect(**ssh_connect_params)
  File "/home/eve/PycharmProjects/ospf_enterprise/venv/lib/python3.6/site-packages/paramiko/client.py", line 406, in connect
    t.start_client(timeout=timeout)
  File "/home/eve/PycharmProjects/ospf_enterprise/venv/lib/python3.6/site-packages/paramiko/transport.py", line 660, in start_client
    raise e
  File "/home/eve/PycharmProjects/ospf_enterprise/venv/lib/python3.6/site-packages/paramiko/transport.py", line 2039, in run
    self._check_banner()
  File "/home/eve/PycharmProjects/ospf_enterprise/venv/lib/python3.6/site-packages/paramiko/transport.py", line 2216, in _check_banner
    "Error reading SSH protocol banner" + str(e)
paramiko.ssh_exception.SSHException: Error reading SSH protocol banner

2020-09-12 20:13:25,909 - nornir.core.task -    ERROR -      start() - Host 'R2': task 'napalm_get' failed with traceback:
Traceback (most recent call last):
  File "/home/eve/PycharmProjects/ospf_enterprise/venv/lib/python3.6/site-packages/netmiko/base_connection.py", line 918, in establish_connection
    self.remote_conn_pre.connect(**ssh_connect_params)
  File "/home/eve/PycharmProjects/ospf_enterprise/venv/lib/python3.6/site-packages/paramiko/client.py", line 412, in connect
    server_key = t.get_remote_server_key()
  File "/home/eve/PycharmProjects/ospf_enterprise/venv/lib/python3.6/site-packages/paramiko/transport.py", line 834, in get_remote_server_key
    raise SSHException("No existing session")
paramiko.ssh_exception.SSHException: No existing session

During handling of the above exception, another exception occurred:

Traceback (most recent call last):
  File "/home/eve/PycharmProjects/ospf_enterprise/venv/lib/python3.6/site-packages/napalm/base/base.py", line 92, in _netmiko_open
    **netmiko_optional_args
  File "/home/eve/PycharmProjects/ospf_enterprise/venv/lib/python3.6/site-packages/netmiko/ssh_dispatcher.py", line 302, in ConnectHandler
    return ConnectionClass(*args, **kwargs)
  File "/home/eve/PycharmProjects/ospf_enterprise/venv/lib/python3.6/site-packages/netmiko/cisco/cisco_ios.py", line 17, in __init__
    return super().__init__(*args, **kwargs)
  File "/home/eve/PycharmProjects/ospf_enterprise/venv/lib/python3.6/site-packages/netmiko/base_connection.py", line 344, in __init__
    self._open()
  File "/home/eve/PycharmProjects/ospf_enterprise/venv/lib/python3.6/site-packages/netmiko/base_connection.py", line 349, in _open
    self.establish_connection()
  File "/home/eve/PycharmProjects/ospf_enterprise/venv/lib/python3.6/site-packages/netmiko/base_connection.py", line 948, in establish_connection
    raise NetmikoTimeoutException(msg)
netmiko.ssh_exception.NetmikoTimeoutException: Paramiko: 'No existing session' error: try increasing 'conn_timeout' to 10 seconds or larger.

During handling of the above exception, another exception occurred:

Traceback (most recent call last):
  File "/home/eve/PycharmProjects/ospf_enterprise/venv/lib/python3.6/site-packages/nornir/core/task.py", line 85, in start
    r = self.task(self, **self.params)
  File "/home/eve/PycharmProjects/ospf_enterprise/venv/lib/python3.6/site-packages/nornir/plugins/tasks/networking/napalm_get.py", line 49, in napalm_get
    device = task.host.get_connection("napalm", task.nornir.config)
  File "/home/eve/PycharmProjects/ospf_enterprise/venv/lib/python3.6/site-packages/nornir/core/inventory.py", line 305, in get_connection
    extras=conn.extras,
  File "/home/eve/PycharmProjects/ospf_enterprise/venv/lib/python3.6/site-packages/nornir/core/inventory.py", line 365, in open_connection
    configuration=configuration,
  File "/home/eve/PycharmProjects/ospf_enterprise/venv/lib/python3.6/site-packages/nornir/plugins/connections/napalm.py", line 51, in open
    connection.open()
  File "/home/eve/PycharmProjects/ospf_enterprise/venv/lib/python3.6/site-packages/napalm/ios/ios.py", line 170, in open
    device_type, netmiko_optional_args=self.netmiko_optional_args
  File "/home/eve/PycharmProjects/ospf_enterprise/venv/lib/python3.6/site-packages/napalm/base/base.py", line 95, in _netmiko_open
    raise ConnectionException("Cannot connect to {}".format(self.hostname))
napalm.base.exceptions.ConnectionException: Cannot connect to 10.0.12.2

2020-09-12 20:17:56,557 -  nornir.core -     INFO -        run() - Running task 'test' with args {} on 6 hosts
2020-09-12 20:17:59,488 - nornir.core.task -    ERROR -      start() - Host 'R8': task 'test' failed with traceback:
Traceback (most recent call last):
  File "/home/eve/PycharmProjects/ospf_enterprise/venv/lib/python3.6/site-packages/nornir/core/task.py", line 85, in start
    r = self.task(self, **self.params)
  File "ospf.py", line 16, in test
    interfaces = task.host['facts']['interfaces']
TypeError: string indices must be integers

2020-09-12 20:17:59,521 - nornir.core.task -    ERROR -      start() - Host 'R2': task 'test' failed with traceback:
Traceback (most recent call last):
  File "/home/eve/PycharmProjects/ospf_enterprise/venv/lib/python3.6/site-packages/nornir/core/task.py", line 85, in start
    r = self.task(self, **self.params)
  File "ospf.py", line 16, in test
    interfaces = task.host['facts']['interfaces']
TypeError: string indices must be integers

2020-09-12 20:17:59,516 - nornir.core.task -    ERROR -      start() - Host 'R3': task 'test' failed with traceback:
Traceback (most recent call last):
  File "/home/eve/PycharmProjects/ospf_enterprise/venv/lib/python3.6/site-packages/nornir/core/task.py", line 85, in start
    r = self.task(self, **self.params)
  File "ospf.py", line 16, in test
    interfaces = task.host['facts']['interfaces']
TypeError: string indices must be integers

2020-09-12 20:17:59,522 - nornir.core.task -    ERROR -      start() - Host 'R7': task 'test' failed with traceback:
Traceback (most recent call last):
  File "/home/eve/PycharmProjects/ospf_enterprise/venv/lib/python3.6/site-packages/nornir/core/task.py", line 85, in start
    r = self.task(self, **self.params)
  File "ospf.py", line 16, in test
    interfaces = task.host['facts']['interfaces']
TypeError: string indices must be integers

2020-09-12 20:17:59,496 - nornir.core.task -    ERROR -      start() - Host 'R4': task 'test' failed with traceback:
Traceback (most recent call last):
  File "/home/eve/PycharmProjects/ospf_enterprise/venv/lib/python3.6/site-packages/nornir/core/task.py", line 85, in start
    r = self.task(self, **self.params)
  File "ospf.py", line 16, in test
    interfaces = task.host['facts']['interfaces']
TypeError: string indices must be integers

2020-09-12 20:17:59,538 - nornir.core.task -    ERROR -      start() - Host 'R1': task 'test' failed with traceback:
Traceback (most recent call last):
  File "/home/eve/PycharmProjects/ospf_enterprise/venv/lib/python3.6/site-packages/nornir/core/task.py", line 85, in start
    r = self.task(self, **self.params)
  File "ospf.py", line 16, in test
    interfaces = task.host['facts']['interfaces']
TypeError: string indices must be integers

2020-09-12 20:28:37,022 -  nornir.core -     INFO -        run() - Running task 'test' with args {} on 6 hosts
2020-09-12 20:28:39,615 - nornir.core.task -    ERROR -      start() - Host 'R3': task 'test' failed with traceback:
Traceback (most recent call last):
  File "/home/eve/PycharmProjects/ospf_enterprise/venv/lib/python3.6/site-packages/nornir/core/task.py", line 85, in start
    r = self.task(self, **self.params)
  File "ospf.py", line 16, in test
    interfaces = task.host['facts']['interfaces']
TypeError: string indices must be integers

2020-09-12 20:28:39,615 - nornir.core.task -    ERROR -      start() - Host 'R7': task 'test' failed with traceback:
Traceback (most recent call last):
  File "/home/eve/PycharmProjects/ospf_enterprise/venv/lib/python3.6/site-packages/nornir/core/task.py", line 85, in start
    r = self.task(self, **self.params)
  File "ospf.py", line 16, in test
    interfaces = task.host['facts']['interfaces']
TypeError: string indices must be integers

2020-09-12 20:28:39,617 - nornir.core.task -    ERROR -      start() - Host 'R2': task 'test' failed with traceback:
Traceback (most recent call last):
  File "/home/eve/PycharmProjects/ospf_enterprise/venv/lib/python3.6/site-packages/nornir/core/task.py", line 85, in start
    r = self.task(self, **self.params)
  File "ospf.py", line 16, in test
    interfaces = task.host['facts']['interfaces']
TypeError: string indices must be integers

2020-09-12 20:28:39,619 - nornir.core.task -    ERROR -      start() - Host 'R1': task 'test' failed with traceback:
Traceback (most recent call last):
  File "/home/eve/PycharmProjects/ospf_enterprise/venv/lib/python3.6/site-packages/nornir/core/task.py", line 85, in start
    r = self.task(self, **self.params)
  File "ospf.py", line 16, in test
    interfaces = task.host['facts']['interfaces']
TypeError: string indices must be integers

2020-09-12 20:28:39,619 - nornir.core.task -    ERROR -      start() - Host 'R8': task 'test' failed with traceback:
Traceback (most recent call last):
  File "/home/eve/PycharmProjects/ospf_enterprise/venv/lib/python3.6/site-packages/nornir/core/task.py", line 85, in start
    r = self.task(self, **self.params)
  File "ospf.py", line 16, in test
    interfaces = task.host['facts']['interfaces']
TypeError: string indices must be integers

2020-09-12 20:28:39,620 - nornir.core.task -    ERROR -      start() - Host 'R4': task 'test' failed with traceback:
Traceback (most recent call last):
  File "/home/eve/PycharmProjects/ospf_enterprise/venv/lib/python3.6/site-packages/nornir/core/task.py", line 85, in start
    r = self.task(self, **self.params)
  File "ospf.py", line 16, in test
    interfaces = task.host['facts']['interfaces']
TypeError: string indices must be integers

2020-09-12 20:28:51,621 -  nornir.core -     INFO -        run() - Running task 'test' with args {} on 6 hosts
2020-09-12 20:28:53,976 - nornir.core.task -    ERROR -      start() - Host 'R8': task 'test' failed with traceback:
Traceback (most recent call last):
  File "/home/eve/PycharmProjects/ospf_enterprise/venv/lib/python3.6/site-packages/nornir/core/task.py", line 85, in start
    r = self.task(self, **self.params)
  File "ospf.py", line 16, in test
    interfaces = task.host['facts']['interfaces']
TypeError: string indices must be integers

2020-09-12 20:28:54,000 - nornir.core.task -    ERROR -      start() - Host 'R4': task 'test' failed with traceback:
Traceback (most recent call last):
  File "/home/eve/PycharmProjects/ospf_enterprise/venv/lib/python3.6/site-packages/nornir/core/task.py", line 85, in start
    r = self.task(self, **self.params)
  File "ospf.py", line 16, in test
    interfaces = task.host['facts']['interfaces']
TypeError: string indices must be integers

2020-09-12 20:28:54,004 - nornir.core.task -    ERROR -      start() - Host 'R7': task 'test' failed with traceback:
Traceback (most recent call last):
  File "/home/eve/PycharmProjects/ospf_enterprise/venv/lib/python3.6/site-packages/nornir/core/task.py", line 85, in start
    r = self.task(self, **self.params)
  File "ospf.py", line 16, in test
    interfaces = task.host['facts']['interfaces']
TypeError: string indices must be integers

2020-09-12 20:28:54,014 - nornir.core.task -    ERROR -      start() - Host 'R3': task 'test' failed with traceback:
Traceback (most recent call last):
  File "/home/eve/PycharmProjects/ospf_enterprise/venv/lib/python3.6/site-packages/nornir/core/task.py", line 85, in start
    r = self.task(self, **self.params)
  File "ospf.py", line 16, in test
    interfaces = task.host['facts']['interfaces']
TypeError: string indices must be integers

2020-09-12 20:28:54,029 - nornir.core.task -    ERROR -      start() - Host 'R1': task 'test' failed with traceback:
Traceback (most recent call last):
  File "/home/eve/PycharmProjects/ospf_enterprise/venv/lib/python3.6/site-packages/nornir/core/task.py", line 85, in start
    r = self.task(self, **self.params)
  File "ospf.py", line 16, in test
    interfaces = task.host['facts']['interfaces']
TypeError: string indices must be integers

2020-09-12 20:28:54,127 - nornir.core.task -    ERROR -      start() - Host 'R2': task 'test' failed with traceback:
Traceback (most recent call last):
  File "/home/eve/PycharmProjects/ospf_enterprise/venv/lib/python3.6/site-packages/nornir/core/task.py", line 85, in start
    r = self.task(self, **self.params)
  File "ospf.py", line 16, in test
    interfaces = task.host['facts']['interfaces']
TypeError: string indices must be integers

2020-09-12 21:06:26,987 -  nornir.core -     INFO -        run() - Running task 'test' with args {} on 6 hosts
2020-09-12 21:09:00,589 -  nornir.core -     INFO -        run() - Running task 'test' with args {} on 6 hosts
2020-09-12 21:11:03,728 -  nornir.core -     INFO -        run() - Running task 'test' with args {} on 6 hosts
2020-09-12 21:14:43,548 -  nornir.core -     INFO -        run() - Running task 'test' with args {} on 6 hosts
2020-09-12 21:14:56,451 -  nornir.core -     INFO -        run() - Running task 'test' with args {} on 6 hosts
2020-09-12 21:16:00,974 -  nornir.core -     INFO -        run() - Running task 'test' with args {} on 6 hosts
2020-09-12 21:17:07,238 -  nornir.core -     INFO -        run() - Running task 'test' with args {} on 6 hosts
2020-09-12 21:21:31,342 -  nornir.core -     INFO -        run() - Running task 'test' with args {} on 6 hosts
2020-09-12 21:23:03,761 -  nornir.core -     INFO -        run() - Running task 'test' with args {} on 6 hosts
2020-09-12 21:24:59,839 -  nornir.core -     INFO -        run() - Running task 'test' with args {} on 6 hosts
2020-09-12 21:26:10,100 -  nornir.core -     INFO -        run() - Running task 'test' with args {} on 6 hosts
2020-09-12 21:32:39,482 -  nornir.core -     INFO -        run() - Running task 'test' with args {} on 6 hosts
2020-09-12 21:44:24,922 -  nornir.core -     INFO -        run() - Running task 'test' with args {} on 6 hosts
2020-09-12 21:45:25,607 -  nornir.core -     INFO -        run() - Running task 'test' with args {} on 6 hosts
2020-09-12 21:45:28,122 - nornir.core.task -    ERROR -      start() - Host 'R4': task 'test' failed with traceback:
Traceback (most recent call last):
  File "/home/eve/PycharmProjects/ospf_enterprise/venv/lib/python3.6/site-packages/nornir/core/task.py", line 85, in start
    r = self.task(self, **self.params)
  File "ospf.py", line 16, in test
    interfaces = task.host['facts']['interfaces']
TypeError: string indices must be integers

2020-09-12 21:45:28,131 - nornir.core.task -    ERROR -      start() - Host 'R7': task 'test' failed with traceback:
Traceback (most recent call last):
  File "/home/eve/PycharmProjects/ospf_enterprise/venv/lib/python3.6/site-packages/nornir/core/task.py", line 85, in start
    r = self.task(self, **self.params)
  File "ospf.py", line 16, in test
    interfaces = task.host['facts']['interfaces']
TypeError: string indices must be integers

2020-09-12 21:45:28,132 - nornir.core.task -    ERROR -      start() - Host 'R8': task 'test' failed with traceback:
Traceback (most recent call last):
  File "/home/eve/PycharmProjects/ospf_enterprise/venv/lib/python3.6/site-packages/nornir/core/task.py", line 85, in start
    r = self.task(self, **self.params)
  File "ospf.py", line 16, in test
    interfaces = task.host['facts']['interfaces']
TypeError: string indices must be integers

2020-09-12 21:45:28,132 - nornir.core.task -    ERROR -      start() - Host 'R1': task 'test' failed with traceback:
Traceback (most recent call last):
  File "/home/eve/PycharmProjects/ospf_enterprise/venv/lib/python3.6/site-packages/nornir/core/task.py", line 85, in start
    r = self.task(self, **self.params)
  File "ospf.py", line 16, in test
    interfaces = task.host['facts']['interfaces']
TypeError: string indices must be integers

2020-09-12 21:45:28,134 - nornir.core.task -    ERROR -      start() - Host 'R2': task 'test' failed with traceback:
Traceback (most recent call last):
  File "/home/eve/PycharmProjects/ospf_enterprise/venv/lib/python3.6/site-packages/nornir/core/task.py", line 85, in start
    r = self.task(self, **self.params)
  File "ospf.py", line 16, in test
    interfaces = task.host['facts']['interfaces']
TypeError: string indices must be integers

2020-09-12 21:45:28,134 - nornir.core.task -    ERROR -      start() - Host 'R3': task 'test' failed with traceback:
Traceback (most recent call last):
  File "/home/eve/PycharmProjects/ospf_enterprise/venv/lib/python3.6/site-packages/nornir/core/task.py", line 85, in start
    r = self.task(self, **self.params)
  File "ospf.py", line 16, in test
    interfaces = task.host['facts']['interfaces']
TypeError: string indices must be integers

2020-09-12 21:46:01,554 -  nornir.core -     INFO -        run() - Running task 'test' with args {} on 6 hosts
2020-09-12 21:46:20,997 -  nornir.core -     INFO -        run() - Running task 'test' with args {} on 6 hosts
2020-09-12 21:46:56,477 -  nornir.core -     INFO -        run() - Running task 'test' with args {} on 6 hosts
2020-09-12 21:47:20,848 -  nornir.core -     INFO -        run() - Running task 'test' with args {} on 6 hosts
2020-09-12 22:23:20,349 -  nornir.core -     INFO -        run() - Running task 'test' with args {} on 6 hosts
2020-09-12 22:23:25,369 - nornir.core.task -    ERROR -      start() - Host 'R4': task 'netmiko_send_command' failed with traceback:
Traceback (most recent call last):
  File "/home/eve/PycharmProjects/ospf_enterprise/venv/lib/python3.6/site-packages/netmiko/base_connection.py", line 918, in establish_connection
    self.remote_conn_pre.connect(**ssh_connect_params)
  File "/home/eve/PycharmProjects/ospf_enterprise/venv/lib/python3.6/site-packages/paramiko/client.py", line 349, in connect
    retry_on_signal(lambda: sock.connect(addr))
  File "/home/eve/PycharmProjects/ospf_enterprise/venv/lib/python3.6/site-packages/paramiko/util.py", line 283, in retry_on_signal
    return function()
  File "/home/eve/PycharmProjects/ospf_enterprise/venv/lib/python3.6/site-packages/paramiko/client.py", line 349, in <lambda>
    retry_on_signal(lambda: sock.connect(addr))
socket.timeout: timed out

During handling of the above exception, another exception occurred:

Traceback (most recent call last):
  File "/home/eve/PycharmProjects/ospf_enterprise/venv/lib/python3.6/site-packages/nornir/core/task.py", line 85, in start
    r = self.task(self, **self.params)
  File "/home/eve/PycharmProjects/ospf_enterprise/venv/lib/python3.6/site-packages/nornir/plugins/tasks/networking/netmiko_send_command.py", line 26, in netmiko_send_command
    net_connect = task.host.get_connection("netmiko", task.nornir.config)
  File "/home/eve/PycharmProjects/ospf_enterprise/venv/lib/python3.6/site-packages/nornir/core/inventory.py", line 305, in get_connection
    extras=conn.extras,
  File "/home/eve/PycharmProjects/ospf_enterprise/venv/lib/python3.6/site-packages/nornir/core/inventory.py", line 365, in open_connection
    configuration=configuration,
  File "/home/eve/PycharmProjects/ospf_enterprise/venv/lib/python3.6/site-packages/nornir/plugins/connections/netmiko.py", line 58, in open
    self.connection = ConnectHandler(**parameters)
  File "/home/eve/PycharmProjects/ospf_enterprise/venv/lib/python3.6/site-packages/netmiko/ssh_dispatcher.py", line 302, in ConnectHandler
    return ConnectionClass(*args, **kwargs)
  File "/home/eve/PycharmProjects/ospf_enterprise/venv/lib/python3.6/site-packages/netmiko/cisco/cisco_ios.py", line 17, in __init__
    return super().__init__(*args, **kwargs)
  File "/home/eve/PycharmProjects/ospf_enterprise/venv/lib/python3.6/site-packages/netmiko/base_connection.py", line 344, in __init__
    self._open()
  File "/home/eve/PycharmProjects/ospf_enterprise/venv/lib/python3.6/site-packages/netmiko/base_connection.py", line 349, in _open
    self.establish_connection()
  File "/home/eve/PycharmProjects/ospf_enterprise/venv/lib/python3.6/site-packages/netmiko/base_connection.py", line 940, in establish_connection
    raise NetmikoTimeoutException(msg)
netmiko.ssh_exception.NetmikoTimeoutException: TCP connection to device failed.

Common causes of this problem are:
1. Incorrect hostname or IP address.
2. Wrong TCP port.
3. Intermediate firewall blocking access.

Device settings: cisco_xe 10.0.34.4:22



2020-09-12 22:23:25,370 - nornir.core.task -    ERROR -      start() - Host 'R4': task 'test' failed with traceback:
Traceback (most recent call last):
  File "/home/eve/PycharmProjects/ospf_enterprise/venv/lib/python3.6/site-packages/nornir/core/task.py", line 85, in start
    r = self.task(self, **self.params)
  File "ospf.py", line 14, in test
    result = task.run(netmiko_send_command, command_string='show ip ospf nei', use_genie=True)
  File "/home/eve/PycharmProjects/ospf_enterprise/venv/lib/python3.6/site-packages/nornir/core/task.py", line 147, in run
    raise NornirSubTaskError(task=task, result=r)
nornir.core.exceptions.NornirSubTaskError: Subtask: <function netmiko_send_command at 0x7f30efcb69d8> (failed)


2020-09-12 22:23:25,371 - nornir.core.task -    ERROR -      start() - Host 'R2': task 'netmiko_send_command' failed with traceback:
Traceback (most recent call last):
  File "/home/eve/PycharmProjects/ospf_enterprise/venv/lib/python3.6/site-packages/netmiko/base_connection.py", line 918, in establish_connection
    self.remote_conn_pre.connect(**ssh_connect_params)
  File "/home/eve/PycharmProjects/ospf_enterprise/venv/lib/python3.6/site-packages/paramiko/client.py", line 349, in connect
    retry_on_signal(lambda: sock.connect(addr))
  File "/home/eve/PycharmProjects/ospf_enterprise/venv/lib/python3.6/site-packages/paramiko/util.py", line 283, in retry_on_signal
    return function()
  File "/home/eve/PycharmProjects/ospf_enterprise/venv/lib/python3.6/site-packages/paramiko/client.py", line 349, in <lambda>
    retry_on_signal(lambda: sock.connect(addr))
socket.timeout: timed out

During handling of the above exception, another exception occurred:

Traceback (most recent call last):
  File "/home/eve/PycharmProjects/ospf_enterprise/venv/lib/python3.6/site-packages/nornir/core/task.py", line 85, in start
    r = self.task(self, **self.params)
  File "/home/eve/PycharmProjects/ospf_enterprise/venv/lib/python3.6/site-packages/nornir/plugins/tasks/networking/netmiko_send_command.py", line 26, in netmiko_send_command
    net_connect = task.host.get_connection("netmiko", task.nornir.config)
  File "/home/eve/PycharmProjects/ospf_enterprise/venv/lib/python3.6/site-packages/nornir/core/inventory.py", line 305, in get_connection
    extras=conn.extras,
  File "/home/eve/PycharmProjects/ospf_enterprise/venv/lib/python3.6/site-packages/nornir/core/inventory.py", line 365, in open_connection
    configuration=configuration,
  File "/home/eve/PycharmProjects/ospf_enterprise/venv/lib/python3.6/site-packages/nornir/plugins/connections/netmiko.py", line 58, in open
    self.connection = ConnectHandler(**parameters)
  File "/home/eve/PycharmProjects/ospf_enterprise/venv/lib/python3.6/site-packages/netmiko/ssh_dispatcher.py", line 302, in ConnectHandler
    return ConnectionClass(*args, **kwargs)
  File "/home/eve/PycharmProjects/ospf_enterprise/venv/lib/python3.6/site-packages/netmiko/cisco/cisco_ios.py", line 17, in __init__
    return super().__init__(*args, **kwargs)
  File "/home/eve/PycharmProjects/ospf_enterprise/venv/lib/python3.6/site-packages/netmiko/base_connection.py", line 344, in __init__
    self._open()
  File "/home/eve/PycharmProjects/ospf_enterprise/venv/lib/python3.6/site-packages/netmiko/base_connection.py", line 349, in _open
    self.establish_connection()
  File "/home/eve/PycharmProjects/ospf_enterprise/venv/lib/python3.6/site-packages/netmiko/base_connection.py", line 940, in establish_connection
    raise NetmikoTimeoutException(msg)
netmiko.ssh_exception.NetmikoTimeoutException: TCP connection to device failed.

Common causes of this problem are:
1. Incorrect hostname or IP address.
2. Wrong TCP port.
3. Intermediate firewall blocking access.

Device settings: cisco_xe 10.0.12.2:22



2020-09-12 22:23:25,372 - nornir.core.task -    ERROR -      start() - Host 'R2': task 'test' failed with traceback:
Traceback (most recent call last):
  File "/home/eve/PycharmProjects/ospf_enterprise/venv/lib/python3.6/site-packages/nornir/core/task.py", line 85, in start
    r = self.task(self, **self.params)
  File "ospf.py", line 14, in test
    result = task.run(netmiko_send_command, command_string='show ip ospf nei', use_genie=True)
  File "/home/eve/PycharmProjects/ospf_enterprise/venv/lib/python3.6/site-packages/nornir/core/task.py", line 147, in run
    raise NornirSubTaskError(task=task, result=r)
nornir.core.exceptions.NornirSubTaskError: Subtask: <function netmiko_send_command at 0x7f30efcb69d8> (failed)


2020-09-12 22:23:25,372 - nornir.core.task -    ERROR -      start() - Host 'R8': task 'netmiko_send_command' failed with traceback:
Traceback (most recent call last):
  File "/home/eve/PycharmProjects/ospf_enterprise/venv/lib/python3.6/site-packages/netmiko/base_connection.py", line 918, in establish_connection
    self.remote_conn_pre.connect(**ssh_connect_params)
  File "/home/eve/PycharmProjects/ospf_enterprise/venv/lib/python3.6/site-packages/paramiko/client.py", line 349, in connect
    retry_on_signal(lambda: sock.connect(addr))
  File "/home/eve/PycharmProjects/ospf_enterprise/venv/lib/python3.6/site-packages/paramiko/util.py", line 283, in retry_on_signal
    return function()
  File "/home/eve/PycharmProjects/ospf_enterprise/venv/lib/python3.6/site-packages/paramiko/client.py", line 349, in <lambda>
    retry_on_signal(lambda: sock.connect(addr))
socket.timeout: timed out

During handling of the above exception, another exception occurred:

Traceback (most recent call last):
  File "/home/eve/PycharmProjects/ospf_enterprise/venv/lib/python3.6/site-packages/nornir/core/task.py", line 85, in start
    r = self.task(self, **self.params)
  File "/home/eve/PycharmProjects/ospf_enterprise/venv/lib/python3.6/site-packages/nornir/plugins/tasks/networking/netmiko_send_command.py", line 26, in netmiko_send_command
    net_connect = task.host.get_connection("netmiko", task.nornir.config)
  File "/home/eve/PycharmProjects/ospf_enterprise/venv/lib/python3.6/site-packages/nornir/core/inventory.py", line 305, in get_connection
    extras=conn.extras,
  File "/home/eve/PycharmProjects/ospf_enterprise/venv/lib/python3.6/site-packages/nornir/core/inventory.py", line 365, in open_connection
    configuration=configuration,
  File "/home/eve/PycharmProjects/ospf_enterprise/venv/lib/python3.6/site-packages/nornir/plugins/connections/netmiko.py", line 58, in open
    self.connection = ConnectHandler(**parameters)
  File "/home/eve/PycharmProjects/ospf_enterprise/venv/lib/python3.6/site-packages/netmiko/ssh_dispatcher.py", line 302, in ConnectHandler
    return ConnectionClass(*args, **kwargs)
  File "/home/eve/PycharmProjects/ospf_enterprise/venv/lib/python3.6/site-packages/netmiko/cisco/cisco_ios.py", line 17, in __init__
    return super().__init__(*args, **kwargs)
  File "/home/eve/PycharmProjects/ospf_enterprise/venv/lib/python3.6/site-packages/netmiko/base_connection.py", line 344, in __init__
    self._open()
  File "/home/eve/PycharmProjects/ospf_enterprise/venv/lib/python3.6/site-packages/netmiko/base_connection.py", line 349, in _open
    self.establish_connection()
  File "/home/eve/PycharmProjects/ospf_enterprise/venv/lib/python3.6/site-packages/netmiko/base_connection.py", line 940, in establish_connection
    raise NetmikoTimeoutException(msg)
netmiko.ssh_exception.NetmikoTimeoutException: TCP connection to device failed.

Common causes of this problem are:
1. Incorrect hostname or IP address.
2. Wrong TCP port.
3. Intermediate firewall blocking access.

Device settings: cisco_xe 10.0.18.8:22



2020-09-12 22:23:25,372 - nornir.core.task -    ERROR -      start() - Host 'R8': task 'test' failed with traceback:
Traceback (most recent call last):
  File "/home/eve/PycharmProjects/ospf_enterprise/venv/lib/python3.6/site-packages/nornir/core/task.py", line 85, in start
    r = self.task(self, **self.params)
  File "ospf.py", line 14, in test
    result = task.run(netmiko_send_command, command_string='show ip ospf nei', use_genie=True)
  File "/home/eve/PycharmProjects/ospf_enterprise/venv/lib/python3.6/site-packages/nornir/core/task.py", line 147, in run
    raise NornirSubTaskError(task=task, result=r)
nornir.core.exceptions.NornirSubTaskError: Subtask: <function netmiko_send_command at 0x7f30efcb69d8> (failed)


2020-09-12 22:23:25,373 - nornir.core.task -    ERROR -      start() - Host 'R7': task 'netmiko_send_command' failed with traceback:
Traceback (most recent call last):
  File "/home/eve/PycharmProjects/ospf_enterprise/venv/lib/python3.6/site-packages/netmiko/base_connection.py", line 918, in establish_connection
    self.remote_conn_pre.connect(**ssh_connect_params)
  File "/home/eve/PycharmProjects/ospf_enterprise/venv/lib/python3.6/site-packages/paramiko/client.py", line 349, in connect
    retry_on_signal(lambda: sock.connect(addr))
  File "/home/eve/PycharmProjects/ospf_enterprise/venv/lib/python3.6/site-packages/paramiko/util.py", line 283, in retry_on_signal
    return function()
  File "/home/eve/PycharmProjects/ospf_enterprise/venv/lib/python3.6/site-packages/paramiko/client.py", line 349, in <lambda>
    retry_on_signal(lambda: sock.connect(addr))
socket.timeout: timed out

During handling of the above exception, another exception occurred:

Traceback (most recent call last):
  File "/home/eve/PycharmProjects/ospf_enterprise/venv/lib/python3.6/site-packages/nornir/core/task.py", line 85, in start
    r = self.task(self, **self.params)
  File "/home/eve/PycharmProjects/ospf_enterprise/venv/lib/python3.6/site-packages/nornir/plugins/tasks/networking/netmiko_send_command.py", line 26, in netmiko_send_command
    net_connect = task.host.get_connection("netmiko", task.nornir.config)
  File "/home/eve/PycharmProjects/ospf_enterprise/venv/lib/python3.6/site-packages/nornir/core/inventory.py", line 305, in get_connection
    extras=conn.extras,
  File "/home/eve/PycharmProjects/ospf_enterprise/venv/lib/python3.6/site-packages/nornir/core/inventory.py", line 365, in open_connection
    configuration=configuration,
  File "/home/eve/PycharmProjects/ospf_enterprise/venv/lib/python3.6/site-packages/nornir/plugins/connections/netmiko.py", line 58, in open
    self.connection = ConnectHandler(**parameters)
  File "/home/eve/PycharmProjects/ospf_enterprise/venv/lib/python3.6/site-packages/netmiko/ssh_dispatcher.py", line 302, in ConnectHandler
    return ConnectionClass(*args, **kwargs)
  File "/home/eve/PycharmProjects/ospf_enterprise/venv/lib/python3.6/site-packages/netmiko/cisco/cisco_ios.py", line 17, in __init__
    return super().__init__(*args, **kwargs)
  File "/home/eve/PycharmProjects/ospf_enterprise/venv/lib/python3.6/site-packages/netmiko/base_connection.py", line 344, in __init__
    self._open()
  File "/home/eve/PycharmProjects/ospf_enterprise/venv/lib/python3.6/site-packages/netmiko/base_connection.py", line 349, in _open
    self.establish_connection()
  File "/home/eve/PycharmProjects/ospf_enterprise/venv/lib/python3.6/site-packages/netmiko/base_connection.py", line 940, in establish_connection
    raise NetmikoTimeoutException(msg)
netmiko.ssh_exception.NetmikoTimeoutException: TCP connection to device failed.

Common causes of this problem are:
1. Incorrect hostname or IP address.
2. Wrong TCP port.
3. Intermediate firewall blocking access.

Device settings: cisco_xe 10.0.27.7:22



2020-09-12 22:23:25,373 - nornir.core.task -    ERROR -      start() - Host 'R7': task 'test' failed with traceback:
Traceback (most recent call last):
  File "/home/eve/PycharmProjects/ospf_enterprise/venv/lib/python3.6/site-packages/nornir/core/task.py", line 85, in start
    r = self.task(self, **self.params)
  File "ospf.py", line 14, in test
    result = task.run(netmiko_send_command, command_string='show ip ospf nei', use_genie=True)
  File "/home/eve/PycharmProjects/ospf_enterprise/venv/lib/python3.6/site-packages/nornir/core/task.py", line 147, in run
    raise NornirSubTaskError(task=task, result=r)
nornir.core.exceptions.NornirSubTaskError: Subtask: <function netmiko_send_command at 0x7f30efcb69d8> (failed)


2020-09-12 22:23:25,374 - nornir.core.task -    ERROR -      start() - Host 'R3': task 'netmiko_send_command' failed with traceback:
Traceback (most recent call last):
  File "/home/eve/PycharmProjects/ospf_enterprise/venv/lib/python3.6/site-packages/netmiko/base_connection.py", line 918, in establish_connection
    self.remote_conn_pre.connect(**ssh_connect_params)
  File "/home/eve/PycharmProjects/ospf_enterprise/venv/lib/python3.6/site-packages/paramiko/client.py", line 349, in connect
    retry_on_signal(lambda: sock.connect(addr))
  File "/home/eve/PycharmProjects/ospf_enterprise/venv/lib/python3.6/site-packages/paramiko/util.py", line 283, in retry_on_signal
    return function()
  File "/home/eve/PycharmProjects/ospf_enterprise/venv/lib/python3.6/site-packages/paramiko/client.py", line 349, in <lambda>
    retry_on_signal(lambda: sock.connect(addr))
socket.timeout: timed out

During handling of the above exception, another exception occurred:

Traceback (most recent call last):
  File "/home/eve/PycharmProjects/ospf_enterprise/venv/lib/python3.6/site-packages/nornir/core/task.py", line 85, in start
    r = self.task(self, **self.params)
  File "/home/eve/PycharmProjects/ospf_enterprise/venv/lib/python3.6/site-packages/nornir/plugins/tasks/networking/netmiko_send_command.py", line 26, in netmiko_send_command
    net_connect = task.host.get_connection("netmiko", task.nornir.config)
  File "/home/eve/PycharmProjects/ospf_enterprise/venv/lib/python3.6/site-packages/nornir/core/inventory.py", line 305, in get_connection
    extras=conn.extras,
  File "/home/eve/PycharmProjects/ospf_enterprise/venv/lib/python3.6/site-packages/nornir/core/inventory.py", line 365, in open_connection
    configuration=configuration,
  File "/home/eve/PycharmProjects/ospf_enterprise/venv/lib/python3.6/site-packages/nornir/plugins/connections/netmiko.py", line 58, in open
    self.connection = ConnectHandler(**parameters)
  File "/home/eve/PycharmProjects/ospf_enterprise/venv/lib/python3.6/site-packages/netmiko/ssh_dispatcher.py", line 302, in ConnectHandler
    return ConnectionClass(*args, **kwargs)
  File "/home/eve/PycharmProjects/ospf_enterprise/venv/lib/python3.6/site-packages/netmiko/cisco/cisco_ios.py", line 17, in __init__
    return super().__init__(*args, **kwargs)
  File "/home/eve/PycharmProjects/ospf_enterprise/venv/lib/python3.6/site-packages/netmiko/base_connection.py", line 344, in __init__
    self._open()
  File "/home/eve/PycharmProjects/ospf_enterprise/venv/lib/python3.6/site-packages/netmiko/base_connection.py", line 349, in _open
    self.establish_connection()
  File "/home/eve/PycharmProjects/ospf_enterprise/venv/lib/python3.6/site-packages/netmiko/base_connection.py", line 940, in establish_connection
    raise NetmikoTimeoutException(msg)
netmiko.ssh_exception.NetmikoTimeoutException: TCP connection to device failed.

Common causes of this problem are:
1. Incorrect hostname or IP address.
2. Wrong TCP port.
3. Intermediate firewall blocking access.

Device settings: cisco_xe 10.0.34.3:22



2020-09-12 22:23:25,374 - nornir.core.task -    ERROR -      start() - Host 'R3': task 'test' failed with traceback:
Traceback (most recent call last):
  File "/home/eve/PycharmProjects/ospf_enterprise/venv/lib/python3.6/site-packages/nornir/core/task.py", line 85, in start
    r = self.task(self, **self.params)
  File "ospf.py", line 14, in test
    result = task.run(netmiko_send_command, command_string='show ip ospf nei', use_genie=True)
  File "/home/eve/PycharmProjects/ospf_enterprise/venv/lib/python3.6/site-packages/nornir/core/task.py", line 147, in run
    raise NornirSubTaskError(task=task, result=r)
nornir.core.exceptions.NornirSubTaskError: Subtask: <function netmiko_send_command at 0x7f30efcb69d8> (failed)


2020-09-12 22:23:25,375 - nornir.core.task -    ERROR -      start() - Host 'R1': task 'netmiko_send_command' failed with traceback:
Traceback (most recent call last):
  File "/home/eve/PycharmProjects/ospf_enterprise/venv/lib/python3.6/site-packages/netmiko/base_connection.py", line 918, in establish_connection
    self.remote_conn_pre.connect(**ssh_connect_params)
  File "/home/eve/PycharmProjects/ospf_enterprise/venv/lib/python3.6/site-packages/paramiko/client.py", line 349, in connect
    retry_on_signal(lambda: sock.connect(addr))
  File "/home/eve/PycharmProjects/ospf_enterprise/venv/lib/python3.6/site-packages/paramiko/util.py", line 283, in retry_on_signal
    return function()
  File "/home/eve/PycharmProjects/ospf_enterprise/venv/lib/python3.6/site-packages/paramiko/client.py", line 349, in <lambda>
    retry_on_signal(lambda: sock.connect(addr))
socket.timeout: timed out

During handling of the above exception, another exception occurred:

Traceback (most recent call last):
  File "/home/eve/PycharmProjects/ospf_enterprise/venv/lib/python3.6/site-packages/nornir/core/task.py", line 85, in start
    r = self.task(self, **self.params)
  File "/home/eve/PycharmProjects/ospf_enterprise/venv/lib/python3.6/site-packages/nornir/plugins/tasks/networking/netmiko_send_command.py", line 26, in netmiko_send_command
    net_connect = task.host.get_connection("netmiko", task.nornir.config)
  File "/home/eve/PycharmProjects/ospf_enterprise/venv/lib/python3.6/site-packages/nornir/core/inventory.py", line 305, in get_connection
    extras=conn.extras,
  File "/home/eve/PycharmProjects/ospf_enterprise/venv/lib/python3.6/site-packages/nornir/core/inventory.py", line 365, in open_connection
    configuration=configuration,
  File "/home/eve/PycharmProjects/ospf_enterprise/venv/lib/python3.6/site-packages/nornir/plugins/connections/netmiko.py", line 58, in open
    self.connection = ConnectHandler(**parameters)
  File "/home/eve/PycharmProjects/ospf_enterprise/venv/lib/python3.6/site-packages/netmiko/ssh_dispatcher.py", line 302, in ConnectHandler
    return ConnectionClass(*args, **kwargs)
  File "/home/eve/PycharmProjects/ospf_enterprise/venv/lib/python3.6/site-packages/netmiko/cisco/cisco_ios.py", line 17, in __init__
    return super().__init__(*args, **kwargs)
  File "/home/eve/PycharmProjects/ospf_enterprise/venv/lib/python3.6/site-packages/netmiko/base_connection.py", line 344, in __init__
    self._open()
  File "/home/eve/PycharmProjects/ospf_enterprise/venv/lib/python3.6/site-packages/netmiko/base_connection.py", line 349, in _open
    self.establish_connection()
  File "/home/eve/PycharmProjects/ospf_enterprise/venv/lib/python3.6/site-packages/netmiko/base_connection.py", line 940, in establish_connection
    raise NetmikoTimeoutException(msg)
netmiko.ssh_exception.NetmikoTimeoutException: TCP connection to device failed.

Common causes of this problem are:
1. Incorrect hostname or IP address.
2. Wrong TCP port.
3. Intermediate firewall blocking access.

Device settings: cisco_xe 10.0.12.1:22



2020-09-12 22:23:25,375 - nornir.core.task -    ERROR -      start() - Host 'R1': task 'test' failed with traceback:
Traceback (most recent call last):
  File "/home/eve/PycharmProjects/ospf_enterprise/venv/lib/python3.6/site-packages/nornir/core/task.py", line 85, in start
    r = self.task(self, **self.params)
  File "ospf.py", line 14, in test
    result = task.run(netmiko_send_command, command_string='show ip ospf nei', use_genie=True)
  File "/home/eve/PycharmProjects/ospf_enterprise/venv/lib/python3.6/site-packages/nornir/core/task.py", line 147, in run
    raise NornirSubTaskError(task=task, result=r)
nornir.core.exceptions.NornirSubTaskError: Subtask: <function netmiko_send_command at 0x7f30efcb69d8> (failed)


2020-09-12 22:24:33,599 -  nornir.core -     INFO -        run() - Running task 'test' with args {} on 6 hosts
2020-09-12 22:25:06,421 -  nornir.core -     INFO -        run() - Running task 'test' with args {} on 6 hosts
2020-09-12 22:25:09,893 - nornir.core.task -    ERROR -      start() - Host 'R2': task 'test' failed with traceback:
Traceback (most recent call last):
  File "/home/eve/PycharmProjects/ospf_enterprise/venv/lib/python3.6/site-packages/urllib3/connection.py", line 160, in _new_conn
    (self._dns_host, self.port), self.timeout, **extra_kw
  File "/home/eve/PycharmProjects/ospf_enterprise/venv/lib/python3.6/site-packages/urllib3/util/connection.py", line 61, in create_connection
    for res in socket.getaddrinfo(host, port, family, socket.SOCK_STREAM):
  File "/usr/lib/python3.6/socket.py", line 745, in getaddrinfo
    for res in _socket.getaddrinfo(host, port, family, type, proto, flags):
socket.gaierror: [Errno -2] Name or service not known

During handling of the above exception, another exception occurred:

Traceback (most recent call last):
  File "/home/eve/PycharmProjects/ospf_enterprise/venv/lib/python3.6/site-packages/urllib3/connectionpool.py", line 677, in urlopen
    chunked=chunked,
  File "/home/eve/PycharmProjects/ospf_enterprise/venv/lib/python3.6/site-packages/urllib3/connectionpool.py", line 381, in _make_request
    self._validate_conn(conn)
  File "/home/eve/PycharmProjects/ospf_enterprise/venv/lib/python3.6/site-packages/urllib3/connectionpool.py", line 978, in _validate_conn
    conn.connect()
  File "/home/eve/PycharmProjects/ospf_enterprise/venv/lib/python3.6/site-packages/urllib3/connection.py", line 309, in connect
    conn = self._new_conn()
  File "/home/eve/PycharmProjects/ospf_enterprise/venv/lib/python3.6/site-packages/urllib3/connection.py", line 172, in _new_conn
    self, "Failed to establish a new connection: %s" % e
urllib3.exceptions.NewConnectionError: <urllib3.connection.HTTPSConnection object at 0x7f9eb27bf518>: Failed to establish a new connection: [Errno -2] Name or service not known

During handling of the above exception, another exception occurred:

Traceback (most recent call last):
  File "/home/eve/PycharmProjects/ospf_enterprise/venv/lib/python3.6/site-packages/requests/adapters.py", line 449, in send
    timeout=timeout
  File "/home/eve/PycharmProjects/ospf_enterprise/venv/lib/python3.6/site-packages/urllib3/connectionpool.py", line 727, in urlopen
    method, url, error=e, _pool=self, _stacktrace=sys.exc_info()[2]
  File "/home/eve/PycharmProjects/ospf_enterprise/venv/lib/python3.6/site-packages/urllib3/util/retry.py", line 439, in increment
    raise MaxRetryError(_pool, url, error or ResponseError(cause))
urllib3.exceptions.MaxRetryError: HTTPSConnectionPool(host='api.ciscospark.com', port=443): Max retries exceeded with url: /v1/messages (Caused by NewConnectionError('<urllib3.connection.HTTPSConnection object at 0x7f9eb27bf518>: Failed to establish a new connection: [Errno -2] Name or service not known',))

During handling of the above exception, another exception occurred:

Traceback (most recent call last):
  File "/home/eve/PycharmProjects/ospf_enterprise/venv/lib/python3.6/site-packages/nornir/core/task.py", line 85, in start
    r = self.task(self, **self.params)
  File "ospf.py", line 27, in test
    failed_report(dev_name)
  File "ospf.py", line 35, in failed_report
    return requests.post("https://api.ciscospark.com/v1/messages", headers=header, data=json.dumps(data), verify=True)
  File "/home/eve/PycharmProjects/ospf_enterprise/venv/lib/python3.6/site-packages/requests/api.py", line 119, in post
    return request('post', url, data=data, json=json, **kwargs)
  File "/home/eve/PycharmProjects/ospf_enterprise/venv/lib/python3.6/site-packages/requests/api.py", line 61, in request
    return session.request(method=method, url=url, **kwargs)
  File "/home/eve/PycharmProjects/ospf_enterprise/venv/lib/python3.6/site-packages/requests/sessions.py", line 530, in request
    resp = self.send(prep, **send_kwargs)
  File "/home/eve/PycharmProjects/ospf_enterprise/venv/lib/python3.6/site-packages/requests/sessions.py", line 643, in send
    r = adapter.send(request, **kwargs)
  File "/home/eve/PycharmProjects/ospf_enterprise/venv/lib/python3.6/site-packages/requests/adapters.py", line 516, in send
    raise ConnectionError(e, request=request)
requests.exceptions.ConnectionError: HTTPSConnectionPool(host='api.ciscospark.com', port=443): Max retries exceeded with url: /v1/messages (Caused by NewConnectionError('<urllib3.connection.HTTPSConnection object at 0x7f9eb27bf518>: Failed to establish a new connection: [Errno -2] Name or service not known',))

2020-09-12 22:25:09,895 - nornir.core.task -    ERROR -      start() - Host 'R3': task 'test' failed with traceback:
Traceback (most recent call last):
  File "/home/eve/PycharmProjects/ospf_enterprise/venv/lib/python3.6/site-packages/urllib3/connection.py", line 160, in _new_conn
    (self._dns_host, self.port), self.timeout, **extra_kw
  File "/home/eve/PycharmProjects/ospf_enterprise/venv/lib/python3.6/site-packages/urllib3/util/connection.py", line 61, in create_connection
    for res in socket.getaddrinfo(host, port, family, socket.SOCK_STREAM):
  File "/usr/lib/python3.6/socket.py", line 745, in getaddrinfo
    for res in _socket.getaddrinfo(host, port, family, type, proto, flags):
socket.gaierror: [Errno -2] Name or service not known

During handling of the above exception, another exception occurred:

Traceback (most recent call last):
  File "/home/eve/PycharmProjects/ospf_enterprise/venv/lib/python3.6/site-packages/urllib3/connectionpool.py", line 677, in urlopen
    chunked=chunked,
  File "/home/eve/PycharmProjects/ospf_enterprise/venv/lib/python3.6/site-packages/urllib3/connectionpool.py", line 381, in _make_request
    self._validate_conn(conn)
  File "/home/eve/PycharmProjects/ospf_enterprise/venv/lib/python3.6/site-packages/urllib3/connectionpool.py", line 978, in _validate_conn
    conn.connect()
  File "/home/eve/PycharmProjects/ospf_enterprise/venv/lib/python3.6/site-packages/urllib3/connection.py", line 309, in connect
    conn = self._new_conn()
  File "/home/eve/PycharmProjects/ospf_enterprise/venv/lib/python3.6/site-packages/urllib3/connection.py", line 172, in _new_conn
    self, "Failed to establish a new connection: %s" % e
urllib3.exceptions.NewConnectionError: <urllib3.connection.HTTPSConnection object at 0x7f9eb27bf908>: Failed to establish a new connection: [Errno -2] Name or service not known

During handling of the above exception, another exception occurred:

Traceback (most recent call last):
  File "/home/eve/PycharmProjects/ospf_enterprise/venv/lib/python3.6/site-packages/requests/adapters.py", line 449, in send
    timeout=timeout
  File "/home/eve/PycharmProjects/ospf_enterprise/venv/lib/python3.6/site-packages/urllib3/connectionpool.py", line 727, in urlopen
    method, url, error=e, _pool=self, _stacktrace=sys.exc_info()[2]
  File "/home/eve/PycharmProjects/ospf_enterprise/venv/lib/python3.6/site-packages/urllib3/util/retry.py", line 439, in increment
    raise MaxRetryError(_pool, url, error or ResponseError(cause))
urllib3.exceptions.MaxRetryError: HTTPSConnectionPool(host='api.ciscospark.com', port=443): Max retries exceeded with url: /v1/messages (Caused by NewConnectionError('<urllib3.connection.HTTPSConnection object at 0x7f9eb27bf908>: Failed to establish a new connection: [Errno -2] Name or service not known',))

During handling of the above exception, another exception occurred:

Traceback (most recent call last):
  File "/home/eve/PycharmProjects/ospf_enterprise/venv/lib/python3.6/site-packages/nornir/core/task.py", line 85, in start
    r = self.task(self, **self.params)
  File "ospf.py", line 27, in test
    failed_report(dev_name)
  File "ospf.py", line 35, in failed_report
    return requests.post("https://api.ciscospark.com/v1/messages", headers=header, data=json.dumps(data), verify=True)
  File "/home/eve/PycharmProjects/ospf_enterprise/venv/lib/python3.6/site-packages/requests/api.py", line 119, in post
    return request('post', url, data=data, json=json, **kwargs)
  File "/home/eve/PycharmProjects/ospf_enterprise/venv/lib/python3.6/site-packages/requests/api.py", line 61, in request
    return session.request(method=method, url=url, **kwargs)
  File "/home/eve/PycharmProjects/ospf_enterprise/venv/lib/python3.6/site-packages/requests/sessions.py", line 530, in request
    resp = self.send(prep, **send_kwargs)
  File "/home/eve/PycharmProjects/ospf_enterprise/venv/lib/python3.6/site-packages/requests/sessions.py", line 643, in send
    r = adapter.send(request, **kwargs)
  File "/home/eve/PycharmProjects/ospf_enterprise/venv/lib/python3.6/site-packages/requests/adapters.py", line 516, in send
    raise ConnectionError(e, request=request)
requests.exceptions.ConnectionError: HTTPSConnectionPool(host='api.ciscospark.com', port=443): Max retries exceeded with url: /v1/messages (Caused by NewConnectionError('<urllib3.connection.HTTPSConnection object at 0x7f9eb27bf908>: Failed to establish a new connection: [Errno -2] Name or service not known',))

2020-09-12 22:25:09,896 - nornir.core.task -    ERROR -      start() - Host 'R1': task 'test' failed with traceback:
Traceback (most recent call last):
  File "/home/eve/PycharmProjects/ospf_enterprise/venv/lib/python3.6/site-packages/urllib3/connection.py", line 160, in _new_conn
    (self._dns_host, self.port), self.timeout, **extra_kw
  File "/home/eve/PycharmProjects/ospf_enterprise/venv/lib/python3.6/site-packages/urllib3/util/connection.py", line 61, in create_connection
    for res in socket.getaddrinfo(host, port, family, socket.SOCK_STREAM):
  File "/usr/lib/python3.6/socket.py", line 745, in getaddrinfo
    for res in _socket.getaddrinfo(host, port, family, type, proto, flags):
socket.gaierror: [Errno -2] Name or service not known

During handling of the above exception, another exception occurred:

Traceback (most recent call last):
  File "/home/eve/PycharmProjects/ospf_enterprise/venv/lib/python3.6/site-packages/urllib3/connectionpool.py", line 677, in urlopen
    chunked=chunked,
  File "/home/eve/PycharmProjects/ospf_enterprise/venv/lib/python3.6/site-packages/urllib3/connectionpool.py", line 381, in _make_request
    self._validate_conn(conn)
  File "/home/eve/PycharmProjects/ospf_enterprise/venv/lib/python3.6/site-packages/urllib3/connectionpool.py", line 978, in _validate_conn
    conn.connect()
  File "/home/eve/PycharmProjects/ospf_enterprise/venv/lib/python3.6/site-packages/urllib3/connection.py", line 309, in connect
    conn = self._new_conn()
  File "/home/eve/PycharmProjects/ospf_enterprise/venv/lib/python3.6/site-packages/urllib3/connection.py", line 172, in _new_conn
    self, "Failed to establish a new connection: %s" % e
urllib3.exceptions.NewConnectionError: <urllib3.connection.HTTPSConnection object at 0x7f9eb27bf630>: Failed to establish a new connection: [Errno -2] Name or service not known

During handling of the above exception, another exception occurred:

Traceback (most recent call last):
  File "/home/eve/PycharmProjects/ospf_enterprise/venv/lib/python3.6/site-packages/requests/adapters.py", line 449, in send
    timeout=timeout
  File "/home/eve/PycharmProjects/ospf_enterprise/venv/lib/python3.6/site-packages/urllib3/connectionpool.py", line 727, in urlopen
    method, url, error=e, _pool=self, _stacktrace=sys.exc_info()[2]
  File "/home/eve/PycharmProjects/ospf_enterprise/venv/lib/python3.6/site-packages/urllib3/util/retry.py", line 439, in increment
    raise MaxRetryError(_pool, url, error or ResponseError(cause))
urllib3.exceptions.MaxRetryError: HTTPSConnectionPool(host='api.ciscospark.com', port=443): Max retries exceeded with url: /v1/messages (Caused by NewConnectionError('<urllib3.connection.HTTPSConnection object at 0x7f9eb27bf630>: Failed to establish a new connection: [Errno -2] Name or service not known',))

During handling of the above exception, another exception occurred:

Traceback (most recent call last):
  File "/home/eve/PycharmProjects/ospf_enterprise/venv/lib/python3.6/site-packages/nornir/core/task.py", line 85, in start
    r = self.task(self, **self.params)
  File "ospf.py", line 27, in test
    failed_report(dev_name)
  File "ospf.py", line 35, in failed_report
    return requests.post("https://api.ciscospark.com/v1/messages", headers=header, data=json.dumps(data), verify=True)
  File "/home/eve/PycharmProjects/ospf_enterprise/venv/lib/python3.6/site-packages/requests/api.py", line 119, in post
    return request('post', url, data=data, json=json, **kwargs)
  File "/home/eve/PycharmProjects/ospf_enterprise/venv/lib/python3.6/site-packages/requests/api.py", line 61, in request
    return session.request(method=method, url=url, **kwargs)
  File "/home/eve/PycharmProjects/ospf_enterprise/venv/lib/python3.6/site-packages/requests/sessions.py", line 530, in request
    resp = self.send(prep, **send_kwargs)
  File "/home/eve/PycharmProjects/ospf_enterprise/venv/lib/python3.6/site-packages/requests/sessions.py", line 643, in send
    r = adapter.send(request, **kwargs)
  File "/home/eve/PycharmProjects/ospf_enterprise/venv/lib/python3.6/site-packages/requests/adapters.py", line 516, in send
    raise ConnectionError(e, request=request)
requests.exceptions.ConnectionError: HTTPSConnectionPool(host='api.ciscospark.com', port=443): Max retries exceeded with url: /v1/messages (Caused by NewConnectionError('<urllib3.connection.HTTPSConnection object at 0x7f9eb27bf630>: Failed to establish a new connection: [Errno -2] Name or service not known',))

2020-09-12 22:26:28,952 -  nornir.core -     INFO -        run() - Running task 'test' with args {} on 6 hosts
2020-09-12 22:33:11,915 -  nornir.core -     INFO -        run() - Running task 'test' with args {} on 6 hosts
2020-09-12 22:33:16,929 - nornir.core.task -    ERROR -      start() - Host 'R1': task 'netmiko_send_command' failed with traceback:
Traceback (most recent call last):
  File "/home/eve/PycharmProjects/ospf_enterprise/venv/lib/python3.6/site-packages/netmiko/base_connection.py", line 918, in establish_connection
    self.remote_conn_pre.connect(**ssh_connect_params)
  File "/home/eve/PycharmProjects/ospf_enterprise/venv/lib/python3.6/site-packages/paramiko/client.py", line 349, in connect
    retry_on_signal(lambda: sock.connect(addr))
  File "/home/eve/PycharmProjects/ospf_enterprise/venv/lib/python3.6/site-packages/paramiko/util.py", line 283, in retry_on_signal
    return function()
  File "/home/eve/PycharmProjects/ospf_enterprise/venv/lib/python3.6/site-packages/paramiko/client.py", line 349, in <lambda>
    retry_on_signal(lambda: sock.connect(addr))
socket.timeout: timed out

During handling of the above exception, another exception occurred:

Traceback (most recent call last):
  File "/home/eve/PycharmProjects/ospf_enterprise/venv/lib/python3.6/site-packages/nornir/core/task.py", line 85, in start
    r = self.task(self, **self.params)
  File "/home/eve/PycharmProjects/ospf_enterprise/venv/lib/python3.6/site-packages/nornir/plugins/tasks/networking/netmiko_send_command.py", line 26, in netmiko_send_command
    net_connect = task.host.get_connection("netmiko", task.nornir.config)
  File "/home/eve/PycharmProjects/ospf_enterprise/venv/lib/python3.6/site-packages/nornir/core/inventory.py", line 305, in get_connection
    extras=conn.extras,
  File "/home/eve/PycharmProjects/ospf_enterprise/venv/lib/python3.6/site-packages/nornir/core/inventory.py", line 365, in open_connection
    configuration=configuration,
  File "/home/eve/PycharmProjects/ospf_enterprise/venv/lib/python3.6/site-packages/nornir/plugins/connections/netmiko.py", line 58, in open
    self.connection = ConnectHandler(**parameters)
  File "/home/eve/PycharmProjects/ospf_enterprise/venv/lib/python3.6/site-packages/netmiko/ssh_dispatcher.py", line 302, in ConnectHandler
    return ConnectionClass(*args, **kwargs)
  File "/home/eve/PycharmProjects/ospf_enterprise/venv/lib/python3.6/site-packages/netmiko/cisco/cisco_ios.py", line 17, in __init__
    return super().__init__(*args, **kwargs)
  File "/home/eve/PycharmProjects/ospf_enterprise/venv/lib/python3.6/site-packages/netmiko/base_connection.py", line 344, in __init__
    self._open()
  File "/home/eve/PycharmProjects/ospf_enterprise/venv/lib/python3.6/site-packages/netmiko/base_connection.py", line 349, in _open
    self.establish_connection()
  File "/home/eve/PycharmProjects/ospf_enterprise/venv/lib/python3.6/site-packages/netmiko/base_connection.py", line 940, in establish_connection
    raise NetmikoTimeoutException(msg)
netmiko.ssh_exception.NetmikoTimeoutException: TCP connection to device failed.

Common causes of this problem are:
1. Incorrect hostname or IP address.
2. Wrong TCP port.
3. Intermediate firewall blocking access.

Device settings: cisco_xe 10.0.12.1:22



2020-09-12 22:33:16,930 - nornir.core.task -    ERROR -      start() - Host 'R1': task 'test' failed with traceback:
Traceback (most recent call last):
  File "/home/eve/PycharmProjects/ospf_enterprise/venv/lib/python3.6/site-packages/nornir/core/task.py", line 85, in start
    r = self.task(self, **self.params)
  File "ospf.py", line 14, in test
    result = task.run(netmiko_send_command, command_string='show ip ospf nei', use_genie=True)
  File "/home/eve/PycharmProjects/ospf_enterprise/venv/lib/python3.6/site-packages/nornir/core/task.py", line 147, in run
    raise NornirSubTaskError(task=task, result=r)
nornir.core.exceptions.NornirSubTaskError: Subtask: <function netmiko_send_command at 0x7f829c63e9d8> (failed)


2020-09-12 22:33:16,936 - nornir.core.task -    ERROR -      start() - Host 'R3': task 'netmiko_send_command' failed with traceback:
Traceback (most recent call last):
  File "/home/eve/PycharmProjects/ospf_enterprise/venv/lib/python3.6/site-packages/netmiko/base_connection.py", line 918, in establish_connection
    self.remote_conn_pre.connect(**ssh_connect_params)
  File "/home/eve/PycharmProjects/ospf_enterprise/venv/lib/python3.6/site-packages/paramiko/client.py", line 349, in connect
    retry_on_signal(lambda: sock.connect(addr))
  File "/home/eve/PycharmProjects/ospf_enterprise/venv/lib/python3.6/site-packages/paramiko/util.py", line 283, in retry_on_signal
    return function()
  File "/home/eve/PycharmProjects/ospf_enterprise/venv/lib/python3.6/site-packages/paramiko/client.py", line 349, in <lambda>
    retry_on_signal(lambda: sock.connect(addr))
socket.timeout: timed out

During handling of the above exception, another exception occurred:

Traceback (most recent call last):
  File "/home/eve/PycharmProjects/ospf_enterprise/venv/lib/python3.6/site-packages/nornir/core/task.py", line 85, in start
    r = self.task(self, **self.params)
  File "/home/eve/PycharmProjects/ospf_enterprise/venv/lib/python3.6/site-packages/nornir/plugins/tasks/networking/netmiko_send_command.py", line 26, in netmiko_send_command
    net_connect = task.host.get_connection("netmiko", task.nornir.config)
  File "/home/eve/PycharmProjects/ospf_enterprise/venv/lib/python3.6/site-packages/nornir/core/inventory.py", line 305, in get_connection
    extras=conn.extras,
  File "/home/eve/PycharmProjects/ospf_enterprise/venv/lib/python3.6/site-packages/nornir/core/inventory.py", line 365, in open_connection
    configuration=configuration,
  File "/home/eve/PycharmProjects/ospf_enterprise/venv/lib/python3.6/site-packages/nornir/plugins/connections/netmiko.py", line 58, in open
    self.connection = ConnectHandler(**parameters)
  File "/home/eve/PycharmProjects/ospf_enterprise/venv/lib/python3.6/site-packages/netmiko/ssh_dispatcher.py", line 302, in ConnectHandler
    return ConnectionClass(*args, **kwargs)
  File "/home/eve/PycharmProjects/ospf_enterprise/venv/lib/python3.6/site-packages/netmiko/cisco/cisco_ios.py", line 17, in __init__
    return super().__init__(*args, **kwargs)
  File "/home/eve/PycharmProjects/ospf_enterprise/venv/lib/python3.6/site-packages/netmiko/base_connection.py", line 344, in __init__
    self._open()
  File "/home/eve/PycharmProjects/ospf_enterprise/venv/lib/python3.6/site-packages/netmiko/base_connection.py", line 349, in _open
    self.establish_connection()
  File "/home/eve/PycharmProjects/ospf_enterprise/venv/lib/python3.6/site-packages/netmiko/base_connection.py", line 940, in establish_connection
    raise NetmikoTimeoutException(msg)
netmiko.ssh_exception.NetmikoTimeoutException: TCP connection to device failed.

Common causes of this problem are:
1. Incorrect hostname or IP address.
2. Wrong TCP port.
3. Intermediate firewall blocking access.

Device settings: cisco_xe 10.0.34.3:22



2020-09-12 22:33:16,937 - nornir.core.task -    ERROR -      start() - Host 'R3': task 'test' failed with traceback:
Traceback (most recent call last):
  File "/home/eve/PycharmProjects/ospf_enterprise/venv/lib/python3.6/site-packages/nornir/core/task.py", line 85, in start
    r = self.task(self, **self.params)
  File "ospf.py", line 14, in test
    result = task.run(netmiko_send_command, command_string='show ip ospf nei', use_genie=True)
  File "/home/eve/PycharmProjects/ospf_enterprise/venv/lib/python3.6/site-packages/nornir/core/task.py", line 147, in run
    raise NornirSubTaskError(task=task, result=r)
nornir.core.exceptions.NornirSubTaskError: Subtask: <function netmiko_send_command at 0x7f829c63e9d8> (failed)


2020-09-12 22:33:16,939 - nornir.core.task -    ERROR -      start() - Host 'R2': task 'netmiko_send_command' failed with traceback:
Traceback (most recent call last):
  File "/home/eve/PycharmProjects/ospf_enterprise/venv/lib/python3.6/site-packages/netmiko/base_connection.py", line 918, in establish_connection
    self.remote_conn_pre.connect(**ssh_connect_params)
  File "/home/eve/PycharmProjects/ospf_enterprise/venv/lib/python3.6/site-packages/paramiko/client.py", line 349, in connect
    retry_on_signal(lambda: sock.connect(addr))
  File "/home/eve/PycharmProjects/ospf_enterprise/venv/lib/python3.6/site-packages/paramiko/util.py", line 283, in retry_on_signal
    return function()
  File "/home/eve/PycharmProjects/ospf_enterprise/venv/lib/python3.6/site-packages/paramiko/client.py", line 349, in <lambda>
    retry_on_signal(lambda: sock.connect(addr))
socket.timeout: timed out

During handling of the above exception, another exception occurred:

Traceback (most recent call last):
  File "/home/eve/PycharmProjects/ospf_enterprise/venv/lib/python3.6/site-packages/nornir/core/task.py", line 85, in start
    r = self.task(self, **self.params)
  File "/home/eve/PycharmProjects/ospf_enterprise/venv/lib/python3.6/site-packages/nornir/plugins/tasks/networking/netmiko_send_command.py", line 26, in netmiko_send_command
    net_connect = task.host.get_connection("netmiko", task.nornir.config)
  File "/home/eve/PycharmProjects/ospf_enterprise/venv/lib/python3.6/site-packages/nornir/core/inventory.py", line 305, in get_connection
    extras=conn.extras,
  File "/home/eve/PycharmProjects/ospf_enterprise/venv/lib/python3.6/site-packages/nornir/core/inventory.py", line 365, in open_connection
    configuration=configuration,
  File "/home/eve/PycharmProjects/ospf_enterprise/venv/lib/python3.6/site-packages/nornir/plugins/connections/netmiko.py", line 58, in open
    self.connection = ConnectHandler(**parameters)
  File "/home/eve/PycharmProjects/ospf_enterprise/venv/lib/python3.6/site-packages/netmiko/ssh_dispatcher.py", line 302, in ConnectHandler
    return ConnectionClass(*args, **kwargs)
  File "/home/eve/PycharmProjects/ospf_enterprise/venv/lib/python3.6/site-packages/netmiko/cisco/cisco_ios.py", line 17, in __init__
    return super().__init__(*args, **kwargs)
  File "/home/eve/PycharmProjects/ospf_enterprise/venv/lib/python3.6/site-packages/netmiko/base_connection.py", line 344, in __init__
    self._open()
  File "/home/eve/PycharmProjects/ospf_enterprise/venv/lib/python3.6/site-packages/netmiko/base_connection.py", line 349, in _open
    self.establish_connection()
  File "/home/eve/PycharmProjects/ospf_enterprise/venv/lib/python3.6/site-packages/netmiko/base_connection.py", line 940, in establish_connection
    raise NetmikoTimeoutException(msg)
netmiko.ssh_exception.NetmikoTimeoutException: TCP connection to device failed.

Common causes of this problem are:
1. Incorrect hostname or IP address.
2. Wrong TCP port.
3. Intermediate firewall blocking access.

Device settings: cisco_xe 10.0.12.2:22



2020-09-12 22:33:16,939 - nornir.core.task -    ERROR -      start() - Host 'R2': task 'test' failed with traceback:
Traceback (most recent call last):
  File "/home/eve/PycharmProjects/ospf_enterprise/venv/lib/python3.6/site-packages/nornir/core/task.py", line 85, in start
    r = self.task(self, **self.params)
  File "ospf.py", line 14, in test
    result = task.run(netmiko_send_command, command_string='show ip ospf nei', use_genie=True)
  File "/home/eve/PycharmProjects/ospf_enterprise/venv/lib/python3.6/site-packages/nornir/core/task.py", line 147, in run
    raise NornirSubTaskError(task=task, result=r)
nornir.core.exceptions.NornirSubTaskError: Subtask: <function netmiko_send_command at 0x7f829c63e9d8> (failed)


2020-09-12 22:33:16,940 - nornir.core.task -    ERROR -      start() - Host 'R7': task 'netmiko_send_command' failed with traceback:
Traceback (most recent call last):
  File "/home/eve/PycharmProjects/ospf_enterprise/venv/lib/python3.6/site-packages/netmiko/base_connection.py", line 918, in establish_connection
    self.remote_conn_pre.connect(**ssh_connect_params)
  File "/home/eve/PycharmProjects/ospf_enterprise/venv/lib/python3.6/site-packages/paramiko/client.py", line 349, in connect
    retry_on_signal(lambda: sock.connect(addr))
  File "/home/eve/PycharmProjects/ospf_enterprise/venv/lib/python3.6/site-packages/paramiko/util.py", line 283, in retry_on_signal
    return function()
  File "/home/eve/PycharmProjects/ospf_enterprise/venv/lib/python3.6/site-packages/paramiko/client.py", line 349, in <lambda>
    retry_on_signal(lambda: sock.connect(addr))
socket.timeout: timed out

During handling of the above exception, another exception occurred:

Traceback (most recent call last):
  File "/home/eve/PycharmProjects/ospf_enterprise/venv/lib/python3.6/site-packages/nornir/core/task.py", line 85, in start
    r = self.task(self, **self.params)
  File "/home/eve/PycharmProjects/ospf_enterprise/venv/lib/python3.6/site-packages/nornir/plugins/tasks/networking/netmiko_send_command.py", line 26, in netmiko_send_command
    net_connect = task.host.get_connection("netmiko", task.nornir.config)
  File "/home/eve/PycharmProjects/ospf_enterprise/venv/lib/python3.6/site-packages/nornir/core/inventory.py", line 305, in get_connection
    extras=conn.extras,
  File "/home/eve/PycharmProjects/ospf_enterprise/venv/lib/python3.6/site-packages/nornir/core/inventory.py", line 365, in open_connection
    configuration=configuration,
  File "/home/eve/PycharmProjects/ospf_enterprise/venv/lib/python3.6/site-packages/nornir/plugins/connections/netmiko.py", line 58, in open
    self.connection = ConnectHandler(**parameters)
  File "/home/eve/PycharmProjects/ospf_enterprise/venv/lib/python3.6/site-packages/netmiko/ssh_dispatcher.py", line 302, in ConnectHandler
    return ConnectionClass(*args, **kwargs)
  File "/home/eve/PycharmProjects/ospf_enterprise/venv/lib/python3.6/site-packages/netmiko/cisco/cisco_ios.py", line 17, in __init__
    return super().__init__(*args, **kwargs)
  File "/home/eve/PycharmProjects/ospf_enterprise/venv/lib/python3.6/site-packages/netmiko/base_connection.py", line 344, in __init__
    self._open()
  File "/home/eve/PycharmProjects/ospf_enterprise/venv/lib/python3.6/site-packages/netmiko/base_connection.py", line 349, in _open
    self.establish_connection()
  File "/home/eve/PycharmProjects/ospf_enterprise/venv/lib/python3.6/site-packages/netmiko/base_connection.py", line 940, in establish_connection
    raise NetmikoTimeoutException(msg)
netmiko.ssh_exception.NetmikoTimeoutException: TCP connection to device failed.

Common causes of this problem are:
1. Incorrect hostname or IP address.
2. Wrong TCP port.
3. Intermediate firewall blocking access.

Device settings: cisco_xe 10.0.27.7:22



2020-09-12 22:33:16,940 - nornir.core.task -    ERROR -      start() - Host 'R7': task 'test' failed with traceback:
Traceback (most recent call last):
  File "/home/eve/PycharmProjects/ospf_enterprise/venv/lib/python3.6/site-packages/nornir/core/task.py", line 85, in start
    r = self.task(self, **self.params)
  File "ospf.py", line 14, in test
    result = task.run(netmiko_send_command, command_string='show ip ospf nei', use_genie=True)
  File "/home/eve/PycharmProjects/ospf_enterprise/venv/lib/python3.6/site-packages/nornir/core/task.py", line 147, in run
    raise NornirSubTaskError(task=task, result=r)
nornir.core.exceptions.NornirSubTaskError: Subtask: <function netmiko_send_command at 0x7f829c63e9d8> (failed)


2020-09-12 22:33:16,943 - nornir.core.task -    ERROR -      start() - Host 'R4': task 'netmiko_send_command' failed with traceback:
Traceback (most recent call last):
  File "/home/eve/PycharmProjects/ospf_enterprise/venv/lib/python3.6/site-packages/netmiko/base_connection.py", line 918, in establish_connection
    self.remote_conn_pre.connect(**ssh_connect_params)
  File "/home/eve/PycharmProjects/ospf_enterprise/venv/lib/python3.6/site-packages/paramiko/client.py", line 349, in connect
    retry_on_signal(lambda: sock.connect(addr))
  File "/home/eve/PycharmProjects/ospf_enterprise/venv/lib/python3.6/site-packages/paramiko/util.py", line 283, in retry_on_signal
    return function()
  File "/home/eve/PycharmProjects/ospf_enterprise/venv/lib/python3.6/site-packages/paramiko/client.py", line 349, in <lambda>
    retry_on_signal(lambda: sock.connect(addr))
socket.timeout: timed out

During handling of the above exception, another exception occurred:

Traceback (most recent call last):
  File "/home/eve/PycharmProjects/ospf_enterprise/venv/lib/python3.6/site-packages/nornir/core/task.py", line 85, in start
    r = self.task(self, **self.params)
  File "/home/eve/PycharmProjects/ospf_enterprise/venv/lib/python3.6/site-packages/nornir/plugins/tasks/networking/netmiko_send_command.py", line 26, in netmiko_send_command
    net_connect = task.host.get_connection("netmiko", task.nornir.config)
  File "/home/eve/PycharmProjects/ospf_enterprise/venv/lib/python3.6/site-packages/nornir/core/inventory.py", line 305, in get_connection
    extras=conn.extras,
  File "/home/eve/PycharmProjects/ospf_enterprise/venv/lib/python3.6/site-packages/nornir/core/inventory.py", line 365, in open_connection
    configuration=configuration,
  File "/home/eve/PycharmProjects/ospf_enterprise/venv/lib/python3.6/site-packages/nornir/plugins/connections/netmiko.py", line 58, in open
    self.connection = ConnectHandler(**parameters)
  File "/home/eve/PycharmProjects/ospf_enterprise/venv/lib/python3.6/site-packages/netmiko/ssh_dispatcher.py", line 302, in ConnectHandler
    return ConnectionClass(*args, **kwargs)
  File "/home/eve/PycharmProjects/ospf_enterprise/venv/lib/python3.6/site-packages/netmiko/cisco/cisco_ios.py", line 17, in __init__
    return super().__init__(*args, **kwargs)
  File "/home/eve/PycharmProjects/ospf_enterprise/venv/lib/python3.6/site-packages/netmiko/base_connection.py", line 344, in __init__
    self._open()
  File "/home/eve/PycharmProjects/ospf_enterprise/venv/lib/python3.6/site-packages/netmiko/base_connection.py", line 349, in _open
    self.establish_connection()
  File "/home/eve/PycharmProjects/ospf_enterprise/venv/lib/python3.6/site-packages/netmiko/base_connection.py", line 940, in establish_connection
    raise NetmikoTimeoutException(msg)
netmiko.ssh_exception.NetmikoTimeoutException: TCP connection to device failed.

Common causes of this problem are:
1. Incorrect hostname or IP address.
2. Wrong TCP port.
3. Intermediate firewall blocking access.

Device settings: cisco_xe 10.0.34.4:22



2020-09-12 22:33:16,943 - nornir.core.task -    ERROR -      start() - Host 'R4': task 'test' failed with traceback:
Traceback (most recent call last):
  File "/home/eve/PycharmProjects/ospf_enterprise/venv/lib/python3.6/site-packages/nornir/core/task.py", line 85, in start
    r = self.task(self, **self.params)
  File "ospf.py", line 14, in test
    result = task.run(netmiko_send_command, command_string='show ip ospf nei', use_genie=True)
  File "/home/eve/PycharmProjects/ospf_enterprise/venv/lib/python3.6/site-packages/nornir/core/task.py", line 147, in run
    raise NornirSubTaskError(task=task, result=r)
nornir.core.exceptions.NornirSubTaskError: Subtask: <function netmiko_send_command at 0x7f829c63e9d8> (failed)


2020-09-12 22:33:16,944 - nornir.core.task -    ERROR -      start() - Host 'R8': task 'netmiko_send_command' failed with traceback:
Traceback (most recent call last):
  File "/home/eve/PycharmProjects/ospf_enterprise/venv/lib/python3.6/site-packages/netmiko/base_connection.py", line 918, in establish_connection
    self.remote_conn_pre.connect(**ssh_connect_params)
  File "/home/eve/PycharmProjects/ospf_enterprise/venv/lib/python3.6/site-packages/paramiko/client.py", line 349, in connect
    retry_on_signal(lambda: sock.connect(addr))
  File "/home/eve/PycharmProjects/ospf_enterprise/venv/lib/python3.6/site-packages/paramiko/util.py", line 283, in retry_on_signal
    return function()
  File "/home/eve/PycharmProjects/ospf_enterprise/venv/lib/python3.6/site-packages/paramiko/client.py", line 349, in <lambda>
    retry_on_signal(lambda: sock.connect(addr))
socket.timeout: timed out

During handling of the above exception, another exception occurred:

Traceback (most recent call last):
  File "/home/eve/PycharmProjects/ospf_enterprise/venv/lib/python3.6/site-packages/nornir/core/task.py", line 85, in start
    r = self.task(self, **self.params)
  File "/home/eve/PycharmProjects/ospf_enterprise/venv/lib/python3.6/site-packages/nornir/plugins/tasks/networking/netmiko_send_command.py", line 26, in netmiko_send_command
    net_connect = task.host.get_connection("netmiko", task.nornir.config)
  File "/home/eve/PycharmProjects/ospf_enterprise/venv/lib/python3.6/site-packages/nornir/core/inventory.py", line 305, in get_connection
    extras=conn.extras,
  File "/home/eve/PycharmProjects/ospf_enterprise/venv/lib/python3.6/site-packages/nornir/core/inventory.py", line 365, in open_connection
    configuration=configuration,
  File "/home/eve/PycharmProjects/ospf_enterprise/venv/lib/python3.6/site-packages/nornir/plugins/connections/netmiko.py", line 58, in open
    self.connection = ConnectHandler(**parameters)
  File "/home/eve/PycharmProjects/ospf_enterprise/venv/lib/python3.6/site-packages/netmiko/ssh_dispatcher.py", line 302, in ConnectHandler
    return ConnectionClass(*args, **kwargs)
  File "/home/eve/PycharmProjects/ospf_enterprise/venv/lib/python3.6/site-packages/netmiko/cisco/cisco_ios.py", line 17, in __init__
    return super().__init__(*args, **kwargs)
  File "/home/eve/PycharmProjects/ospf_enterprise/venv/lib/python3.6/site-packages/netmiko/base_connection.py", line 344, in __init__
    self._open()
  File "/home/eve/PycharmProjects/ospf_enterprise/venv/lib/python3.6/site-packages/netmiko/base_connection.py", line 349, in _open
    self.establish_connection()
  File "/home/eve/PycharmProjects/ospf_enterprise/venv/lib/python3.6/site-packages/netmiko/base_connection.py", line 940, in establish_connection
    raise NetmikoTimeoutException(msg)
netmiko.ssh_exception.NetmikoTimeoutException: TCP connection to device failed.

Common causes of this problem are:
1. Incorrect hostname or IP address.
2. Wrong TCP port.
3. Intermediate firewall blocking access.

Device settings: cisco_xe 10.0.18.8:22



2020-09-12 22:33:16,948 - nornir.core.task -    ERROR -      start() - Host 'R8': task 'test' failed with traceback:
Traceback (most recent call last):
  File "/home/eve/PycharmProjects/ospf_enterprise/venv/lib/python3.6/site-packages/nornir/core/task.py", line 85, in start
    r = self.task(self, **self.params)
  File "ospf.py", line 14, in test
    result = task.run(netmiko_send_command, command_string='show ip ospf nei', use_genie=True)
  File "/home/eve/PycharmProjects/ospf_enterprise/venv/lib/python3.6/site-packages/nornir/core/task.py", line 147, in run
    raise NornirSubTaskError(task=task, result=r)
nornir.core.exceptions.NornirSubTaskError: Subtask: <function netmiko_send_command at 0x7f829c63e9d8> (failed)


